2023-05-15 08:47:13,822 ERROR something went wrong
2023-05-15 09:00:07,277 ERROR something went wrong
2023-05-15 09:00:50,735 ERROR something went wrong
2023-05-15 09:01:51,897 ERROR something went wrong
2023-05-15 09:01:51,897 ERROR An error occurred during login: cannot access local variable 'e' where it is not associated with a value
2023-05-15 09:02:27,511 ERROR something went wrong
2023-05-15 09:03:05,641 ERROR something went wrong
2023-05-15 09:05:23,998 ERROR something went wrong
2023-05-15 09:07:41,196 ERROR something went wrong
2023-05-15 09:12:00,510 ERROR something went wrong
2023-05-15 09:12:08,897 ERROR something went wrong
2023-05-15 09:13:32,526 ERROR something went wrong
2023-05-15 09:15:02,357 ERROR Internal Server Error: /admin/frontapp/exceptions/3/change/
Traceback (most recent call last):
  File "/home/simprosys-aman/.local/lib/python3.11/site-packages/django/core/handlers/exception.py", line 55, in inner
    response = get_response(request)
               ^^^^^^^^^^^^^^^^^^^^^
  File "/home/simprosys-aman/.local/lib/python3.11/site-packages/django/core/handlers/base.py", line 197, in _get_response
    response = wrapped_callback(request, *callback_args, **callback_kwargs)
               ^^^^^^^^^^^^^^^^^^^^^^^^^^^^^^^^^^^^^^^^^^^^^^^^^^^^^^^^^^^^
  File "/home/simprosys-aman/.local/lib/python3.11/site-packages/django/contrib/admin/options.py", line 688, in wrapper
    return self.admin_site.admin_view(view)(*args, **kwargs)
           ^^^^^^^^^^^^^^^^^^^^^^^^^^^^^^^^^^^^^^^^^^^^^^^^^
  File "/home/simprosys-aman/.local/lib/python3.11/site-packages/django/utils/decorators.py", line 134, in _wrapper_view
    response = view_func(request, *args, **kwargs)
               ^^^^^^^^^^^^^^^^^^^^^^^^^^^^^^^^^^^
  File "/home/simprosys-aman/.local/lib/python3.11/site-packages/django/views/decorators/cache.py", line 62, in _wrapper_view_func
    response = view_func(request, *args, **kwargs)
               ^^^^^^^^^^^^^^^^^^^^^^^^^^^^^^^^^^^
  File "/home/simprosys-aman/.local/lib/python3.11/site-packages/django/contrib/admin/sites.py", line 242, in inner
    return view(request, *args, **kwargs)
           ^^^^^^^^^^^^^^^^^^^^^^^^^^^^^^
  File "/home/simprosys-aman/.local/lib/python3.11/site-packages/django/contrib/admin/options.py", line 1889, in change_view
    return self.changeform_view(request, object_id, form_url, extra_context)
           ^^^^^^^^^^^^^^^^^^^^^^^^^^^^^^^^^^^^^^^^^^^^^^^^^^^^^^^^^^^^^^^^^
  File "/home/simprosys-aman/.local/lib/python3.11/site-packages/django/utils/decorators.py", line 46, in _wrapper
    return bound_method(*args, **kwargs)
           ^^^^^^^^^^^^^^^^^^^^^^^^^^^^^
  File "/home/simprosys-aman/.local/lib/python3.11/site-packages/django/utils/decorators.py", line 134, in _wrapper_view
    response = view_func(request, *args, **kwargs)
               ^^^^^^^^^^^^^^^^^^^^^^^^^^^^^^^^^^^
  File "/home/simprosys-aman/.local/lib/python3.11/site-packages/django/contrib/admin/options.py", line 1747, in changeform_view
    return self._changeform_view(request, object_id, form_url, extra_context)
           ^^^^^^^^^^^^^^^^^^^^^^^^^^^^^^^^^^^^^^^^^^^^^^^^^^^^^^^^^^^^^^^^^^
  File "/home/simprosys-aman/.local/lib/python3.11/site-packages/django/contrib/admin/options.py", line 1855, in _changeform_view
    "subtitle": str(obj) if obj else None,
                ^^^^^^^^
TypeError: __str__ returned non-string (type User)
2023-05-15 09:19:24,756 ERROR something went wrong
2023-05-15 09:20:19,665 ERROR Internal Server Error: /admin/frontapp/exceptions/
Traceback (most recent call last):
  File "/home/simprosys-aman/.local/lib/python3.11/site-packages/django/db/models/options.py", line 681, in get_field
    return self.fields_map[field_name]
           ~~~~~~~~~~~~~~~^^^^^^^^^^^^
KeyError: '__str__'

During handling of the above exception, another exception occurred:

Traceback (most recent call last):
  File "/home/simprosys-aman/.local/lib/python3.11/site-packages/django/contrib/admin/utils.py", line 272, in lookup_field
    f = _get_non_gfk_field(opts, name)
        ^^^^^^^^^^^^^^^^^^^^^^^^^^^^^^
  File "/home/simprosys-aman/.local/lib/python3.11/site-packages/django/contrib/admin/utils.py", line 303, in _get_non_gfk_field
    field = opts.get_field(name)
            ^^^^^^^^^^^^^^^^^^^^
  File "/home/simprosys-aman/.local/lib/python3.11/site-packages/django/db/models/options.py", line 683, in get_field
    raise FieldDoesNotExist(
django.core.exceptions.FieldDoesNotExist: Exceptions has no field named '__str__'

During handling of the above exception, another exception occurred:

Traceback (most recent call last):
  File "/home/simprosys-aman/.local/lib/python3.11/site-packages/django/core/handlers/exception.py", line 55, in inner
    response = get_response(request)
               ^^^^^^^^^^^^^^^^^^^^^
  File "/home/simprosys-aman/.local/lib/python3.11/site-packages/django/core/handlers/base.py", line 220, in _get_response
    response = response.render()
               ^^^^^^^^^^^^^^^^^
  File "/home/simprosys-aman/.local/lib/python3.11/site-packages/django/template/response.py", line 114, in render
    self.content = self.rendered_content
                   ^^^^^^^^^^^^^^^^^^^^^
  File "/home/simprosys-aman/.local/lib/python3.11/site-packages/django/template/response.py", line 92, in rendered_content
    return template.render(context, self._request)
           ^^^^^^^^^^^^^^^^^^^^^^^^^^^^^^^^^^^^^^^
  File "/home/simprosys-aman/.local/lib/python3.11/site-packages/django/template/backends/django.py", line 61, in render
    return self.template.render(context)
           ^^^^^^^^^^^^^^^^^^^^^^^^^^^^^
  File "/home/simprosys-aman/.local/lib/python3.11/site-packages/django/template/base.py", line 175, in render
    return self._render(context)
           ^^^^^^^^^^^^^^^^^^^^^
  File "/home/simprosys-aman/.local/lib/python3.11/site-packages/django/template/base.py", line 167, in _render
    return self.nodelist.render(context)
           ^^^^^^^^^^^^^^^^^^^^^^^^^^^^^
  File "/home/simprosys-aman/.local/lib/python3.11/site-packages/django/template/base.py", line 1005, in render
    return SafeString("".join([node.render_annotated(context) for node in self]))
                              ^^^^^^^^^^^^^^^^^^^^^^^^^^^^^^^^^^^^^^^^^^^^^^^^^
  File "/home/simprosys-aman/.local/lib/python3.11/site-packages/django/template/base.py", line 1005, in <listcomp>
    return SafeString("".join([node.render_annotated(context) for node in self]))
                               ^^^^^^^^^^^^^^^^^^^^^^^^^^^^^^
  File "/home/simprosys-aman/.local/lib/python3.11/site-packages/django/template/base.py", line 966, in render_annotated
    return self.render(context)
           ^^^^^^^^^^^^^^^^^^^^
  File "/home/simprosys-aman/.local/lib/python3.11/site-packages/django/template/loader_tags.py", line 157, in render
    return compiled_parent._render(context)
           ^^^^^^^^^^^^^^^^^^^^^^^^^^^^^^^^
  File "/home/simprosys-aman/.local/lib/python3.11/site-packages/django/template/base.py", line 167, in _render
    return self.nodelist.render(context)
           ^^^^^^^^^^^^^^^^^^^^^^^^^^^^^
  File "/home/simprosys-aman/.local/lib/python3.11/site-packages/django/template/base.py", line 1005, in render
    return SafeString("".join([node.render_annotated(context) for node in self]))
                              ^^^^^^^^^^^^^^^^^^^^^^^^^^^^^^^^^^^^^^^^^^^^^^^^^
  File "/home/simprosys-aman/.local/lib/python3.11/site-packages/django/template/base.py", line 1005, in <listcomp>
    return SafeString("".join([node.render_annotated(context) for node in self]))
                               ^^^^^^^^^^^^^^^^^^^^^^^^^^^^^^
  File "/home/simprosys-aman/.local/lib/python3.11/site-packages/django/template/base.py", line 966, in render_annotated
    return self.render(context)
           ^^^^^^^^^^^^^^^^^^^^
  File "/home/simprosys-aman/.local/lib/python3.11/site-packages/django/template/loader_tags.py", line 157, in render
    return compiled_parent._render(context)
           ^^^^^^^^^^^^^^^^^^^^^^^^^^^^^^^^
  File "/home/simprosys-aman/.local/lib/python3.11/site-packages/django/template/base.py", line 167, in _render
    return self.nodelist.render(context)
           ^^^^^^^^^^^^^^^^^^^^^^^^^^^^^
  File "/home/simprosys-aman/.local/lib/python3.11/site-packages/django/template/base.py", line 1005, in render
    return SafeString("".join([node.render_annotated(context) for node in self]))
                              ^^^^^^^^^^^^^^^^^^^^^^^^^^^^^^^^^^^^^^^^^^^^^^^^^
  File "/home/simprosys-aman/.local/lib/python3.11/site-packages/django/template/base.py", line 1005, in <listcomp>
    return SafeString("".join([node.render_annotated(context) for node in self]))
                               ^^^^^^^^^^^^^^^^^^^^^^^^^^^^^^
  File "/home/simprosys-aman/.local/lib/python3.11/site-packages/django/template/base.py", line 966, in render_annotated
    return self.render(context)
           ^^^^^^^^^^^^^^^^^^^^
  File "/home/simprosys-aman/.local/lib/python3.11/site-packages/django/template/loader_tags.py", line 63, in render
    result = block.nodelist.render(context)
             ^^^^^^^^^^^^^^^^^^^^^^^^^^^^^^
  File "/home/simprosys-aman/.local/lib/python3.11/site-packages/django/template/base.py", line 1005, in render
    return SafeString("".join([node.render_annotated(context) for node in self]))
                              ^^^^^^^^^^^^^^^^^^^^^^^^^^^^^^^^^^^^^^^^^^^^^^^^^
  File "/home/simprosys-aman/.local/lib/python3.11/site-packages/django/template/base.py", line 1005, in <listcomp>
    return SafeString("".join([node.render_annotated(context) for node in self]))
                               ^^^^^^^^^^^^^^^^^^^^^^^^^^^^^^
  File "/home/simprosys-aman/.local/lib/python3.11/site-packages/django/template/base.py", line 966, in render_annotated
    return self.render(context)
           ^^^^^^^^^^^^^^^^^^^^
  File "/home/simprosys-aman/.local/lib/python3.11/site-packages/django/template/loader_tags.py", line 63, in render
    result = block.nodelist.render(context)
             ^^^^^^^^^^^^^^^^^^^^^^^^^^^^^^
  File "/home/simprosys-aman/.local/lib/python3.11/site-packages/django/template/base.py", line 1005, in render
    return SafeString("".join([node.render_annotated(context) for node in self]))
                              ^^^^^^^^^^^^^^^^^^^^^^^^^^^^^^^^^^^^^^^^^^^^^^^^^
  File "/home/simprosys-aman/.local/lib/python3.11/site-packages/django/template/base.py", line 1005, in <listcomp>
    return SafeString("".join([node.render_annotated(context) for node in self]))
                               ^^^^^^^^^^^^^^^^^^^^^^^^^^^^^^
  File "/home/simprosys-aman/.local/lib/python3.11/site-packages/django/template/base.py", line 966, in render_annotated
    return self.render(context)
           ^^^^^^^^^^^^^^^^^^^^
  File "/home/simprosys-aman/.local/lib/python3.11/site-packages/django/contrib/admin/templatetags/base.py", line 45, in render
    return super().render(context)
           ^^^^^^^^^^^^^^^^^^^^^^^
  File "/home/simprosys-aman/.local/lib/python3.11/site-packages/django/template/library.py", line 258, in render
    _dict = self.func(*resolved_args, **resolved_kwargs)
            ^^^^^^^^^^^^^^^^^^^^^^^^^^^^^^^^^^^^^^^^^^^^
  File "/home/simprosys-aman/.local/lib/python3.11/site-packages/django/contrib/admin/templatetags/admin_list.py", line 336, in result_list
    "results": list(results(cl)),
               ^^^^^^^^^^^^^^^^^
  File "/home/simprosys-aman/.local/lib/python3.11/site-packages/django/contrib/admin/templatetags/admin_list.py", line 312, in results
    yield ResultList(None, items_for_result(cl, res, None))
          ^^^^^^^^^^^^^^^^^^^^^^^^^^^^^^^^^^^^^^^^^^^^^^^^^
  File "/home/simprosys-aman/.local/lib/python3.11/site-packages/django/contrib/admin/templatetags/admin_list.py", line 303, in __init__
    super().__init__(*items)
  File "/home/simprosys-aman/.local/lib/python3.11/site-packages/django/contrib/admin/templatetags/admin_list.py", line 213, in items_for_result
    f, attr, value = lookup_field(field_name, result, cl.model_admin)
                     ^^^^^^^^^^^^^^^^^^^^^^^^^^^^^^^^^^^^^^^^^^^^^^^^
  File "/home/simprosys-aman/.local/lib/python3.11/site-packages/django/contrib/admin/utils.py", line 285, in lookup_field
    value = attr()
            ^^^^^^
  File "/home/simprosys-aman/Aman/Aman/Practical/Shopify/frontapp/models.py", line 104, in __str__
    return self.user_id + str(self.user_id)
           ~~~~~~~~~~~~~^~~~~~~~~~~~~~~~~~~
TypeError: unsupported operand type(s) for +: 'User' and 'str'
2023-05-15 09:26:45,923 ERROR something went wrong
2023-05-15 09:27:51,244 ERROR something went wrong
2023-05-15 09:29:10,510 ERROR something went wrong
2023-05-15 09:30:13,090 ERROR something went wrong
2023-05-15 09:31:25,042 ERROR something went wrong
2023-05-15 09:32:59,334 ERROR something went wrong
2023-05-15 09:39:24,770 ERROR something went wrong
2023-05-15 09:41:26,571 ERROR something went wrong
2023-05-15 09:42:15,731 ERROR something went wrong
2023-05-15 09:45:24,410 ERROR something went wrong
2023-05-15 09:45:24,411 ERROR An error occurred during login: cannot access local variable 'e' where it is not associated with a value
2023-05-15 09:45:55,545 ERROR something went wrong
2023-05-15 09:45:55,545 ERROR An error occurred during login: cannot access local variable 'e' where it is not associated with a value
2023-05-15 09:48:56,006 ERROR something went wrong
2023-05-15 10:10:40,036 ERROR Internal Server Error: /front/login/
Traceback (most recent call last):
  File "/home/simprosys-aman/.local/lib/python3.11/site-packages/django/db/backends/utils.py", line 89, in _execute
    return self.cursor.execute(sql, params)
           ^^^^^^^^^^^^^^^^^^^^^^^^^^^^^^^^
  File "/home/simprosys-aman/.local/lib/python3.11/site-packages/django/db/backends/sqlite3/base.py", line 328, in execute
    return super().execute(query, params)
           ^^^^^^^^^^^^^^^^^^^^^^^^^^^^^^
sqlite3.IntegrityError: NOT NULL constraint failed: frontapp_useractivity.user_id_id

The above exception was the direct cause of the following exception:

Traceback (most recent call last):
  File "/home/simprosys-aman/Aman/Aman/Practical/Shopify/frontapp/views.py", line 54, in login_user
    activity.save()
  File "/home/simprosys-aman/.local/lib/python3.11/site-packages/django/db/models/base.py", line 814, in save
    self.save_base(
  File "/home/simprosys-aman/.local/lib/python3.11/site-packages/django/db/models/base.py", line 877, in save_base
    updated = self._save_table(
              ^^^^^^^^^^^^^^^^^
  File "/home/simprosys-aman/.local/lib/python3.11/site-packages/django/db/models/base.py", line 1020, in _save_table
    results = self._do_insert(
              ^^^^^^^^^^^^^^^^
  File "/home/simprosys-aman/.local/lib/python3.11/site-packages/django/db/models/base.py", line 1061, in _do_insert
    return manager._insert(
           ^^^^^^^^^^^^^^^^
  File "/home/simprosys-aman/.local/lib/python3.11/site-packages/django/db/models/manager.py", line 87, in manager_method
    return getattr(self.get_queryset(), name)(*args, **kwargs)
           ^^^^^^^^^^^^^^^^^^^^^^^^^^^^^^^^^^^^^^^^^^^^^^^^^^^
  File "/home/simprosys-aman/.local/lib/python3.11/site-packages/django/db/models/query.py", line 1805, in _insert
    return query.get_compiler(using=using).execute_sql(returning_fields)
           ^^^^^^^^^^^^^^^^^^^^^^^^^^^^^^^^^^^^^^^^^^^^^^^^^^^^^^^^^^^^^
  File "/home/simprosys-aman/.local/lib/python3.11/site-packages/django/db/models/sql/compiler.py", line 1820, in execute_sql
    cursor.execute(sql, params)
  File "/home/simprosys-aman/.local/lib/python3.11/site-packages/django/db/backends/utils.py", line 102, in execute
    return super().execute(sql, params)
           ^^^^^^^^^^^^^^^^^^^^^^^^^^^^
  File "/home/simprosys-aman/.local/lib/python3.11/site-packages/django/db/backends/utils.py", line 67, in execute
    return self._execute_with_wrappers(
           ^^^^^^^^^^^^^^^^^^^^^^^^^^^^
  File "/home/simprosys-aman/.local/lib/python3.11/site-packages/django/db/backends/utils.py", line 80, in _execute_with_wrappers
    return executor(sql, params, many, context)
           ^^^^^^^^^^^^^^^^^^^^^^^^^^^^^^^^^^^^
  File "/home/simprosys-aman/.local/lib/python3.11/site-packages/django/db/backends/utils.py", line 84, in _execute
    with self.db.wrap_database_errors:
  File "/home/simprosys-aman/.local/lib/python3.11/site-packages/django/db/utils.py", line 91, in __exit__
    raise dj_exc_value.with_traceback(traceback) from exc_value
  File "/home/simprosys-aman/.local/lib/python3.11/site-packages/django/db/backends/utils.py", line 89, in _execute
    return self.cursor.execute(sql, params)
           ^^^^^^^^^^^^^^^^^^^^^^^^^^^^^^^^
  File "/home/simprosys-aman/.local/lib/python3.11/site-packages/django/db/backends/sqlite3/base.py", line 328, in execute
    return super().execute(query, params)
           ^^^^^^^^^^^^^^^^^^^^^^^^^^^^^^
django.db.utils.IntegrityError: NOT NULL constraint failed: frontapp_useractivity.user_id_id

During handling of the above exception, another exception occurred:

Traceback (most recent call last):
  File "/home/simprosys-aman/.local/lib/python3.11/site-packages/django/core/handlers/exception.py", line 55, in inner
    response = get_response(request)
               ^^^^^^^^^^^^^^^^^^^^^
  File "/home/simprosys-aman/.local/lib/python3.11/site-packages/django/core/handlers/base.py", line 197, in _get_response
    response = wrapped_callback(request, *callback_args, **callback_kwargs)
               ^^^^^^^^^^^^^^^^^^^^^^^^^^^^^^^^^^^^^^^^^^^^^^^^^^^^^^^^^^^^
  File "/home/simprosys-aman/Aman/Aman/Practical/Shopify/frontapp/views.py", line 80, in login_user
    save_exception_to_database(
TypeError: save_exception_to_database() got an unexpected keyword argument 'type'
2023-05-15 10:11:25,479 ERROR Internal Server Error: /front/login/
Traceback (most recent call last):
  File "/home/simprosys-aman/.local/lib/python3.11/site-packages/django/db/backends/utils.py", line 89, in _execute
    return self.cursor.execute(sql, params)
           ^^^^^^^^^^^^^^^^^^^^^^^^^^^^^^^^
  File "/home/simprosys-aman/.local/lib/python3.11/site-packages/django/db/backends/sqlite3/base.py", line 328, in execute
    return super().execute(query, params)
           ^^^^^^^^^^^^^^^^^^^^^^^^^^^^^^
sqlite3.IntegrityError: NOT NULL constraint failed: frontapp_useractivity.user_id_id

The above exception was the direct cause of the following exception:

Traceback (most recent call last):
  File "/home/simprosys-aman/Aman/Aman/Practical/Shopify/frontapp/views.py", line 66, in login_user
    activity.save()
  File "/home/simprosys-aman/.local/lib/python3.11/site-packages/django/db/models/base.py", line 814, in save
    self.save_base(
  File "/home/simprosys-aman/.local/lib/python3.11/site-packages/django/db/models/base.py", line 877, in save_base
    updated = self._save_table(
              ^^^^^^^^^^^^^^^^^
  File "/home/simprosys-aman/.local/lib/python3.11/site-packages/django/db/models/base.py", line 1020, in _save_table
    results = self._do_insert(
              ^^^^^^^^^^^^^^^^
  File "/home/simprosys-aman/.local/lib/python3.11/site-packages/django/db/models/base.py", line 1061, in _do_insert
    return manager._insert(
           ^^^^^^^^^^^^^^^^
  File "/home/simprosys-aman/.local/lib/python3.11/site-packages/django/db/models/manager.py", line 87, in manager_method
    return getattr(self.get_queryset(), name)(*args, **kwargs)
           ^^^^^^^^^^^^^^^^^^^^^^^^^^^^^^^^^^^^^^^^^^^^^^^^^^^
  File "/home/simprosys-aman/.local/lib/python3.11/site-packages/django/db/models/query.py", line 1805, in _insert
    return query.get_compiler(using=using).execute_sql(returning_fields)
           ^^^^^^^^^^^^^^^^^^^^^^^^^^^^^^^^^^^^^^^^^^^^^^^^^^^^^^^^^^^^^
  File "/home/simprosys-aman/.local/lib/python3.11/site-packages/django/db/models/sql/compiler.py", line 1820, in execute_sql
    cursor.execute(sql, params)
  File "/home/simprosys-aman/.local/lib/python3.11/site-packages/django/db/backends/utils.py", line 102, in execute
    return super().execute(sql, params)
           ^^^^^^^^^^^^^^^^^^^^^^^^^^^^
  File "/home/simprosys-aman/.local/lib/python3.11/site-packages/django/db/backends/utils.py", line 67, in execute
    return self._execute_with_wrappers(
           ^^^^^^^^^^^^^^^^^^^^^^^^^^^^
  File "/home/simprosys-aman/.local/lib/python3.11/site-packages/django/db/backends/utils.py", line 80, in _execute_with_wrappers
    return executor(sql, params, many, context)
           ^^^^^^^^^^^^^^^^^^^^^^^^^^^^^^^^^^^^
  File "/home/simprosys-aman/.local/lib/python3.11/site-packages/django/db/backends/utils.py", line 84, in _execute
    with self.db.wrap_database_errors:
  File "/home/simprosys-aman/.local/lib/python3.11/site-packages/django/db/utils.py", line 91, in __exit__
    raise dj_exc_value.with_traceback(traceback) from exc_value
  File "/home/simprosys-aman/.local/lib/python3.11/site-packages/django/db/backends/utils.py", line 89, in _execute
    return self.cursor.execute(sql, params)
           ^^^^^^^^^^^^^^^^^^^^^^^^^^^^^^^^
  File "/home/simprosys-aman/.local/lib/python3.11/site-packages/django/db/backends/sqlite3/base.py", line 328, in execute
    return super().execute(query, params)
           ^^^^^^^^^^^^^^^^^^^^^^^^^^^^^^
django.db.utils.IntegrityError: NOT NULL constraint failed: frontapp_useractivity.user_id_id

During handling of the above exception, another exception occurred:

Traceback (most recent call last):
  File "/home/simprosys-aman/.local/lib/python3.11/site-packages/django/core/handlers/exception.py", line 55, in inner
    response = get_response(request)
               ^^^^^^^^^^^^^^^^^^^^^
  File "/home/simprosys-aman/.local/lib/python3.11/site-packages/django/core/handlers/base.py", line 197, in _get_response
    response = wrapped_callback(request, *callback_args, **callback_kwargs)
               ^^^^^^^^^^^^^^^^^^^^^^^^^^^^^^^^^^^^^^^^^^^^^^^^^^^^^^^^^^^^
  File "/home/simprosys-aman/Aman/Aman/Practical/Shopify/frontapp/views.py", line 92, in login_user
    save_exception_to_database(
TypeError: save_exception_to_database() got an unexpected keyword argument 'type'
2023-05-15 10:12:20,808 ERROR Internal Server Error: /front/login/
Traceback (most recent call last):
  File "/home/simprosys-aman/.local/lib/python3.11/site-packages/django/db/backends/utils.py", line 89, in _execute
    return self.cursor.execute(sql, params)
           ^^^^^^^^^^^^^^^^^^^^^^^^^^^^^^^^
  File "/home/simprosys-aman/.local/lib/python3.11/site-packages/django/db/backends/sqlite3/base.py", line 328, in execute
    return super().execute(query, params)
           ^^^^^^^^^^^^^^^^^^^^^^^^^^^^^^
sqlite3.IntegrityError: NOT NULL constraint failed: frontapp_useractivity.user_id_id

The above exception was the direct cause of the following exception:

Traceback (most recent call last):
  File "/home/simprosys-aman/Aman/Aman/Practical/Shopify/frontapp/views.py", line 66, in login_user
    activity.save()
  File "/home/simprosys-aman/.local/lib/python3.11/site-packages/django/db/models/base.py", line 814, in save
    self.save_base(
  File "/home/simprosys-aman/.local/lib/python3.11/site-packages/django/db/models/base.py", line 877, in save_base
    updated = self._save_table(
              ^^^^^^^^^^^^^^^^^
  File "/home/simprosys-aman/.local/lib/python3.11/site-packages/django/db/models/base.py", line 1020, in _save_table
    results = self._do_insert(
              ^^^^^^^^^^^^^^^^
  File "/home/simprosys-aman/.local/lib/python3.11/site-packages/django/db/models/base.py", line 1061, in _do_insert
    return manager._insert(
           ^^^^^^^^^^^^^^^^
  File "/home/simprosys-aman/.local/lib/python3.11/site-packages/django/db/models/manager.py", line 87, in manager_method
    return getattr(self.get_queryset(), name)(*args, **kwargs)
           ^^^^^^^^^^^^^^^^^^^^^^^^^^^^^^^^^^^^^^^^^^^^^^^^^^^
  File "/home/simprosys-aman/.local/lib/python3.11/site-packages/django/db/models/query.py", line 1805, in _insert
    return query.get_compiler(using=using).execute_sql(returning_fields)
           ^^^^^^^^^^^^^^^^^^^^^^^^^^^^^^^^^^^^^^^^^^^^^^^^^^^^^^^^^^^^^
  File "/home/simprosys-aman/.local/lib/python3.11/site-packages/django/db/models/sql/compiler.py", line 1820, in execute_sql
    cursor.execute(sql, params)
  File "/home/simprosys-aman/.local/lib/python3.11/site-packages/django/db/backends/utils.py", line 102, in execute
    return super().execute(sql, params)
           ^^^^^^^^^^^^^^^^^^^^^^^^^^^^
  File "/home/simprosys-aman/.local/lib/python3.11/site-packages/django/db/backends/utils.py", line 67, in execute
    return self._execute_with_wrappers(
           ^^^^^^^^^^^^^^^^^^^^^^^^^^^^
  File "/home/simprosys-aman/.local/lib/python3.11/site-packages/django/db/backends/utils.py", line 80, in _execute_with_wrappers
    return executor(sql, params, many, context)
           ^^^^^^^^^^^^^^^^^^^^^^^^^^^^^^^^^^^^
  File "/home/simprosys-aman/.local/lib/python3.11/site-packages/django/db/backends/utils.py", line 84, in _execute
    with self.db.wrap_database_errors:
  File "/home/simprosys-aman/.local/lib/python3.11/site-packages/django/db/utils.py", line 91, in __exit__
    raise dj_exc_value.with_traceback(traceback) from exc_value
  File "/home/simprosys-aman/.local/lib/python3.11/site-packages/django/db/backends/utils.py", line 89, in _execute
    return self.cursor.execute(sql, params)
           ^^^^^^^^^^^^^^^^^^^^^^^^^^^^^^^^
  File "/home/simprosys-aman/.local/lib/python3.11/site-packages/django/db/backends/sqlite3/base.py", line 328, in execute
    return super().execute(query, params)
           ^^^^^^^^^^^^^^^^^^^^^^^^^^^^^^
django.db.utils.IntegrityError: NOT NULL constraint failed: frontapp_useractivity.user_id_id

During handling of the above exception, another exception occurred:

Traceback (most recent call last):
  File "/home/simprosys-aman/.local/lib/python3.11/site-packages/django/core/handlers/exception.py", line 55, in inner
    response = get_response(request)
               ^^^^^^^^^^^^^^^^^^^^^
  File "/home/simprosys-aman/.local/lib/python3.11/site-packages/django/core/handlers/base.py", line 197, in _get_response
    response = wrapped_callback(request, *callback_args, **callback_kwargs)
               ^^^^^^^^^^^^^^^^^^^^^^^^^^^^^^^^^^^^^^^^^^^^^^^^^^^^^^^^^^^^
  File "/home/simprosys-aman/Aman/Aman/Practical/Shopify/frontapp/views.py", line 92, in login_user
    save_exception_to_database(
TypeError: save_exception_to_database() got an unexpected keyword argument 'type'
2023-05-15 10:18:35,925 ERROR Internal Server Error: /front/login/
Traceback (most recent call last):
  File "/home/simprosys-aman/.local/lib/python3.11/site-packages/django/db/backends/utils.py", line 89, in _execute
    return self.cursor.execute(sql, params)
           ^^^^^^^^^^^^^^^^^^^^^^^^^^^^^^^^
  File "/home/simprosys-aman/.local/lib/python3.11/site-packages/django/db/backends/sqlite3/base.py", line 328, in execute
    return super().execute(query, params)
           ^^^^^^^^^^^^^^^^^^^^^^^^^^^^^^
sqlite3.IntegrityError: NOT NULL constraint failed: frontapp_useractivity.user_id_id

The above exception was the direct cause of the following exception:

Traceback (most recent call last):
  File "/home/simprosys-aman/Aman/Aman/Practical/Shopify/frontapp/views.py", line 66, in login_user
    activity.save()
  File "/home/simprosys-aman/.local/lib/python3.11/site-packages/django/db/models/base.py", line 814, in save
    self.save_base(
  File "/home/simprosys-aman/.local/lib/python3.11/site-packages/django/db/models/base.py", line 877, in save_base
    updated = self._save_table(
              ^^^^^^^^^^^^^^^^^
  File "/home/simprosys-aman/.local/lib/python3.11/site-packages/django/db/models/base.py", line 1020, in _save_table
    results = self._do_insert(
              ^^^^^^^^^^^^^^^^
  File "/home/simprosys-aman/.local/lib/python3.11/site-packages/django/db/models/base.py", line 1061, in _do_insert
    return manager._insert(
           ^^^^^^^^^^^^^^^^
  File "/home/simprosys-aman/.local/lib/python3.11/site-packages/django/db/models/manager.py", line 87, in manager_method
    return getattr(self.get_queryset(), name)(*args, **kwargs)
           ^^^^^^^^^^^^^^^^^^^^^^^^^^^^^^^^^^^^^^^^^^^^^^^^^^^
  File "/home/simprosys-aman/.local/lib/python3.11/site-packages/django/db/models/query.py", line 1805, in _insert
    return query.get_compiler(using=using).execute_sql(returning_fields)
           ^^^^^^^^^^^^^^^^^^^^^^^^^^^^^^^^^^^^^^^^^^^^^^^^^^^^^^^^^^^^^
  File "/home/simprosys-aman/.local/lib/python3.11/site-packages/django/db/models/sql/compiler.py", line 1820, in execute_sql
    cursor.execute(sql, params)
  File "/home/simprosys-aman/.local/lib/python3.11/site-packages/django/db/backends/utils.py", line 102, in execute
    return super().execute(sql, params)
           ^^^^^^^^^^^^^^^^^^^^^^^^^^^^
  File "/home/simprosys-aman/.local/lib/python3.11/site-packages/django/db/backends/utils.py", line 67, in execute
    return self._execute_with_wrappers(
           ^^^^^^^^^^^^^^^^^^^^^^^^^^^^
  File "/home/simprosys-aman/.local/lib/python3.11/site-packages/django/db/backends/utils.py", line 80, in _execute_with_wrappers
    return executor(sql, params, many, context)
           ^^^^^^^^^^^^^^^^^^^^^^^^^^^^^^^^^^^^
  File "/home/simprosys-aman/.local/lib/python3.11/site-packages/django/db/backends/utils.py", line 84, in _execute
    with self.db.wrap_database_errors:
  File "/home/simprosys-aman/.local/lib/python3.11/site-packages/django/db/utils.py", line 91, in __exit__
    raise dj_exc_value.with_traceback(traceback) from exc_value
  File "/home/simprosys-aman/.local/lib/python3.11/site-packages/django/db/backends/utils.py", line 89, in _execute
    return self.cursor.execute(sql, params)
           ^^^^^^^^^^^^^^^^^^^^^^^^^^^^^^^^
  File "/home/simprosys-aman/.local/lib/python3.11/site-packages/django/db/backends/sqlite3/base.py", line 328, in execute
    return super().execute(query, params)
           ^^^^^^^^^^^^^^^^^^^^^^^^^^^^^^
django.db.utils.IntegrityError: NOT NULL constraint failed: frontapp_useractivity.user_id_id

During handling of the above exception, another exception occurred:

Traceback (most recent call last):
  File "/home/simprosys-aman/.local/lib/python3.11/site-packages/django/core/handlers/exception.py", line 55, in inner
    response = get_response(request)
               ^^^^^^^^^^^^^^^^^^^^^
  File "/home/simprosys-aman/.local/lib/python3.11/site-packages/django/core/handlers/base.py", line 197, in _get_response
    response = wrapped_callback(request, *callback_args, **callback_kwargs)
               ^^^^^^^^^^^^^^^^^^^^^^^^^^^^^^^^^^^^^^^^^^^^^^^^^^^^^^^^^^^^
  File "/home/simprosys-aman/Aman/Aman/Practical/Shopify/frontapp/views.py", line 95, in login_user
    save_exception_to_database(
TypeError: save_exception_to_database() got an unexpected keyword argument 'type'
2023-05-15 10:20:28,201 ERROR Internal Server Error: /front/login/
Traceback (most recent call last):
  File "/home/simprosys-aman/.local/lib/python3.11/site-packages/django/db/backends/utils.py", line 89, in _execute
    return self.cursor.execute(sql, params)
           ^^^^^^^^^^^^^^^^^^^^^^^^^^^^^^^^
  File "/home/simprosys-aman/.local/lib/python3.11/site-packages/django/db/backends/sqlite3/base.py", line 328, in execute
    return super().execute(query, params)
           ^^^^^^^^^^^^^^^^^^^^^^^^^^^^^^
sqlite3.IntegrityError: NOT NULL constraint failed: frontapp_useractivity.user_id_id

The above exception was the direct cause of the following exception:

Traceback (most recent call last):
  File "/home/simprosys-aman/Aman/Aman/Practical/Shopify/frontapp/views.py", line 66, in login_user
    activity.save()
  File "/home/simprosys-aman/.local/lib/python3.11/site-packages/django/db/models/base.py", line 814, in save
    self.save_base(
  File "/home/simprosys-aman/.local/lib/python3.11/site-packages/django/db/models/base.py", line 877, in save_base
    updated = self._save_table(
              ^^^^^^^^^^^^^^^^^
  File "/home/simprosys-aman/.local/lib/python3.11/site-packages/django/db/models/base.py", line 1020, in _save_table
    results = self._do_insert(
              ^^^^^^^^^^^^^^^^
  File "/home/simprosys-aman/.local/lib/python3.11/site-packages/django/db/models/base.py", line 1061, in _do_insert
    return manager._insert(
           ^^^^^^^^^^^^^^^^
  File "/home/simprosys-aman/.local/lib/python3.11/site-packages/django/db/models/manager.py", line 87, in manager_method
    return getattr(self.get_queryset(), name)(*args, **kwargs)
           ^^^^^^^^^^^^^^^^^^^^^^^^^^^^^^^^^^^^^^^^^^^^^^^^^^^
  File "/home/simprosys-aman/.local/lib/python3.11/site-packages/django/db/models/query.py", line 1805, in _insert
    return query.get_compiler(using=using).execute_sql(returning_fields)
           ^^^^^^^^^^^^^^^^^^^^^^^^^^^^^^^^^^^^^^^^^^^^^^^^^^^^^^^^^^^^^
  File "/home/simprosys-aman/.local/lib/python3.11/site-packages/django/db/models/sql/compiler.py", line 1820, in execute_sql
    cursor.execute(sql, params)
  File "/home/simprosys-aman/.local/lib/python3.11/site-packages/django/db/backends/utils.py", line 102, in execute
    return super().execute(sql, params)
           ^^^^^^^^^^^^^^^^^^^^^^^^^^^^
  File "/home/simprosys-aman/.local/lib/python3.11/site-packages/django/db/backends/utils.py", line 67, in execute
    return self._execute_with_wrappers(
           ^^^^^^^^^^^^^^^^^^^^^^^^^^^^
  File "/home/simprosys-aman/.local/lib/python3.11/site-packages/django/db/backends/utils.py", line 80, in _execute_with_wrappers
    return executor(sql, params, many, context)
           ^^^^^^^^^^^^^^^^^^^^^^^^^^^^^^^^^^^^
  File "/home/simprosys-aman/.local/lib/python3.11/site-packages/django/db/backends/utils.py", line 84, in _execute
    with self.db.wrap_database_errors:
  File "/home/simprosys-aman/.local/lib/python3.11/site-packages/django/db/utils.py", line 91, in __exit__
    raise dj_exc_value.with_traceback(traceback) from exc_value
  File "/home/simprosys-aman/.local/lib/python3.11/site-packages/django/db/backends/utils.py", line 89, in _execute
    return self.cursor.execute(sql, params)
           ^^^^^^^^^^^^^^^^^^^^^^^^^^^^^^^^
  File "/home/simprosys-aman/.local/lib/python3.11/site-packages/django/db/backends/sqlite3/base.py", line 328, in execute
    return super().execute(query, params)
           ^^^^^^^^^^^^^^^^^^^^^^^^^^^^^^
django.db.utils.IntegrityError: NOT NULL constraint failed: frontapp_useractivity.user_id_id

During handling of the above exception, another exception occurred:

Traceback (most recent call last):
  File "/home/simprosys-aman/.local/lib/python3.11/site-packages/django/core/handlers/exception.py", line 55, in inner
    response = get_response(request)
               ^^^^^^^^^^^^^^^^^^^^^
  File "/home/simprosys-aman/.local/lib/python3.11/site-packages/django/core/handlers/base.py", line 197, in _get_response
    response = wrapped_callback(request, *callback_args, **callback_kwargs)
               ^^^^^^^^^^^^^^^^^^^^^^^^^^^^^^^^^^^^^^^^^^^^^^^^^^^^^^^^^^^^
  File "/home/simprosys-aman/Aman/Aman/Practical/Shopify/frontapp/views.py", line 95, in login_user
    save_exception_to_database(
TypeError: save_exception_to_database() got an unexpected keyword argument 'messages'
2023-05-15 10:21:28,052 ERROR Internal Server Error: /front/login/
Traceback (most recent call last):
  File "/home/simprosys-aman/.local/lib/python3.11/site-packages/django/db/backends/utils.py", line 89, in _execute
    return self.cursor.execute(sql, params)
           ^^^^^^^^^^^^^^^^^^^^^^^^^^^^^^^^
  File "/home/simprosys-aman/.local/lib/python3.11/site-packages/django/db/backends/sqlite3/base.py", line 328, in execute
    return super().execute(query, params)
           ^^^^^^^^^^^^^^^^^^^^^^^^^^^^^^
sqlite3.IntegrityError: NOT NULL constraint failed: frontapp_useractivity.user_id_id

The above exception was the direct cause of the following exception:

Traceback (most recent call last):
  File "/home/simprosys-aman/Aman/Aman/Practical/Shopify/frontapp/views.py", line 66, in login_user
    activity.save()
  File "/home/simprosys-aman/.local/lib/python3.11/site-packages/django/db/models/base.py", line 814, in save
    self.save_base(
  File "/home/simprosys-aman/.local/lib/python3.11/site-packages/django/db/models/base.py", line 877, in save_base
    updated = self._save_table(
              ^^^^^^^^^^^^^^^^^
  File "/home/simprosys-aman/.local/lib/python3.11/site-packages/django/db/models/base.py", line 1020, in _save_table
    results = self._do_insert(
              ^^^^^^^^^^^^^^^^
  File "/home/simprosys-aman/.local/lib/python3.11/site-packages/django/db/models/base.py", line 1061, in _do_insert
    return manager._insert(
           ^^^^^^^^^^^^^^^^
  File "/home/simprosys-aman/.local/lib/python3.11/site-packages/django/db/models/manager.py", line 87, in manager_method
    return getattr(self.get_queryset(), name)(*args, **kwargs)
           ^^^^^^^^^^^^^^^^^^^^^^^^^^^^^^^^^^^^^^^^^^^^^^^^^^^
  File "/home/simprosys-aman/.local/lib/python3.11/site-packages/django/db/models/query.py", line 1805, in _insert
    return query.get_compiler(using=using).execute_sql(returning_fields)
           ^^^^^^^^^^^^^^^^^^^^^^^^^^^^^^^^^^^^^^^^^^^^^^^^^^^^^^^^^^^^^
  File "/home/simprosys-aman/.local/lib/python3.11/site-packages/django/db/models/sql/compiler.py", line 1820, in execute_sql
    cursor.execute(sql, params)
  File "/home/simprosys-aman/.local/lib/python3.11/site-packages/django/db/backends/utils.py", line 102, in execute
    return super().execute(sql, params)
           ^^^^^^^^^^^^^^^^^^^^^^^^^^^^
  File "/home/simprosys-aman/.local/lib/python3.11/site-packages/django/db/backends/utils.py", line 67, in execute
    return self._execute_with_wrappers(
           ^^^^^^^^^^^^^^^^^^^^^^^^^^^^
  File "/home/simprosys-aman/.local/lib/python3.11/site-packages/django/db/backends/utils.py", line 80, in _execute_with_wrappers
    return executor(sql, params, many, context)
           ^^^^^^^^^^^^^^^^^^^^^^^^^^^^^^^^^^^^
  File "/home/simprosys-aman/.local/lib/python3.11/site-packages/django/db/backends/utils.py", line 84, in _execute
    with self.db.wrap_database_errors:
  File "/home/simprosys-aman/.local/lib/python3.11/site-packages/django/db/utils.py", line 91, in __exit__
    raise dj_exc_value.with_traceback(traceback) from exc_value
  File "/home/simprosys-aman/.local/lib/python3.11/site-packages/django/db/backends/utils.py", line 89, in _execute
    return self.cursor.execute(sql, params)
           ^^^^^^^^^^^^^^^^^^^^^^^^^^^^^^^^
  File "/home/simprosys-aman/.local/lib/python3.11/site-packages/django/db/backends/sqlite3/base.py", line 328, in execute
    return super().execute(query, params)
           ^^^^^^^^^^^^^^^^^^^^^^^^^^^^^^
django.db.utils.IntegrityError: NOT NULL constraint failed: frontapp_useractivity.user_id_id

During handling of the above exception, another exception occurred:

Traceback (most recent call last):
  File "/home/simprosys-aman/.local/lib/python3.11/site-packages/django/core/handlers/exception.py", line 55, in inner
    response = get_response(request)
               ^^^^^^^^^^^^^^^^^^^^^
  File "/home/simprosys-aman/.local/lib/python3.11/site-packages/django/core/handlers/base.py", line 197, in _get_response
    response = wrapped_callback(request, *callback_args, **callback_kwargs)
               ^^^^^^^^^^^^^^^^^^^^^^^^^^^^^^^^^^^^^^^^^^^^^^^^^^^^^^^^^^^^
  File "/home/simprosys-aman/Aman/Aman/Practical/Shopify/frontapp/views.py", line 95, in login_user
    save_exception_to_database(
  File "/home/simprosys-aman/Aman/Aman/Practical/Shopify/frontapp/views.py", line 46, in save_exception_to_database
    user_id_instence = User.objects.get(id=user_id)
                       ^^^^^^^^^^^^^^^^^^^^^^^^^^^^
  File "/home/simprosys-aman/.local/lib/python3.11/site-packages/django/db/models/manager.py", line 87, in manager_method
    return getattr(self.get_queryset(), name)(*args, **kwargs)
           ^^^^^^^^^^^^^^^^^^^^^^^^^^^^^^^^^^^^^^^^^^^^^^^^^^^
  File "/home/simprosys-aman/.local/lib/python3.11/site-packages/django/db/models/query.py", line 637, in get
    raise self.model.DoesNotExist(
django.contrib.auth.models.User.DoesNotExist: User matching query does not exist.
2023-05-15 10:24:33,817 ERROR Internal Server Error: /front/login/
Traceback (most recent call last):
  File "/home/simprosys-aman/.local/lib/python3.11/site-packages/django/db/backends/utils.py", line 89, in _execute
    return self.cursor.execute(sql, params)
           ^^^^^^^^^^^^^^^^^^^^^^^^^^^^^^^^
  File "/home/simprosys-aman/.local/lib/python3.11/site-packages/django/db/backends/sqlite3/base.py", line 328, in execute
    return super().execute(query, params)
           ^^^^^^^^^^^^^^^^^^^^^^^^^^^^^^
sqlite3.IntegrityError: NOT NULL constraint failed: frontapp_useractivity.user_id_id

The above exception was the direct cause of the following exception:

Traceback (most recent call last):
  File "/home/simprosys-aman/Aman/Aman/Practical/Shopify/frontapp/views.py", line 66, in login_user
    activity.save()
  File "/home/simprosys-aman/.local/lib/python3.11/site-packages/django/db/models/base.py", line 814, in save
    self.save_base(
  File "/home/simprosys-aman/.local/lib/python3.11/site-packages/django/db/models/base.py", line 877, in save_base
    updated = self._save_table(
              ^^^^^^^^^^^^^^^^^
  File "/home/simprosys-aman/.local/lib/python3.11/site-packages/django/db/models/base.py", line 1020, in _save_table
    results = self._do_insert(
              ^^^^^^^^^^^^^^^^
  File "/home/simprosys-aman/.local/lib/python3.11/site-packages/django/db/models/base.py", line 1061, in _do_insert
    return manager._insert(
           ^^^^^^^^^^^^^^^^
  File "/home/simprosys-aman/.local/lib/python3.11/site-packages/django/db/models/manager.py", line 87, in manager_method
    return getattr(self.get_queryset(), name)(*args, **kwargs)
           ^^^^^^^^^^^^^^^^^^^^^^^^^^^^^^^^^^^^^^^^^^^^^^^^^^^
  File "/home/simprosys-aman/.local/lib/python3.11/site-packages/django/db/models/query.py", line 1805, in _insert
    return query.get_compiler(using=using).execute_sql(returning_fields)
           ^^^^^^^^^^^^^^^^^^^^^^^^^^^^^^^^^^^^^^^^^^^^^^^^^^^^^^^^^^^^^
  File "/home/simprosys-aman/.local/lib/python3.11/site-packages/django/db/models/sql/compiler.py", line 1820, in execute_sql
    cursor.execute(sql, params)
  File "/home/simprosys-aman/.local/lib/python3.11/site-packages/django/db/backends/utils.py", line 102, in execute
    return super().execute(sql, params)
           ^^^^^^^^^^^^^^^^^^^^^^^^^^^^
  File "/home/simprosys-aman/.local/lib/python3.11/site-packages/django/db/backends/utils.py", line 67, in execute
    return self._execute_with_wrappers(
           ^^^^^^^^^^^^^^^^^^^^^^^^^^^^
  File "/home/simprosys-aman/.local/lib/python3.11/site-packages/django/db/backends/utils.py", line 80, in _execute_with_wrappers
    return executor(sql, params, many, context)
           ^^^^^^^^^^^^^^^^^^^^^^^^^^^^^^^^^^^^
  File "/home/simprosys-aman/.local/lib/python3.11/site-packages/django/db/backends/utils.py", line 84, in _execute
    with self.db.wrap_database_errors:
  File "/home/simprosys-aman/.local/lib/python3.11/site-packages/django/db/utils.py", line 91, in __exit__
    raise dj_exc_value.with_traceback(traceback) from exc_value
  File "/home/simprosys-aman/.local/lib/python3.11/site-packages/django/db/backends/utils.py", line 89, in _execute
    return self.cursor.execute(sql, params)
           ^^^^^^^^^^^^^^^^^^^^^^^^^^^^^^^^
  File "/home/simprosys-aman/.local/lib/python3.11/site-packages/django/db/backends/sqlite3/base.py", line 328, in execute
    return super().execute(query, params)
           ^^^^^^^^^^^^^^^^^^^^^^^^^^^^^^
django.db.utils.IntegrityError: NOT NULL constraint failed: frontapp_useractivity.user_id_id

During handling of the above exception, another exception occurred:

Traceback (most recent call last):
  File "/home/simprosys-aman/.local/lib/python3.11/site-packages/django/core/handlers/exception.py", line 55, in inner
    response = get_response(request)
               ^^^^^^^^^^^^^^^^^^^^^
  File "/home/simprosys-aman/.local/lib/python3.11/site-packages/django/core/handlers/base.py", line 197, in _get_response
    response = wrapped_callback(request, *callback_args, **callback_kwargs)
               ^^^^^^^^^^^^^^^^^^^^^^^^^^^^^^^^^^^^^^^^^^^^^^^^^^^^^^^^^^^^
  File "/home/simprosys-aman/Aman/Aman/Practical/Shopify/frontapp/views.py", line 93, in login_user
    save_exception_to_database(
  File "/home/simprosys-aman/Aman/Aman/Practical/Shopify/frontapp/views.py", line 46, in save_exception_to_database
    user_id_instence = User.objects.get(id=user_id)
                       ^^^^^^^^^^^^^^^^^^^^^^^^^^^^
  File "/home/simprosys-aman/.local/lib/python3.11/site-packages/django/db/models/manager.py", line 87, in manager_method
    return getattr(self.get_queryset(), name)(*args, **kwargs)
           ^^^^^^^^^^^^^^^^^^^^^^^^^^^^^^^^^^^^^^^^^^^^^^^^^^^
  File "/home/simprosys-aman/.local/lib/python3.11/site-packages/django/db/models/query.py", line 637, in get
    raise self.model.DoesNotExist(
django.contrib.auth.models.User.DoesNotExist: User matching query does not exist.
2023-05-15 10:30:14,930 ERROR something went wrong
2023-05-15 10:30:28,757 ERROR something went wrong
2023-05-15 10:30:28,758 ERROR An error occurred during login: cannot access local variable 'e' where it is not associated with a value
2023-05-15 10:31:05,252 ERROR something went wrong
2023-05-15 10:31:05,252 ERROR An error occurred during login: cannot access local variable 'e' where it is not associated with a value
2023-05-15 10:32:02,687 ERROR something went wrong
2023-05-15 10:32:10,690 ERROR something went wrong
2023-05-15 10:32:10,690 ERROR An error occurred during login: cannot access local variable 'e' where it is not associated with a value
2023-05-15 10:32:41,492 ERROR something went wrong
2023-05-15 10:32:41,493 ERROR An error occurred during login: cannot access local variable 'e' where it is not associated with a value
2023-05-15 10:33:46,524 ERROR something went wrong
2023-05-15 10:33:46,524 ERROR An error occurred during login: cannot access local variable 'e' where it is not associated with a value
2023-05-15 10:34:51,172 ERROR something went wrong
2023-05-15 10:34:51,172 ERROR An error occurred during login: cannot access local variable 'e' where it is not associated with a value
2023-05-15 10:35:52,097 ERROR something went wrong
2023-05-15 10:35:52,097 ERROR An error occurred during login: cannot access local variable 'e' where it is not associated with a value
2023-05-15 10:35:57,762 ERROR something went wrong
2023-05-15 10:35:57,762 ERROR An error occurred during login: cannot access local variable 'e' where it is not associated with a value
2023-05-15 10:37:00,448 ERROR something went wrong
2023-05-15 10:37:00,449 ERROR An error occurred during login: cannot access local variable 'e' where it is not associated with a value
2023-05-15 12:21:35,318 ERROR Internal Server Error: /front/logout/
Traceback (most recent call last):
  File "/home/simprosys-aman/.local/lib/python3.11/site-packages/django/core/handlers/exception.py", line 55, in inner
    response = get_response(request)
               ^^^^^^^^^^^^^^^^^^^^^
  File "/home/simprosys-aman/.local/lib/python3.11/site-packages/django/core/handlers/base.py", line 204, in _get_response
    self.check_response(response, callback)
  File "/home/simprosys-aman/.local/lib/python3.11/site-packages/django/core/handlers/base.py", line 332, in check_response
    raise ValueError(
ValueError: The view frontapp.views.logout_user didn't return an HttpResponse object. It returned None instead.
2023-05-15 12:21:56,091 ERROR something went wrong
2023-05-15 12:21:56,626 ERROR something went wrong
2023-05-15 12:21:56,811 ERROR something went wrong
2023-05-15 12:22:25,148 ERROR something went wrong
2023-05-15 12:22:57,019 ERROR Internal Server Error: /front/logout/
Traceback (most recent call last):
  File "/home/simprosys-aman/.local/lib/python3.11/site-packages/django/core/handlers/exception.py", line 55, in inner
    response = get_response(request)
               ^^^^^^^^^^^^^^^^^^^^^
  File "/home/simprosys-aman/.local/lib/python3.11/site-packages/django/core/handlers/base.py", line 204, in _get_response
    self.check_response(response, callback)
  File "/home/simprosys-aman/.local/lib/python3.11/site-packages/django/core/handlers/base.py", line 332, in check_response
    raise ValueError(
ValueError: The view frontapp.views.logout_user didn't return an HttpResponse object. It returned None instead.
2023-05-15 12:26:07,911 ERROR Internal Server Error: /front/logout/
Traceback (most recent call last):
  File "/home/simprosys-aman/.local/lib/python3.11/site-packages/django/core/handlers/exception.py", line 55, in inner
    response = get_response(request)
               ^^^^^^^^^^^^^^^^^^^^^
  File "/home/simprosys-aman/.local/lib/python3.11/site-packages/django/core/handlers/base.py", line 204, in _get_response
    self.check_response(response, callback)
  File "/home/simprosys-aman/.local/lib/python3.11/site-packages/django/core/handlers/base.py", line 332, in check_response
    raise ValueError(
ValueError: The view frontapp.views.logout_user didn't return an HttpResponse object. It returned None instead.
2023-05-15 12:44:06,600 ERROR Internal Server Error: /front/productlist1/
Traceback (most recent call last):
  File "/home/simprosys-aman/.local/lib/python3.11/site-packages/django/core/handlers/exception.py", line 55, in inner
    response = get_response(request)
               ^^^^^^^^^^^^^^^^^^^^^
  File "/home/simprosys-aman/.local/lib/python3.11/site-packages/django/core/handlers/base.py", line 204, in _get_response
    self.check_response(response, callback)
  File "/home/simprosys-aman/.local/lib/python3.11/site-packages/django/core/handlers/base.py", line 332, in check_response
    raise ValueError(
ValueError: The view frontapp.views.ProductList didn't return an HttpResponse object. It returned None instead.
2023-05-15 12:45:33,910 ERROR Internal Server Error: /front/productlist1/
Traceback (most recent call last):
  File "/home/simprosys-aman/.local/lib/python3.11/site-packages/django/core/handlers/exception.py", line 55, in inner
    response = get_response(request)
               ^^^^^^^^^^^^^^^^^^^^^
  File "/home/simprosys-aman/.local/lib/python3.11/site-packages/django/core/handlers/base.py", line 204, in _get_response
    self.check_response(response, callback)
  File "/home/simprosys-aman/.local/lib/python3.11/site-packages/django/core/handlers/base.py", line 332, in check_response
    raise ValueError(
ValueError: The view frontapp.views.ProductList didn't return an HttpResponse object. It returned None instead.
2023-05-15 12:45:39,858 ERROR Internal Server Error: /front/home/
Traceback (most recent call last):
  File "/home/simprosys-aman/Aman/Aman/Practical/Shopify/frontapp/views.py", line 541, in delete_multiple_product
    import acsd
ModuleNotFoundError: No module named 'acsd'

During handling of the above exception, another exception occurred:

Traceback (most recent call last):
  File "/home/simprosys-aman/.local/lib/python3.11/site-packages/django/core/handlers/exception.py", line 55, in inner
    response = get_response(request)
               ^^^^^^^^^^^^^^^^^^^^^
  File "/home/simprosys-aman/.local/lib/python3.11/site-packages/django/core/handlers/base.py", line 197, in _get_response
    response = wrapped_callback(request, *callback_args, **callback_kwargs)
               ^^^^^^^^^^^^^^^^^^^^^^^^^^^^^^^^^^^^^^^^^^^^^^^^^^^^^^^^^^^^
  File "/home/simprosys-aman/.local/lib/python3.11/site-packages/django/contrib/auth/decorators.py", line 23, in _wrapper_view
    return view_func(request, *args, **kwargs)
           ^^^^^^^^^^^^^^^^^^^^^^^^^^^^^^^^^^^
  File "/home/simprosys-aman/Aman/Aman/Practical/Shopify/frontapp/views.py", line 575, in delete_multiple_product
    return render(request, "temp/homepage.html")
           ^^^^^^^^^^^^^^^^^^^^^^^^^^^^^^^^^^^^^
  File "/home/simprosys-aman/.local/lib/python3.11/site-packages/django/shortcuts.py", line 24, in render
    content = loader.render_to_string(template_name, context, request, using=using)
              ^^^^^^^^^^^^^^^^^^^^^^^^^^^^^^^^^^^^^^^^^^^^^^^^^^^^^^^^^^^^^^^^^^^^^
  File "/home/simprosys-aman/.local/lib/python3.11/site-packages/django/template/loader.py", line 62, in render_to_string
    return template.render(context, request)
           ^^^^^^^^^^^^^^^^^^^^^^^^^^^^^^^^^
  File "/home/simprosys-aman/.local/lib/python3.11/site-packages/django/template/backends/django.py", line 61, in render
    return self.template.render(context)
           ^^^^^^^^^^^^^^^^^^^^^^^^^^^^^
  File "/home/simprosys-aman/.local/lib/python3.11/site-packages/django/template/base.py", line 175, in render
    return self._render(context)
           ^^^^^^^^^^^^^^^^^^^^^
  File "/home/simprosys-aman/.local/lib/python3.11/site-packages/django/template/base.py", line 167, in _render
    return self.nodelist.render(context)
           ^^^^^^^^^^^^^^^^^^^^^^^^^^^^^
  File "/home/simprosys-aman/.local/lib/python3.11/site-packages/django/template/base.py", line 1005, in render
    return SafeString("".join([node.render_annotated(context) for node in self]))
                              ^^^^^^^^^^^^^^^^^^^^^^^^^^^^^^^^^^^^^^^^^^^^^^^^^
  File "/home/simprosys-aman/.local/lib/python3.11/site-packages/django/template/base.py", line 1005, in <listcomp>
    return SafeString("".join([node.render_annotated(context) for node in self]))
                               ^^^^^^^^^^^^^^^^^^^^^^^^^^^^^^
  File "/home/simprosys-aman/.local/lib/python3.11/site-packages/django/template/base.py", line 966, in render_annotated
    return self.render(context)
           ^^^^^^^^^^^^^^^^^^^^
  File "/home/simprosys-aman/.local/lib/python3.11/site-packages/django/template/loader_tags.py", line 157, in render
    return compiled_parent._render(context)
           ^^^^^^^^^^^^^^^^^^^^^^^^^^^^^^^^
  File "/home/simprosys-aman/.local/lib/python3.11/site-packages/django/template/base.py", line 167, in _render
    return self.nodelist.render(context)
           ^^^^^^^^^^^^^^^^^^^^^^^^^^^^^
  File "/home/simprosys-aman/.local/lib/python3.11/site-packages/django/template/base.py", line 1005, in render
    return SafeString("".join([node.render_annotated(context) for node in self]))
                              ^^^^^^^^^^^^^^^^^^^^^^^^^^^^^^^^^^^^^^^^^^^^^^^^^
  File "/home/simprosys-aman/.local/lib/python3.11/site-packages/django/template/base.py", line 1005, in <listcomp>
    return SafeString("".join([node.render_annotated(context) for node in self]))
                               ^^^^^^^^^^^^^^^^^^^^^^^^^^^^^^
  File "/home/simprosys-aman/.local/lib/python3.11/site-packages/django/template/base.py", line 966, in render_annotated
    return self.render(context)
           ^^^^^^^^^^^^^^^^^^^^
  File "/home/simprosys-aman/.local/lib/python3.11/site-packages/django/template/defaulttags.py", line 471, in render
    url = reverse(view_name, args=args, kwargs=kwargs, current_app=current_app)
          ^^^^^^^^^^^^^^^^^^^^^^^^^^^^^^^^^^^^^^^^^^^^^^^^^^^^^^^^^^^^^^^^^^^^^
  File "/home/simprosys-aman/.local/lib/python3.11/site-packages/django/urls/base.py", line 88, in reverse
    return resolver._reverse_with_prefix(view, prefix, *args, **kwargs)
           ^^^^^^^^^^^^^^^^^^^^^^^^^^^^^^^^^^^^^^^^^^^^^^^^^^^^^^^^^^^^
  File "/home/simprosys-aman/.local/lib/python3.11/site-packages/django/urls/resolvers.py", line 828, in _reverse_with_prefix
    raise NoReverseMatch(msg)
django.urls.exceptions.NoReverseMatch: Reverse for 'delete_multiple_product' not found. 'delete_multiple_product' is not a valid view function or pattern name.
2023-05-15 12:46:03,266 ERROR Internal Server Error: /front/productlist1/
Traceback (most recent call last):
  File "/home/simprosys-aman/.local/lib/python3.11/site-packages/django/core/handlers/exception.py", line 55, in inner
    response = get_response(request)
               ^^^^^^^^^^^^^^^^^^^^^
  File "/home/simprosys-aman/.local/lib/python3.11/site-packages/django/core/handlers/base.py", line 204, in _get_response
    self.check_response(response, callback)
  File "/home/simprosys-aman/.local/lib/python3.11/site-packages/django/core/handlers/base.py", line 332, in check_response
    raise ValueError(
ValueError: The view frontapp.views.ProductList didn't return an HttpResponse object. It returned None instead.
2023-05-15 12:46:29,701 ERROR Internal Server Error: /front/productlist1/
Traceback (most recent call last):
  File "/home/simprosys-aman/.local/lib/python3.11/site-packages/django/core/handlers/exception.py", line 55, in inner
    response = get_response(request)
               ^^^^^^^^^^^^^^^^^^^^^
  File "/home/simprosys-aman/.local/lib/python3.11/site-packages/django/core/handlers/base.py", line 204, in _get_response
    self.check_response(response, callback)
  File "/home/simprosys-aman/.local/lib/python3.11/site-packages/django/core/handlers/base.py", line 332, in check_response
    raise ValueError(
ValueError: The view frontapp.views.ProductList didn't return an HttpResponse object. It returned None instead.
2023-05-15 12:46:31,359 ERROR Internal Server Error: /front/productlist1/
Traceback (most recent call last):
  File "/home/simprosys-aman/.local/lib/python3.11/site-packages/django/core/handlers/exception.py", line 55, in inner
    response = get_response(request)
               ^^^^^^^^^^^^^^^^^^^^^
  File "/home/simprosys-aman/.local/lib/python3.11/site-packages/django/core/handlers/base.py", line 204, in _get_response
    self.check_response(response, callback)
  File "/home/simprosys-aman/.local/lib/python3.11/site-packages/django/core/handlers/base.py", line 332, in check_response
    raise ValueError(
ValueError: The view frontapp.views.ProductList didn't return an HttpResponse object. It returned None instead.
2023-05-15 12:49:08,542 ERROR Internal Server Error: /front/productlist1/
Traceback (most recent call last):
  File "/home/simprosys-aman/.local/lib/python3.11/site-packages/django/core/handlers/exception.py", line 55, in inner
    response = get_response(request)
               ^^^^^^^^^^^^^^^^^^^^^
  File "/home/simprosys-aman/.local/lib/python3.11/site-packages/django/core/handlers/base.py", line 204, in _get_response
    self.check_response(response, callback)
  File "/home/simprosys-aman/.local/lib/python3.11/site-packages/django/core/handlers/base.py", line 332, in check_response
    raise ValueError(
ValueError: The view frontapp.views.ProductList didn't return an HttpResponse object. It returned None instead.
2023-05-15 12:49:35,419 ERROR Internal Server Error: /front/productlist1/
Traceback (most recent call last):
  File "/home/simprosys-aman/.local/lib/python3.11/site-packages/django/core/handlers/exception.py", line 55, in inner
    response = get_response(request)
               ^^^^^^^^^^^^^^^^^^^^^
  File "/home/simprosys-aman/.local/lib/python3.11/site-packages/django/core/handlers/base.py", line 204, in _get_response
    self.check_response(response, callback)
  File "/home/simprosys-aman/.local/lib/python3.11/site-packages/django/core/handlers/base.py", line 332, in check_response
    raise ValueError(
ValueError: The view frontapp.views.ProductList didn't return an HttpResponse object. It returned None instead.
2023-05-15 12:49:35,714 ERROR Internal Server Error: /front/productlist1/
Traceback (most recent call last):
  File "/home/simprosys-aman/.local/lib/python3.11/site-packages/django/core/handlers/exception.py", line 55, in inner
    response = get_response(request)
               ^^^^^^^^^^^^^^^^^^^^^
  File "/home/simprosys-aman/.local/lib/python3.11/site-packages/django/core/handlers/base.py", line 204, in _get_response
    self.check_response(response, callback)
  File "/home/simprosys-aman/.local/lib/python3.11/site-packages/django/core/handlers/base.py", line 332, in check_response
    raise ValueError(
ValueError: The view frontapp.views.ProductList didn't return an HttpResponse object. It returned None instead.
2023-05-15 12:49:35,914 ERROR Internal Server Error: /front/productlist1/
Traceback (most recent call last):
  File "/home/simprosys-aman/.local/lib/python3.11/site-packages/django/core/handlers/exception.py", line 55, in inner
    response = get_response(request)
               ^^^^^^^^^^^^^^^^^^^^^
  File "/home/simprosys-aman/.local/lib/python3.11/site-packages/django/core/handlers/base.py", line 204, in _get_response
    self.check_response(response, callback)
  File "/home/simprosys-aman/.local/lib/python3.11/site-packages/django/core/handlers/base.py", line 332, in check_response
    raise ValueError(
ValueError: The view frontapp.views.ProductList didn't return an HttpResponse object. It returned None instead.
2023-05-15 12:49:36,026 ERROR Internal Server Error: /front/productlist1/
Traceback (most recent call last):
  File "/home/simprosys-aman/.local/lib/python3.11/site-packages/django/core/handlers/exception.py", line 55, in inner
    response = get_response(request)
               ^^^^^^^^^^^^^^^^^^^^^
  File "/home/simprosys-aman/.local/lib/python3.11/site-packages/django/core/handlers/base.py", line 204, in _get_response
    self.check_response(response, callback)
  File "/home/simprosys-aman/.local/lib/python3.11/site-packages/django/core/handlers/base.py", line 332, in check_response
    raise ValueError(
ValueError: The view frontapp.views.ProductList didn't return an HttpResponse object. It returned None instead.
2023-05-15 12:49:36,254 ERROR Internal Server Error: /front/productlist1/
Traceback (most recent call last):
  File "/home/simprosys-aman/.local/lib/python3.11/site-packages/django/core/handlers/exception.py", line 55, in inner
    response = get_response(request)
               ^^^^^^^^^^^^^^^^^^^^^
  File "/home/simprosys-aman/.local/lib/python3.11/site-packages/django/core/handlers/base.py", line 204, in _get_response
    self.check_response(response, callback)
  File "/home/simprosys-aman/.local/lib/python3.11/site-packages/django/core/handlers/base.py", line 332, in check_response
    raise ValueError(
ValueError: The view frontapp.views.ProductList didn't return an HttpResponse object. It returned None instead.
2023-05-15 12:49:36,434 ERROR Internal Server Error: /front/productlist1/
Traceback (most recent call last):
  File "/home/simprosys-aman/.local/lib/python3.11/site-packages/django/core/handlers/exception.py", line 55, in inner
    response = get_response(request)
               ^^^^^^^^^^^^^^^^^^^^^
  File "/home/simprosys-aman/.local/lib/python3.11/site-packages/django/core/handlers/base.py", line 204, in _get_response
    self.check_response(response, callback)
  File "/home/simprosys-aman/.local/lib/python3.11/site-packages/django/core/handlers/base.py", line 332, in check_response
    raise ValueError(
ValueError: The view frontapp.views.ProductList didn't return an HttpResponse object. It returned None instead.
2023-05-15 12:49:36,630 ERROR Internal Server Error: /front/productlist1/
Traceback (most recent call last):
  File "/home/simprosys-aman/.local/lib/python3.11/site-packages/django/core/handlers/exception.py", line 55, in inner
    response = get_response(request)
               ^^^^^^^^^^^^^^^^^^^^^
  File "/home/simprosys-aman/.local/lib/python3.11/site-packages/django/core/handlers/base.py", line 204, in _get_response
    self.check_response(response, callback)
  File "/home/simprosys-aman/.local/lib/python3.11/site-packages/django/core/handlers/base.py", line 332, in check_response
    raise ValueError(
ValueError: The view frontapp.views.ProductList didn't return an HttpResponse object. It returned None instead.
2023-05-15 12:49:36,770 ERROR Internal Server Error: /front/productlist1/
Traceback (most recent call last):
  File "/home/simprosys-aman/.local/lib/python3.11/site-packages/django/core/handlers/exception.py", line 55, in inner
    response = get_response(request)
               ^^^^^^^^^^^^^^^^^^^^^
  File "/home/simprosys-aman/.local/lib/python3.11/site-packages/django/core/handlers/base.py", line 204, in _get_response
    self.check_response(response, callback)
  File "/home/simprosys-aman/.local/lib/python3.11/site-packages/django/core/handlers/base.py", line 332, in check_response
    raise ValueError(
ValueError: The view frontapp.views.ProductList didn't return an HttpResponse object. It returned None instead.
2023-05-15 12:55:10,456 ERROR Internal Server Error: /front/change_password/16814276-6903-4f92-a452-ab61ae09c85a
Traceback (most recent call last):
  File "/home/simprosys-aman/Aman/Aman/Practical/Shopify/frontapp/views.py", line 212, in change_password_with_token
    user_id_instence = User.objects.get(id=request.user.id)
                       ^^^^^^^^^^^^^^^^^^^^^^^^^^^^^^^^^^^^
  File "/home/simprosys-aman/.local/lib/python3.11/site-packages/django/db/models/manager.py", line 87, in manager_method
    return getattr(self.get_queryset(), name)(*args, **kwargs)
           ^^^^^^^^^^^^^^^^^^^^^^^^^^^^^^^^^^^^^^^^^^^^^^^^^^^
  File "/home/simprosys-aman/.local/lib/python3.11/site-packages/django/db/models/query.py", line 637, in get
    raise self.model.DoesNotExist(
django.contrib.auth.models.User.DoesNotExist: User matching query does not exist.

During handling of the above exception, another exception occurred:

Traceback (most recent call last):
  File "/home/simprosys-aman/.local/lib/python3.11/site-packages/django/core/handlers/exception.py", line 55, in inner
    response = get_response(request)
               ^^^^^^^^^^^^^^^^^^^^^
  File "/home/simprosys-aman/.local/lib/python3.11/site-packages/django/core/handlers/base.py", line 197, in _get_response
    response = wrapped_callback(request, *callback_args, **callback_kwargs)
               ^^^^^^^^^^^^^^^^^^^^^^^^^^^^^^^^^^^^^^^^^^^^^^^^^^^^^^^^^^^^
  File "/home/simprosys-aman/Aman/Aman/Practical/Shopify/frontapp/views.py", line 253, in change_password_with_token
    save_exception_to_database(request.user.id, "40", type(e), str(e), ip_address)
  File "/home/simprosys-aman/Aman/Aman/Practical/Shopify/frontapp/views.py", line 51, in save_exception_to_database
    user_id_instence = User.objects.get(id=user_id)
                       ^^^^^^^^^^^^^^^^^^^^^^^^^^^^
  File "/home/simprosys-aman/.local/lib/python3.11/site-packages/django/db/models/manager.py", line 87, in manager_method
    return getattr(self.get_queryset(), name)(*args, **kwargs)
           ^^^^^^^^^^^^^^^^^^^^^^^^^^^^^^^^^^^^^^^^^^^^^^^^^^^
  File "/home/simprosys-aman/.local/lib/python3.11/site-packages/django/db/models/query.py", line 637, in get
    raise self.model.DoesNotExist(
django.contrib.auth.models.User.DoesNotExist: User matching query does not exist.
