2023-05-17 04:34:33,145 ERROR Internal Server Error: /front/forgot-password/
Traceback (most recent call last):
  File "/home/simprosys-aman/Aman/Aman/Practical/Shopify/frontapp/views.py", line 260, in forgot_password_with_email
    profile_obj = Profile.objects.get(user=user_obj)
                  ^^^^^^^^^^^^^^^^^^^^^^^^^^^^^^^^^^
  File "/home/simprosys-aman/.local/lib/python3.11/site-packages/django/db/models/manager.py", line 87, in manager_method
    return getattr(self.get_queryset(), name)(*args, **kwargs)
           ^^^^^^^^^^^^^^^^^^^^^^^^^^^^^^^^^^^^^^^^^^^^^^^^^^^
  File "/home/simprosys-aman/.local/lib/python3.11/site-packages/django/db/models/query.py", line 637, in get
    raise self.model.DoesNotExist(
frontapp.models.Profile.DoesNotExist: Profile matching query does not exist.

During handling of the above exception, another exception occurred:

Traceback (most recent call last):
  File "/home/simprosys-aman/.local/lib/python3.11/site-packages/django/core/handlers/exception.py", line 55, in inner
    response = get_response(request)
               ^^^^^^^^^^^^^^^^^^^^^
  File "/home/simprosys-aman/.local/lib/python3.11/site-packages/django/core/handlers/base.py", line 197, in _get_response
    response = wrapped_callback(request, *callback_args, **callback_kwargs)
               ^^^^^^^^^^^^^^^^^^^^^^^^^^^^^^^^^^^^^^^^^^^^^^^^^^^^^^^^^^^^
  File "/home/simprosys-aman/Aman/Aman/Practical/Shopify/frontapp/views.py", line 283, in forgot_password_with_email
    save_exception_to_database(request.user.id, "40", type(e), str(e), ip_address)
  File "/home/simprosys-aman/Aman/Aman/Practical/Shopify/frontapp/views.py", line 51, in save_exception_to_database
    user_id_instence = User.objects.get(id=user_id)
                       ^^^^^^^^^^^^^^^^^^^^^^^^^^^^
  File "/home/simprosys-aman/.local/lib/python3.11/site-packages/django/db/models/manager.py", line 87, in manager_method
    return getattr(self.get_queryset(), name)(*args, **kwargs)
           ^^^^^^^^^^^^^^^^^^^^^^^^^^^^^^^^^^^^^^^^^^^^^^^^^^^
  File "/home/simprosys-aman/.local/lib/python3.11/site-packages/django/db/models/query.py", line 637, in get
    raise self.model.DoesNotExist(
django.contrib.auth.models.User.DoesNotExist: User matching query does not exist.
2023-05-17 04:37:14,132 ERROR Internal Server Error: /front/forgot-password/
Traceback (most recent call last):
  File "/home/simprosys-aman/Aman/Aman/Practical/Shopify/frontapp/views.py", line 265, in forgot_password_with_email
    profile_obj = Profile.objects.get(user=user_obj)
                  ^^^^^^^^^^^^^^^^^^^^^^^^^^^^^^^^^^
  File "/home/simprosys-aman/.local/lib/python3.11/site-packages/django/db/models/manager.py", line 87, in manager_method
    return getattr(self.get_queryset(), name)(*args, **kwargs)
           ^^^^^^^^^^^^^^^^^^^^^^^^^^^^^^^^^^^^^^^^^^^^^^^^^^^
  File "/home/simprosys-aman/.local/lib/python3.11/site-packages/django/db/models/query.py", line 637, in get
    raise self.model.DoesNotExist(
frontapp.models.Profile.DoesNotExist: Profile matching query does not exist.

During handling of the above exception, another exception occurred:

Traceback (most recent call last):
  File "/home/simprosys-aman/.local/lib/python3.11/site-packages/django/core/handlers/exception.py", line 55, in inner
    response = get_response(request)
               ^^^^^^^^^^^^^^^^^^^^^
  File "/home/simprosys-aman/.local/lib/python3.11/site-packages/django/core/handlers/base.py", line 197, in _get_response
    response = wrapped_callback(request, *callback_args, **callback_kwargs)
               ^^^^^^^^^^^^^^^^^^^^^^^^^^^^^^^^^^^^^^^^^^^^^^^^^^^^^^^^^^^^
  File "/home/simprosys-aman/Aman/Aman/Practical/Shopify/frontapp/views.py", line 288, in forgot_password_with_email
    save_exception_to_database(request.user.id, "40", type(e), str(e), ip_address)
  File "/home/simprosys-aman/Aman/Aman/Practical/Shopify/frontapp/views.py", line 51, in save_exception_to_database
    user_id_instence = User.objects.get(id=user_id)
                       ^^^^^^^^^^^^^^^^^^^^^^^^^^^^
  File "/home/simprosys-aman/.local/lib/python3.11/site-packages/django/db/models/manager.py", line 87, in manager_method
    return getattr(self.get_queryset(), name)(*args, **kwargs)
           ^^^^^^^^^^^^^^^^^^^^^^^^^^^^^^^^^^^^^^^^^^^^^^^^^^^
  File "/home/simprosys-aman/.local/lib/python3.11/site-packages/django/db/models/query.py", line 637, in get
    raise self.model.DoesNotExist(
django.contrib.auth.models.User.DoesNotExist: User matching query does not exist.
