2023-05-16 04:04:55,974 ERROR Internal Server Error: /front/forgot-password/
Traceback (most recent call last):
  File "/home/simprosys-aman/Aman/Aman/Practical/Shopify/frontapp/views.py", line 260, in forgot_password_with_email
    import ssss
ModuleNotFoundError: No module named 'ssss'

During handling of the above exception, another exception occurred:

Traceback (most recent call last):
  File "/home/simprosys-aman/.local/lib/python3.11/site-packages/django/core/handlers/exception.py", line 55, in inner
    response = get_response(request)
               ^^^^^^^^^^^^^^^^^^^^^
  File "/home/simprosys-aman/.local/lib/python3.11/site-packages/django/core/handlers/base.py", line 197, in _get_response
    response = wrapped_callback(request, *callback_args, **callback_kwargs)
               ^^^^^^^^^^^^^^^^^^^^^^^^^^^^^^^^^^^^^^^^^^^^^^^^^^^^^^^^^^^^
  File "/home/simprosys-aman/Aman/Aman/Practical/Shopify/frontapp/views.py", line 284, in forgot_password_with_email
    save_exception_to_database(request.user.id, "40", type(e), str(e), ip_address)
  File "/home/simprosys-aman/Aman/Aman/Practical/Shopify/frontapp/views.py", line 51, in save_exception_to_database
    user_id_instence = User.objects.get(id=user_id)
                       ^^^^^^^^^^^^^^^^^^^^^^^^^^^^
  File "/home/simprosys-aman/.local/lib/python3.11/site-packages/django/db/models/manager.py", line 87, in manager_method
    return getattr(self.get_queryset(), name)(*args, **kwargs)
           ^^^^^^^^^^^^^^^^^^^^^^^^^^^^^^^^^^^^^^^^^^^^^^^^^^^
  File "/home/simprosys-aman/.local/lib/python3.11/site-packages/django/db/models/query.py", line 637, in get
    raise self.model.DoesNotExist(
django.contrib.auth.models.User.DoesNotExist: User matching query does not exist.
2023-05-16 04:05:01,415 ERROR Internal Server Error: /front/forgot-password/
Traceback (most recent call last):
  File "/home/simprosys-aman/Aman/Aman/Practical/Shopify/frontapp/views.py", line 260, in forgot_password_with_email
    import ssss
ModuleNotFoundError: No module named 'ssss'

During handling of the above exception, another exception occurred:

Traceback (most recent call last):
  File "/home/simprosys-aman/.local/lib/python3.11/site-packages/django/core/handlers/exception.py", line 55, in inner
    response = get_response(request)
               ^^^^^^^^^^^^^^^^^^^^^
  File "/home/simprosys-aman/.local/lib/python3.11/site-packages/django/core/handlers/base.py", line 197, in _get_response
    response = wrapped_callback(request, *callback_args, **callback_kwargs)
               ^^^^^^^^^^^^^^^^^^^^^^^^^^^^^^^^^^^^^^^^^^^^^^^^^^^^^^^^^^^^
  File "/home/simprosys-aman/Aman/Aman/Practical/Shopify/frontapp/views.py", line 284, in forgot_password_with_email
    save_exception_to_database(request.user.id, "40", type(e), str(e), ip_address)
  File "/home/simprosys-aman/Aman/Aman/Practical/Shopify/frontapp/views.py", line 51, in save_exception_to_database
    user_id_instence = User.objects.get(id=user_id)
                       ^^^^^^^^^^^^^^^^^^^^^^^^^^^^
  File "/home/simprosys-aman/.local/lib/python3.11/site-packages/django/db/models/manager.py", line 87, in manager_method
    return getattr(self.get_queryset(), name)(*args, **kwargs)
           ^^^^^^^^^^^^^^^^^^^^^^^^^^^^^^^^^^^^^^^^^^^^^^^^^^^
  File "/home/simprosys-aman/.local/lib/python3.11/site-packages/django/db/models/query.py", line 637, in get
    raise self.model.DoesNotExist(
django.contrib.auth.models.User.DoesNotExist: User matching query does not exist.
2023-05-16 04:15:30,269 ERROR Internal Server Error: /front/forgot-password/
Traceback (most recent call last):
  File "/home/simprosys-aman/Aman/Aman/Practical/Shopify/frontapp/views.py", line 260, in forgot_password_with_email
    import ssss
ModuleNotFoundError: No module named 'ssss'

During handling of the above exception, another exception occurred:

Traceback (most recent call last):
  File "/home/simprosys-aman/.local/lib/python3.11/site-packages/django/core/handlers/exception.py", line 55, in inner
    response = get_response(request)
               ^^^^^^^^^^^^^^^^^^^^^
  File "/home/simprosys-aman/.local/lib/python3.11/site-packages/django/core/handlers/base.py", line 197, in _get_response
    response = wrapped_callback(request, *callback_args, **callback_kwargs)
               ^^^^^^^^^^^^^^^^^^^^^^^^^^^^^^^^^^^^^^^^^^^^^^^^^^^^^^^^^^^^
  File "/home/simprosys-aman/Aman/Aman/Practical/Shopify/frontapp/views.py", line 290, in forgot_password_with_email
    save_exception_to_database(user_id,exception_code, exception_type, exception_message, IP)
  File "/home/simprosys-aman/Aman/Aman/Practical/Shopify/frontapp/views.py", line 51, in save_exception_to_database
    user_id_instence = User.objects.get(id=user_id)
                       ^^^^^^^^^^^^^^^^^^^^^^^^^^^^
  File "/home/simprosys-aman/.local/lib/python3.11/site-packages/django/db/models/manager.py", line 87, in manager_method
    return getattr(self.get_queryset(), name)(*args, **kwargs)
           ^^^^^^^^^^^^^^^^^^^^^^^^^^^^^^^^^^^^^^^^^^^^^^^^^^^
  File "/home/simprosys-aman/.local/lib/python3.11/site-packages/django/db/models/query.py", line 637, in get
    raise self.model.DoesNotExist(
django.contrib.auth.models.User.DoesNotExist: User matching query does not exist.
2023-05-16 04:15:35,730 ERROR Internal Server Error: /front/forgot-password/
Traceback (most recent call last):
  File "/home/simprosys-aman/Aman/Aman/Practical/Shopify/frontapp/views.py", line 260, in forgot_password_with_email
    import ssss
ModuleNotFoundError: No module named 'ssss'

During handling of the above exception, another exception occurred:

Traceback (most recent call last):
  File "/home/simprosys-aman/.local/lib/python3.11/site-packages/django/core/handlers/exception.py", line 55, in inner
    response = get_response(request)
               ^^^^^^^^^^^^^^^^^^^^^
  File "/home/simprosys-aman/.local/lib/python3.11/site-packages/django/core/handlers/base.py", line 197, in _get_response
    response = wrapped_callback(request, *callback_args, **callback_kwargs)
               ^^^^^^^^^^^^^^^^^^^^^^^^^^^^^^^^^^^^^^^^^^^^^^^^^^^^^^^^^^^^
  File "/home/simprosys-aman/Aman/Aman/Practical/Shopify/frontapp/views.py", line 290, in forgot_password_with_email
    save_exception_to_database(user_id,exception_code, exception_type, exception_message, IP)
  File "/home/simprosys-aman/Aman/Aman/Practical/Shopify/frontapp/views.py", line 51, in save_exception_to_database
    user_id_instence = User.objects.get(id=user_id)
                       ^^^^^^^^^^^^^^^^^^^^^^^^^^^^
  File "/home/simprosys-aman/.local/lib/python3.11/site-packages/django/db/models/manager.py", line 87, in manager_method
    return getattr(self.get_queryset(), name)(*args, **kwargs)
           ^^^^^^^^^^^^^^^^^^^^^^^^^^^^^^^^^^^^^^^^^^^^^^^^^^^
  File "/home/simprosys-aman/.local/lib/python3.11/site-packages/django/db/models/query.py", line 637, in get
    raise self.model.DoesNotExist(
django.contrib.auth.models.User.DoesNotExist: User matching query does not exist.
2023-05-16 04:16:12,055 ERROR Internal Server Error: /front/forgot-password/
Traceback (most recent call last):
  File "/home/simprosys-aman/Aman/Aman/Practical/Shopify/frontapp/views.py", line 260, in forgot_password_with_email
    import ssss
ModuleNotFoundError: No module named 'ssss'

During handling of the above exception, another exception occurred:

Traceback (most recent call last):
  File "/home/simprosys-aman/.local/lib/python3.11/site-packages/django/core/handlers/exception.py", line 55, in inner
    response = get_response(request)
               ^^^^^^^^^^^^^^^^^^^^^
  File "/home/simprosys-aman/.local/lib/python3.11/site-packages/django/core/handlers/base.py", line 197, in _get_response
    response = wrapped_callback(request, *callback_args, **callback_kwargs)
               ^^^^^^^^^^^^^^^^^^^^^^^^^^^^^^^^^^^^^^^^^^^^^^^^^^^^^^^^^^^^
  File "/home/simprosys-aman/Aman/Aman/Practical/Shopify/frontapp/views.py", line 285, in forgot_password_with_email
    user_id = username
              ^^^^^^^^
UnboundLocalError: cannot access local variable 'username' where it is not associated with a value
2023-05-16 04:24:36,572 ERROR Internal Server Error: /front/csv_import/
Traceback (most recent call last):
  File "/home/simprosys-aman/.local/lib/python3.11/site-packages/django/core/handlers/exception.py", line 55, in inner
    response = get_response(request)
               ^^^^^^^^^^^^^^^^^^^^^
  File "/home/simprosys-aman/.local/lib/python3.11/site-packages/django/core/handlers/base.py", line 204, in _get_response
    self.check_response(response, callback)
  File "/home/simprosys-aman/.local/lib/python3.11/site-packages/django/core/handlers/base.py", line 332, in check_response
    raise ValueError(
ValueError: The view frontapp.views.import_csv_with_thread didn't return an HttpResponse object. It returned None instead.
2023-05-16 04:24:55,028 ERROR Internal Server Error: /front/csv_import/
Traceback (most recent call last):
  File "/home/simprosys-aman/.local/lib/python3.11/site-packages/django/core/handlers/exception.py", line 55, in inner
    response = get_response(request)
               ^^^^^^^^^^^^^^^^^^^^^
  File "/home/simprosys-aman/.local/lib/python3.11/site-packages/django/core/handlers/base.py", line 204, in _get_response
    self.check_response(response, callback)
  File "/home/simprosys-aman/.local/lib/python3.11/site-packages/django/core/handlers/base.py", line 332, in check_response
    raise ValueError(
ValueError: The view frontapp.views.import_csv_with_thread didn't return an HttpResponse object. It returned None instead.
2023-05-16 04:26:20,970 ERROR Internal Server Error: /front/csv_import/
Traceback (most recent call last):
  File "/home/simprosys-aman/.local/lib/python3.11/site-packages/django/core/handlers/exception.py", line 55, in inner
    response = get_response(request)
               ^^^^^^^^^^^^^^^^^^^^^
  File "/home/simprosys-aman/.local/lib/python3.11/site-packages/django/core/handlers/base.py", line 204, in _get_response
    self.check_response(response, callback)
  File "/home/simprosys-aman/.local/lib/python3.11/site-packages/django/core/handlers/base.py", line 332, in check_response
    raise ValueError(
ValueError: The view frontapp.views.import_csv_with_thread didn't return an HttpResponse object. It returned None instead.
2023-05-16 04:26:58,514 ERROR Internal Server Error: /front/csv_import/
Traceback (most recent call last):
  File "/home/simprosys-aman/.local/lib/python3.11/site-packages/django/core/handlers/exception.py", line 55, in inner
    response = get_response(request)
               ^^^^^^^^^^^^^^^^^^^^^
  File "/home/simprosys-aman/.local/lib/python3.11/site-packages/django/core/handlers/base.py", line 204, in _get_response
    self.check_response(response, callback)
  File "/home/simprosys-aman/.local/lib/python3.11/site-packages/django/core/handlers/base.py", line 332, in check_response
    raise ValueError(
ValueError: The view frontapp.views.import_csv_with_thread didn't return an HttpResponse object. It returned None instead.
2023-05-16 04:27:12,448 ERROR Internal Server Error: /front/csv_import/
Traceback (most recent call last):
  File "/home/simprosys-aman/.local/lib/python3.11/site-packages/django/core/handlers/exception.py", line 55, in inner
    response = get_response(request)
               ^^^^^^^^^^^^^^^^^^^^^
  File "/home/simprosys-aman/.local/lib/python3.11/site-packages/django/core/handlers/base.py", line 204, in _get_response
    self.check_response(response, callback)
  File "/home/simprosys-aman/.local/lib/python3.11/site-packages/django/core/handlers/base.py", line 332, in check_response
    raise ValueError(
ValueError: The view frontapp.views.import_csv_with_thread didn't return an HttpResponse object. It returned None instead.
2023-05-16 04:28:17,631 ERROR Internal Server Error: /front/csv_import/
Traceback (most recent call last):
  File "/home/simprosys-aman/.local/lib/python3.11/site-packages/django/core/handlers/exception.py", line 55, in inner
    response = get_response(request)
               ^^^^^^^^^^^^^^^^^^^^^
  File "/home/simprosys-aman/.local/lib/python3.11/site-packages/django/core/handlers/base.py", line 204, in _get_response
    self.check_response(response, callback)
  File "/home/simprosys-aman/.local/lib/python3.11/site-packages/django/core/handlers/base.py", line 332, in check_response
    raise ValueError(
ValueError: The view frontapp.views.import_csv_with_thread didn't return an HttpResponse object. It returned None instead.
2023-05-16 04:28:27,080 ERROR Internal Server Error: /front/csv_import/
Traceback (most recent call last):
  File "/home/simprosys-aman/.local/lib/python3.11/site-packages/django/core/handlers/exception.py", line 55, in inner
    response = get_response(request)
               ^^^^^^^^^^^^^^^^^^^^^
  File "/home/simprosys-aman/.local/lib/python3.11/site-packages/django/core/handlers/base.py", line 204, in _get_response
    self.check_response(response, callback)
  File "/home/simprosys-aman/.local/lib/python3.11/site-packages/django/core/handlers/base.py", line 332, in check_response
    raise ValueError(
ValueError: The view frontapp.views.import_csv_with_thread didn't return an HttpResponse object. It returned None instead.
2023-05-16 04:29:58,237 ERROR Internal Server Error: /front/csv_import/
Traceback (most recent call last):
  File "/home/simprosys-aman/Aman/Aman/Practical/Shopify/frontapp/views.py", line 447, in import_csv_with_thread
    import_data_from_csv(file_data)
  File "/home/simprosys-aman/.local/lib/python3.11/site-packages/django/contrib/auth/decorators.py", line 22, in _wrapper_view
    if test_func(request.user):
                 ^^^^^^^^^^^^
AttributeError: 'bytes' object has no attribute 'user'

During handling of the above exception, another exception occurred:

Traceback (most recent call last):
  File "/home/simprosys-aman/.local/lib/python3.11/site-packages/django/core/handlers/exception.py", line 55, in inner
    response = get_response(request)
               ^^^^^^^^^^^^^^^^^^^^^
  File "/home/simprosys-aman/.local/lib/python3.11/site-packages/django/core/handlers/base.py", line 197, in _get_response
    response = wrapped_callback(request, *callback_args, **callback_kwargs)
               ^^^^^^^^^^^^^^^^^^^^^^^^^^^^^^^^^^^^^^^^^^^^^^^^^^^^^^^^^^^^
  File "/home/simprosys-aman/.local/lib/python3.11/site-packages/django/contrib/auth/decorators.py", line 23, in _wrapper_view
    return view_func(request, *args, **kwargs)
           ^^^^^^^^^^^^^^^^^^^^^^^^^^^^^^^^^^^
  File "/home/simprosys-aman/Aman/Aman/Practical/Shopify/frontapp/views.py", line 461, in import_csv_with_thread
    IP = ip_addres()
         ^^^^^^^^^^^
TypeError: 'str' object is not callable
2023-05-16 04:30:26,843 ERROR Internal Server Error: /front/csv_import/
Traceback (most recent call last):
  File "/home/simprosys-aman/.local/lib/python3.11/site-packages/django/core/handlers/exception.py", line 55, in inner
    response = get_response(request)
               ^^^^^^^^^^^^^^^^^^^^^
  File "/home/simprosys-aman/.local/lib/python3.11/site-packages/django/core/handlers/base.py", line 197, in _get_response
    response = wrapped_callback(request, *callback_args, **callback_kwargs)
               ^^^^^^^^^^^^^^^^^^^^^^^^^^^^^^^^^^^^^^^^^^^^^^^^^^^^^^^^^^^^
  File "/home/simprosys-aman/.local/lib/python3.11/site-packages/django/contrib/auth/decorators.py", line 23, in _wrapper_view
    return view_func(request, *args, **kwargs)
           ^^^^^^^^^^^^^^^^^^^^^^^^^^^^^^^^^^^
  File "/home/simprosys-aman/Aman/Aman/Practical/Shopify/frontapp/views.py", line 464, in import_csv_with_thread
    return redirect("import_csv_file",messages=messages)
           ^^^^^^^^^^^^^^^^^^^^^^^^^^^^^^^^^^^^^^^^^^^^^
  File "/home/simprosys-aman/.local/lib/python3.11/site-packages/django/shortcuts.py", line 48, in redirect
    return redirect_class(resolve_url(to, *args, **kwargs))
                          ^^^^^^^^^^^^^^^^^^^^^^^^^^^^^^^^
  File "/home/simprosys-aman/.local/lib/python3.11/site-packages/django/shortcuts.py", line 145, in resolve_url
    return reverse(to, args=args, kwargs=kwargs)
           ^^^^^^^^^^^^^^^^^^^^^^^^^^^^^^^^^^^^^
  File "/home/simprosys-aman/.local/lib/python3.11/site-packages/django/urls/base.py", line 88, in reverse
    return resolver._reverse_with_prefix(view, prefix, *args, **kwargs)
           ^^^^^^^^^^^^^^^^^^^^^^^^^^^^^^^^^^^^^^^^^^^^^^^^^^^^^^^^^^^^
  File "/home/simprosys-aman/.local/lib/python3.11/site-packages/django/urls/resolvers.py", line 828, in _reverse_with_prefix
    raise NoReverseMatch(msg)
django.urls.exceptions.NoReverseMatch: Reverse for 'import_csv_file' not found. 'import_csv_file' is not a valid view function or pattern name.
2023-05-16 04:31:11,279 ERROR Internal Server Error: /front/csv_import/
Traceback (most recent call last):
  File "/home/simprosys-aman/.local/lib/python3.11/site-packages/django/core/handlers/exception.py", line 55, in inner
    response = get_response(request)
               ^^^^^^^^^^^^^^^^^^^^^
  File "/home/simprosys-aman/.local/lib/python3.11/site-packages/django/core/handlers/base.py", line 197, in _get_response
    response = wrapped_callback(request, *callback_args, **callback_kwargs)
               ^^^^^^^^^^^^^^^^^^^^^^^^^^^^^^^^^^^^^^^^^^^^^^^^^^^^^^^^^^^^
  File "/home/simprosys-aman/.local/lib/python3.11/site-packages/django/contrib/auth/decorators.py", line 23, in _wrapper_view
    return view_func(request, *args, **kwargs)
           ^^^^^^^^^^^^^^^^^^^^^^^^^^^^^^^^^^^
  File "/home/simprosys-aman/Aman/Aman/Practical/Shopify/frontapp/views.py", line 464, in import_csv_with_thread
    return render(request, "temp/import_csv.html",messages=messages)
           ^^^^^^^^^^^^^^^^^^^^^^^^^^^^^^^^^^^^^^^^^^^^^^^^^^^^^^^^^
TypeError: render() got an unexpected keyword argument 'messages'
2023-05-16 04:39:51,274 ERROR Internal Server Error: /front/csv_import/
Traceback (most recent call last):
  File "/home/simprosys-aman/.local/lib/python3.11/site-packages/django/core/handlers/exception.py", line 55, in inner
    response = get_response(request)
               ^^^^^^^^^^^^^^^^^^^^^
  File "/home/simprosys-aman/.local/lib/python3.11/site-packages/django/core/handlers/base.py", line 204, in _get_response
    self.check_response(response, callback)
  File "/home/simprosys-aman/.local/lib/python3.11/site-packages/django/core/handlers/base.py", line 332, in check_response
    raise ValueError(
ValueError: The view frontapp.views.import_csv_with_thread didn't return an HttpResponse object. It returned None instead.
2023-05-16 04:40:08,928 ERROR Internal Server Error: /front/csv_import/
Traceback (most recent call last):
  File "/home/simprosys-aman/.local/lib/python3.11/site-packages/django/core/handlers/exception.py", line 55, in inner
    response = get_response(request)
               ^^^^^^^^^^^^^^^^^^^^^
  File "/home/simprosys-aman/.local/lib/python3.11/site-packages/django/core/handlers/base.py", line 197, in _get_response
    response = wrapped_callback(request, *callback_args, **callback_kwargs)
               ^^^^^^^^^^^^^^^^^^^^^^^^^^^^^^^^^^^^^^^^^^^^^^^^^^^^^^^^^^^^
  File "/home/simprosys-aman/.local/lib/python3.11/site-packages/django/contrib/auth/decorators.py", line 23, in _wrapper_view
    return view_func(request, *args, **kwargs)
           ^^^^^^^^^^^^^^^^^^^^^^^^^^^^^^^^^^^
  File "/home/simprosys-aman/Aman/Aman/Practical/Shopify/frontapp/views.py", line 429, in import_csv_with_thread
    import_data_from_csv(file_data)
  File "/home/simprosys-aman/.local/lib/python3.11/site-packages/django/contrib/auth/decorators.py", line 22, in _wrapper_view
    if test_func(request.user):
                 ^^^^^^^^^^^^
AttributeError: 'bytes' object has no attribute 'user'
2023-05-16 04:42:38,819 ERROR Internal Server Error: /front/csv_import/
Traceback (most recent call last):
  File "/home/simprosys-aman/.local/lib/python3.11/site-packages/django/core/handlers/exception.py", line 55, in inner
    response = get_response(request)
               ^^^^^^^^^^^^^^^^^^^^^
  File "/home/simprosys-aman/.local/lib/python3.11/site-packages/django/core/handlers/base.py", line 197, in _get_response
    response = wrapped_callback(request, *callback_args, **callback_kwargs)
               ^^^^^^^^^^^^^^^^^^^^^^^^^^^^^^^^^^^^^^^^^^^^^^^^^^^^^^^^^^^^
  File "/home/simprosys-aman/Aman/Aman/Practical/Shopify/frontapp/views.py", line 429, in import_csv_with_thread
    import_data_from_csv(file_data)
  File "/home/simprosys-aman/.local/lib/python3.11/site-packages/django/contrib/auth/decorators.py", line 22, in _wrapper_view
    if test_func(request.user):
                 ^^^^^^^^^^^^
AttributeError: 'bytes' object has no attribute 'user'
2023-05-16 04:45:37,770 ERROR Internal Server Error: /front/csv_import/
Traceback (most recent call last):
  File "/home/simprosys-aman/.local/lib/python3.11/site-packages/django/core/handlers/exception.py", line 55, in inner
    response = get_response(request)
               ^^^^^^^^^^^^^^^^^^^^^
  File "/home/simprosys-aman/.local/lib/python3.11/site-packages/django/core/handlers/base.py", line 197, in _get_response
    response = wrapped_callback(request, *callback_args, **callback_kwargs)
               ^^^^^^^^^^^^^^^^^^^^^^^^^^^^^^^^^^^^^^^^^^^^^^^^^^^^^^^^^^^^
  File "/home/simprosys-aman/.local/lib/python3.11/site-packages/django/contrib/auth/decorators.py", line 23, in _wrapper_view
    return view_func(request, *args, **kwargs)
           ^^^^^^^^^^^^^^^^^^^^^^^^^^^^^^^^^^^
  File "/home/simprosys-aman/Aman/Aman/Practical/Shopify/frontapp/views.py", line 442, in import_csv_with_thread
    save_exception_to_database(request.user.id, "40", type(e), str(e), ip_address)
                                                           ^
UnboundLocalError: cannot access local variable 'e' where it is not associated with a value
2023-05-16 04:45:55,565 ERROR Internal Server Error: /front/csv_import/
Traceback (most recent call last):
  File "/home/simprosys-aman/.local/lib/python3.11/site-packages/django/core/handlers/exception.py", line 55, in inner
    response = get_response(request)
               ^^^^^^^^^^^^^^^^^^^^^
  File "/home/simprosys-aman/.local/lib/python3.11/site-packages/django/core/handlers/base.py", line 204, in _get_response
    self.check_response(response, callback)
  File "/home/simprosys-aman/.local/lib/python3.11/site-packages/django/core/handlers/base.py", line 332, in check_response
    raise ValueError(
ValueError: The view frontapp.views.import_csv_with_thread didn't return an HttpResponse object. It returned None instead.
2023-05-16 04:55:14,383 ERROR Internal Server Error: /front/data_to_pdf/
Traceback (most recent call last):
  File "/home/simprosys-aman/.local/lib/python3.11/site-packages/django/core/handlers/exception.py", line 55, in inner
    response = get_response(request)
               ^^^^^^^^^^^^^^^^^^^^^
  File "/home/simprosys-aman/.local/lib/python3.11/site-packages/django/core/handlers/base.py", line 204, in _get_response
    self.check_response(response, callback)
  File "/home/simprosys-aman/.local/lib/python3.11/site-packages/django/core/handlers/base.py", line 332, in check_response
    raise ValueError(
ValueError: The view frontapp.views.generate_pdf didn't return an HttpResponse object. It returned None instead.
2023-05-16 04:55:27,157 ERROR Internal Server Error: /front/data_to_pdf/
Traceback (most recent call last):
  File "/home/simprosys-aman/.local/lib/python3.11/site-packages/django/core/handlers/exception.py", line 55, in inner
    response = get_response(request)
               ^^^^^^^^^^^^^^^^^^^^^
  File "/home/simprosys-aman/.local/lib/python3.11/site-packages/django/core/handlers/base.py", line 204, in _get_response
    self.check_response(response, callback)
  File "/home/simprosys-aman/.local/lib/python3.11/site-packages/django/core/handlers/base.py", line 332, in check_response
    raise ValueError(
ValueError: The view frontapp.views.generate_pdf didn't return an HttpResponse object. It returned None instead.
2023-05-16 04:55:27,386 ERROR Internal Server Error: /front/data_to_pdf/
Traceback (most recent call last):
  File "/home/simprosys-aman/.local/lib/python3.11/site-packages/django/core/handlers/exception.py", line 55, in inner
    response = get_response(request)
               ^^^^^^^^^^^^^^^^^^^^^
  File "/home/simprosys-aman/.local/lib/python3.11/site-packages/django/core/handlers/base.py", line 204, in _get_response
    self.check_response(response, callback)
  File "/home/simprosys-aman/.local/lib/python3.11/site-packages/django/core/handlers/base.py", line 332, in check_response
    raise ValueError(
ValueError: The view frontapp.views.generate_pdf didn't return an HttpResponse object. It returned None instead.
2023-05-16 04:55:27,792 ERROR Internal Server Error: /front/data_to_pdf/
Traceback (most recent call last):
  File "/home/simprosys-aman/.local/lib/python3.11/site-packages/django/core/handlers/exception.py", line 55, in inner
    response = get_response(request)
               ^^^^^^^^^^^^^^^^^^^^^
  File "/home/simprosys-aman/.local/lib/python3.11/site-packages/django/core/handlers/base.py", line 204, in _get_response
    self.check_response(response, callback)
  File "/home/simprosys-aman/.local/lib/python3.11/site-packages/django/core/handlers/base.py", line 332, in check_response
    raise ValueError(
ValueError: The view frontapp.views.generate_pdf didn't return an HttpResponse object. It returned None instead.
2023-05-16 04:55:28,088 ERROR Internal Server Error: /front/data_to_pdf/
Traceback (most recent call last):
  File "/home/simprosys-aman/.local/lib/python3.11/site-packages/django/core/handlers/exception.py", line 55, in inner
    response = get_response(request)
               ^^^^^^^^^^^^^^^^^^^^^
  File "/home/simprosys-aman/.local/lib/python3.11/site-packages/django/core/handlers/base.py", line 204, in _get_response
    self.check_response(response, callback)
  File "/home/simprosys-aman/.local/lib/python3.11/site-packages/django/core/handlers/base.py", line 332, in check_response
    raise ValueError(
ValueError: The view frontapp.views.generate_pdf didn't return an HttpResponse object. It returned None instead.
2023-05-16 04:55:28,278 ERROR Internal Server Error: /front/data_to_pdf/
Traceback (most recent call last):
  File "/home/simprosys-aman/.local/lib/python3.11/site-packages/django/core/handlers/exception.py", line 55, in inner
    response = get_response(request)
               ^^^^^^^^^^^^^^^^^^^^^
  File "/home/simprosys-aman/.local/lib/python3.11/site-packages/django/core/handlers/base.py", line 204, in _get_response
    self.check_response(response, callback)
  File "/home/simprosys-aman/.local/lib/python3.11/site-packages/django/core/handlers/base.py", line 332, in check_response
    raise ValueError(
ValueError: The view frontapp.views.generate_pdf didn't return an HttpResponse object. It returned None instead.
2023-05-16 04:55:28,475 ERROR Internal Server Error: /front/data_to_pdf/
Traceback (most recent call last):
  File "/home/simprosys-aman/.local/lib/python3.11/site-packages/django/core/handlers/exception.py", line 55, in inner
    response = get_response(request)
               ^^^^^^^^^^^^^^^^^^^^^
  File "/home/simprosys-aman/.local/lib/python3.11/site-packages/django/core/handlers/base.py", line 204, in _get_response
    self.check_response(response, callback)
  File "/home/simprosys-aman/.local/lib/python3.11/site-packages/django/core/handlers/base.py", line 332, in check_response
    raise ValueError(
ValueError: The view frontapp.views.generate_pdf didn't return an HttpResponse object. It returned None instead.
2023-05-16 04:55:28,673 ERROR Internal Server Error: /front/data_to_pdf/
Traceback (most recent call last):
  File "/home/simprosys-aman/.local/lib/python3.11/site-packages/django/core/handlers/exception.py", line 55, in inner
    response = get_response(request)
               ^^^^^^^^^^^^^^^^^^^^^
  File "/home/simprosys-aman/.local/lib/python3.11/site-packages/django/core/handlers/base.py", line 204, in _get_response
    self.check_response(response, callback)
  File "/home/simprosys-aman/.local/lib/python3.11/site-packages/django/core/handlers/base.py", line 332, in check_response
    raise ValueError(
ValueError: The view frontapp.views.generate_pdf didn't return an HttpResponse object. It returned None instead.
2023-05-16 04:56:08,561 ERROR Internal Server Error: /front/data_to_pdf/
Traceback (most recent call last):
  File "/home/simprosys-aman/.local/lib/python3.11/site-packages/django/core/handlers/exception.py", line 55, in inner
    response = get_response(request)
               ^^^^^^^^^^^^^^^^^^^^^
  File "/home/simprosys-aman/.local/lib/python3.11/site-packages/django/core/handlers/base.py", line 204, in _get_response
    self.check_response(response, callback)
  File "/home/simprosys-aman/.local/lib/python3.11/site-packages/django/core/handlers/base.py", line 332, in check_response
    raise ValueError(
ValueError: The view frontapp.views.generate_pdf didn't return an HttpResponse object. It returned None instead.
2023-05-16 04:56:12,134 ERROR Internal Server Error: /front/data_to_pdf/
Traceback (most recent call last):
  File "/home/simprosys-aman/.local/lib/python3.11/site-packages/django/core/handlers/exception.py", line 55, in inner
    response = get_response(request)
               ^^^^^^^^^^^^^^^^^^^^^
  File "/home/simprosys-aman/.local/lib/python3.11/site-packages/django/core/handlers/base.py", line 204, in _get_response
    self.check_response(response, callback)
  File "/home/simprosys-aman/.local/lib/python3.11/site-packages/django/core/handlers/base.py", line 332, in check_response
    raise ValueError(
ValueError: The view frontapp.views.generate_pdf didn't return an HttpResponse object. It returned None instead.
2023-05-16 04:56:13,657 ERROR Internal Server Error: /front/data_to_pdf/
Traceback (most recent call last):
  File "/home/simprosys-aman/.local/lib/python3.11/site-packages/django/core/handlers/exception.py", line 55, in inner
    response = get_response(request)
               ^^^^^^^^^^^^^^^^^^^^^
  File "/home/simprosys-aman/.local/lib/python3.11/site-packages/django/core/handlers/base.py", line 204, in _get_response
    self.check_response(response, callback)
  File "/home/simprosys-aman/.local/lib/python3.11/site-packages/django/core/handlers/base.py", line 332, in check_response
    raise ValueError(
ValueError: The view frontapp.views.generate_pdf didn't return an HttpResponse object. It returned None instead.
2023-05-16 04:56:14,615 ERROR Internal Server Error: /front/data_to_pdf/
Traceback (most recent call last):
  File "/home/simprosys-aman/.local/lib/python3.11/site-packages/django/core/handlers/exception.py", line 55, in inner
    response = get_response(request)
               ^^^^^^^^^^^^^^^^^^^^^
  File "/home/simprosys-aman/.local/lib/python3.11/site-packages/django/core/handlers/base.py", line 204, in _get_response
    self.check_response(response, callback)
  File "/home/simprosys-aman/.local/lib/python3.11/site-packages/django/core/handlers/base.py", line 332, in check_response
    raise ValueError(
ValueError: The view frontapp.views.generate_pdf didn't return an HttpResponse object. It returned None instead.
2023-05-16 05:04:08,057 ERROR Internal Server Error: /front/data_to_pdf/
Traceback (most recent call last):
  File "/home/simprosys-aman/.local/lib/python3.11/site-packages/django/core/handlers/exception.py", line 55, in inner
    response = get_response(request)
               ^^^^^^^^^^^^^^^^^^^^^
  File "/home/simprosys-aman/.local/lib/python3.11/site-packages/django/core/handlers/base.py", line 204, in _get_response
    self.check_response(response, callback)
  File "/home/simprosys-aman/.local/lib/python3.11/site-packages/django/core/handlers/base.py", line 332, in check_response
    raise ValueError(
ValueError: The view frontapp.views.generate_pdf didn't return an HttpResponse object. It returned None instead.
2023-05-16 05:04:10,780 ERROR Internal Server Error: /front/data_to_pdf/
Traceback (most recent call last):
  File "/home/simprosys-aman/.local/lib/python3.11/site-packages/django/core/handlers/exception.py", line 55, in inner
    response = get_response(request)
               ^^^^^^^^^^^^^^^^^^^^^
  File "/home/simprosys-aman/.local/lib/python3.11/site-packages/django/core/handlers/base.py", line 204, in _get_response
    self.check_response(response, callback)
  File "/home/simprosys-aman/.local/lib/python3.11/site-packages/django/core/handlers/base.py", line 332, in check_response
    raise ValueError(
ValueError: The view frontapp.views.generate_pdf didn't return an HttpResponse object. It returned None instead.
2023-05-16 05:06:29,011 ERROR Internal Server Error: /front/data_to_pdf/
Traceback (most recent call last):
  File "/home/simprosys-aman/.local/lib/python3.11/site-packages/django/core/handlers/exception.py", line 55, in inner
    response = get_response(request)
               ^^^^^^^^^^^^^^^^^^^^^
  File "/home/simprosys-aman/.local/lib/python3.11/site-packages/django/core/handlers/base.py", line 204, in _get_response
    self.check_response(response, callback)
  File "/home/simprosys-aman/.local/lib/python3.11/site-packages/django/core/handlers/base.py", line 332, in check_response
    raise ValueError(
ValueError: The view frontapp.views.generate_pdf didn't return an HttpResponse object. It returned None instead.
2023-05-16 05:24:33,665 ERROR Internal Server Error: /front/login/
Traceback (most recent call last):
  File "/home/simprosys-aman/Aman/Aman/Practical/Shopify/frontapp/views.py", line 74, in login_user
    track_user_activity(request.user.id,ip_address,"login/url")
  File "/home/simprosys-aman/Aman/Aman/Practical/Shopify/frontapp/views.py", line 64, in track_user_activity
    activity = UserActivity(user_id=user.id, IP=ip_address, description=description)
                                    ^^^^^^^
AttributeError: 'NoneType' object has no attribute 'id'

During handling of the above exception, another exception occurred:

Traceback (most recent call last):
  File "/home/simprosys-aman/.local/lib/python3.11/site-packages/django/core/handlers/exception.py", line 55, in inner
    response = get_response(request)
               ^^^^^^^^^^^^^^^^^^^^^
  File "/home/simprosys-aman/.local/lib/python3.11/site-packages/django/core/handlers/base.py", line 197, in _get_response
    response = wrapped_callback(request, *callback_args, **callback_kwargs)
               ^^^^^^^^^^^^^^^^^^^^^^^^^^^^^^^^^^^^^^^^^^^^^^^^^^^^^^^^^^^^
  File "/home/simprosys-aman/Aman/Aman/Practical/Shopify/frontapp/views.py", line 104, in login_user
    save_exception_to_database(request.user.id, "40", type(e), str(e), ip_address)
  File "/home/simprosys-aman/Aman/Aman/Practical/Shopify/frontapp/views.py", line 51, in save_exception_to_database
    user_id_instence = User.objects.get(id=user_id)
                       ^^^^^^^^^^^^^^^^^^^^^^^^^^^^
  File "/home/simprosys-aman/.local/lib/python3.11/site-packages/django/db/models/manager.py", line 87, in manager_method
    return getattr(self.get_queryset(), name)(*args, **kwargs)
           ^^^^^^^^^^^^^^^^^^^^^^^^^^^^^^^^^^^^^^^^^^^^^^^^^^^
  File "/home/simprosys-aman/.local/lib/python3.11/site-packages/django/db/models/query.py", line 637, in get
    raise self.model.DoesNotExist(
django.contrib.auth.models.User.DoesNotExist: User matching query does not exist.
2023-05-16 05:25:07,640 ERROR Internal Server Error: /front/login/
Traceback (most recent call last):
  File "/home/simprosys-aman/Aman/Aman/Practical/Shopify/frontapp/views.py", line 74, in login_user
    track_user_activity(username,ip_address,"login/url")
  File "/home/simprosys-aman/Aman/Aman/Practical/Shopify/frontapp/views.py", line 64, in track_user_activity
    activity = UserActivity(user_id=user.id, IP=ip_address, description=description)
                                    ^^^^^^^
AttributeError: 'str' object has no attribute 'id'

During handling of the above exception, another exception occurred:

Traceback (most recent call last):
  File "/home/simprosys-aman/.local/lib/python3.11/site-packages/django/core/handlers/exception.py", line 55, in inner
    response = get_response(request)
               ^^^^^^^^^^^^^^^^^^^^^
  File "/home/simprosys-aman/.local/lib/python3.11/site-packages/django/core/handlers/base.py", line 197, in _get_response
    response = wrapped_callback(request, *callback_args, **callback_kwargs)
               ^^^^^^^^^^^^^^^^^^^^^^^^^^^^^^^^^^^^^^^^^^^^^^^^^^^^^^^^^^^^
  File "/home/simprosys-aman/Aman/Aman/Practical/Shopify/frontapp/views.py", line 104, in login_user
    save_exception_to_database(request.user.id, "40", type(e), str(e), ip_address)
  File "/home/simprosys-aman/Aman/Aman/Practical/Shopify/frontapp/views.py", line 51, in save_exception_to_database
    user_id_instence = User.objects.get(id=user_id)
                       ^^^^^^^^^^^^^^^^^^^^^^^^^^^^
  File "/home/simprosys-aman/.local/lib/python3.11/site-packages/django/db/models/manager.py", line 87, in manager_method
    return getattr(self.get_queryset(), name)(*args, **kwargs)
           ^^^^^^^^^^^^^^^^^^^^^^^^^^^^^^^^^^^^^^^^^^^^^^^^^^^
  File "/home/simprosys-aman/.local/lib/python3.11/site-packages/django/db/models/query.py", line 637, in get
    raise self.model.DoesNotExist(
django.contrib.auth.models.User.DoesNotExist: User matching query does not exist.
2023-05-16 05:25:15,705 ERROR Internal Server Error: /front/login/
Traceback (most recent call last):
  File "/home/simprosys-aman/Aman/Aman/Practical/Shopify/frontapp/views.py", line 74, in login_user
    track_user_activity(username,ip_address,"login/url")
  File "/home/simprosys-aman/Aman/Aman/Practical/Shopify/frontapp/views.py", line 64, in track_user_activity
    activity = UserActivity(user_id=user.id, IP=ip_address, description=description)
                                    ^^^^^^^
AttributeError: 'str' object has no attribute 'id'

During handling of the above exception, another exception occurred:

Traceback (most recent call last):
  File "/home/simprosys-aman/.local/lib/python3.11/site-packages/django/core/handlers/exception.py", line 55, in inner
    response = get_response(request)
               ^^^^^^^^^^^^^^^^^^^^^
  File "/home/simprosys-aman/.local/lib/python3.11/site-packages/django/core/handlers/base.py", line 197, in _get_response
    response = wrapped_callback(request, *callback_args, **callback_kwargs)
               ^^^^^^^^^^^^^^^^^^^^^^^^^^^^^^^^^^^^^^^^^^^^^^^^^^^^^^^^^^^^
  File "/home/simprosys-aman/Aman/Aman/Practical/Shopify/frontapp/views.py", line 104, in login_user
    save_exception_to_database(request.user.id, "40", type(e), str(e), ip_address)
  File "/home/simprosys-aman/Aman/Aman/Practical/Shopify/frontapp/views.py", line 51, in save_exception_to_database
    user_id_instence = User.objects.get(id=user_id)
                       ^^^^^^^^^^^^^^^^^^^^^^^^^^^^
  File "/home/simprosys-aman/.local/lib/python3.11/site-packages/django/db/models/manager.py", line 87, in manager_method
    return getattr(self.get_queryset(), name)(*args, **kwargs)
           ^^^^^^^^^^^^^^^^^^^^^^^^^^^^^^^^^^^^^^^^^^^^^^^^^^^
  File "/home/simprosys-aman/.local/lib/python3.11/site-packages/django/db/models/query.py", line 637, in get
    raise self.model.DoesNotExist(
django.contrib.auth.models.User.DoesNotExist: User matching query does not exist.
2023-05-16 05:25:57,574 ERROR Internal Server Error: /front/login/
Traceback (most recent call last):
  File "/home/simprosys-aman/Aman/Aman/Practical/Shopify/frontapp/views.py", line 74, in login_user
    track_user_activity(username,ip_address,"login/url")
  File "/home/simprosys-aman/Aman/Aman/Practical/Shopify/frontapp/views.py", line 64, in track_user_activity
    activity = UserActivity(user_id=user, IP=ip_address, description=description)
               ^^^^^^^^^^^^^^^^^^^^^^^^^^^^^^^^^^^^^^^^^^^^^^^^^^^^^^^^^^^^^^^^^^
  File "/home/simprosys-aman/.local/lib/python3.11/site-packages/django/db/models/base.py", line 543, in __init__
    _setattr(self, field.name, rel_obj)
  File "/home/simprosys-aman/.local/lib/python3.11/site-packages/django/db/models/fields/related_descriptors.py", line 266, in __set__
    raise ValueError(
ValueError: Cannot assign "'Aman Dubey'": "UserActivity.user_id" must be a "User" instance.

During handling of the above exception, another exception occurred:

Traceback (most recent call last):
  File "/home/simprosys-aman/.local/lib/python3.11/site-packages/django/core/handlers/exception.py", line 55, in inner
    response = get_response(request)
               ^^^^^^^^^^^^^^^^^^^^^
  File "/home/simprosys-aman/.local/lib/python3.11/site-packages/django/core/handlers/base.py", line 197, in _get_response
    response = wrapped_callback(request, *callback_args, **callback_kwargs)
               ^^^^^^^^^^^^^^^^^^^^^^^^^^^^^^^^^^^^^^^^^^^^^^^^^^^^^^^^^^^^
  File "/home/simprosys-aman/Aman/Aman/Practical/Shopify/frontapp/views.py", line 104, in login_user
    save_exception_to_database(request.user.id, "40", type(e), str(e), ip_address)
  File "/home/simprosys-aman/Aman/Aman/Practical/Shopify/frontapp/views.py", line 51, in save_exception_to_database
    user_id_instence = User.objects.get(id=user_id)
                       ^^^^^^^^^^^^^^^^^^^^^^^^^^^^
  File "/home/simprosys-aman/.local/lib/python3.11/site-packages/django/db/models/manager.py", line 87, in manager_method
    return getattr(self.get_queryset(), name)(*args, **kwargs)
           ^^^^^^^^^^^^^^^^^^^^^^^^^^^^^^^^^^^^^^^^^^^^^^^^^^^
  File "/home/simprosys-aman/.local/lib/python3.11/site-packages/django/db/models/query.py", line 637, in get
    raise self.model.DoesNotExist(
django.contrib.auth.models.User.DoesNotExist: User matching query does not exist.
2023-05-16 05:26:29,858 ERROR Internal Server Error: /front/login/
Traceback (most recent call last):
  File "/home/simprosys-aman/Aman/Aman/Practical/Shopify/frontapp/views.py", line 74, in login_user
    track_user_activity(request.user,ip_address,"login/url")
  File "/home/simprosys-aman/Aman/Aman/Practical/Shopify/frontapp/views.py", line 64, in track_user_activity
    activity = UserActivity(user_id=user, IP=ip_address, description=description)
               ^^^^^^^^^^^^^^^^^^^^^^^^^^^^^^^^^^^^^^^^^^^^^^^^^^^^^^^^^^^^^^^^^^
  File "/home/simprosys-aman/.local/lib/python3.11/site-packages/django/db/models/base.py", line 543, in __init__
    _setattr(self, field.name, rel_obj)
  File "/home/simprosys-aman/.local/lib/python3.11/site-packages/django/db/models/fields/related_descriptors.py", line 266, in __set__
    raise ValueError(
ValueError: Cannot assign "<SimpleLazyObject: <django.contrib.auth.models.AnonymousUser object at 0x7fc1351f1b90>>": "UserActivity.user_id" must be a "User" instance.

During handling of the above exception, another exception occurred:

Traceback (most recent call last):
  File "/home/simprosys-aman/.local/lib/python3.11/site-packages/django/core/handlers/exception.py", line 55, in inner
    response = get_response(request)
               ^^^^^^^^^^^^^^^^^^^^^
  File "/home/simprosys-aman/.local/lib/python3.11/site-packages/django/core/handlers/base.py", line 197, in _get_response
    response = wrapped_callback(request, *callback_args, **callback_kwargs)
               ^^^^^^^^^^^^^^^^^^^^^^^^^^^^^^^^^^^^^^^^^^^^^^^^^^^^^^^^^^^^
  File "/home/simprosys-aman/Aman/Aman/Practical/Shopify/frontapp/views.py", line 104, in login_user
    save_exception_to_database(request.user.id, "40", type(e), str(e), ip_address)
  File "/home/simprosys-aman/Aman/Aman/Practical/Shopify/frontapp/views.py", line 51, in save_exception_to_database
    user_id_instence = User.objects.get(id=user_id)
                       ^^^^^^^^^^^^^^^^^^^^^^^^^^^^
  File "/home/simprosys-aman/.local/lib/python3.11/site-packages/django/db/models/manager.py", line 87, in manager_method
    return getattr(self.get_queryset(), name)(*args, **kwargs)
           ^^^^^^^^^^^^^^^^^^^^^^^^^^^^^^^^^^^^^^^^^^^^^^^^^^^
  File "/home/simprosys-aman/.local/lib/python3.11/site-packages/django/db/models/query.py", line 637, in get
    raise self.model.DoesNotExist(
django.contrib.auth.models.User.DoesNotExist: User matching query does not exist.
2023-05-16 05:26:48,588 ERROR Internal Server Error: /front/login/
Traceback (most recent call last):
  File "/home/simprosys-aman/Aman/Aman/Practical/Shopify/frontapp/views.py", line 74, in login_user
    track_user_activity(request.user,ip_address,"login/url")
  File "/home/simprosys-aman/Aman/Aman/Practical/Shopify/frontapp/views.py", line 64, in track_user_activity
    activity = UserActivity(user_id=user, IP=ip_address, description=description)
               ^^^^^^^^^^^^^^^^^^^^^^^^^^^^^^^^^^^^^^^^^^^^^^^^^^^^^^^^^^^^^^^^^^
  File "/home/simprosys-aman/.local/lib/python3.11/site-packages/django/db/models/base.py", line 543, in __init__
    _setattr(self, field.name, rel_obj)
  File "/home/simprosys-aman/.local/lib/python3.11/site-packages/django/db/models/fields/related_descriptors.py", line 266, in __set__
    raise ValueError(
ValueError: Cannot assign "<SimpleLazyObject: <django.contrib.auth.models.AnonymousUser object at 0x7fc135247610>>": "UserActivity.user_id" must be a "User" instance.

During handling of the above exception, another exception occurred:

Traceback (most recent call last):
  File "/home/simprosys-aman/.local/lib/python3.11/site-packages/django/core/handlers/exception.py", line 55, in inner
    response = get_response(request)
               ^^^^^^^^^^^^^^^^^^^^^
  File "/home/simprosys-aman/.local/lib/python3.11/site-packages/django/core/handlers/base.py", line 197, in _get_response
    response = wrapped_callback(request, *callback_args, **callback_kwargs)
               ^^^^^^^^^^^^^^^^^^^^^^^^^^^^^^^^^^^^^^^^^^^^^^^^^^^^^^^^^^^^
  File "/home/simprosys-aman/Aman/Aman/Practical/Shopify/frontapp/views.py", line 104, in login_user
    save_exception_to_database(request.user.id, "40", type(e), str(e), ip_address)
  File "/home/simprosys-aman/Aman/Aman/Practical/Shopify/frontapp/views.py", line 51, in save_exception_to_database
    user_id_instence = User.objects.get(id=user_id)
                       ^^^^^^^^^^^^^^^^^^^^^^^^^^^^
  File "/home/simprosys-aman/.local/lib/python3.11/site-packages/django/db/models/manager.py", line 87, in manager_method
    return getattr(self.get_queryset(), name)(*args, **kwargs)
           ^^^^^^^^^^^^^^^^^^^^^^^^^^^^^^^^^^^^^^^^^^^^^^^^^^^
  File "/home/simprosys-aman/.local/lib/python3.11/site-packages/django/db/models/query.py", line 637, in get
    raise self.model.DoesNotExist(
django.contrib.auth.models.User.DoesNotExist: User matching query does not exist.
2023-05-16 05:28:36,244 ERROR Internal Server Error: /front/login/
Traceback (most recent call last):
  File "/home/simprosys-aman/Aman/Aman/Practical/Shopify/frontapp/views.py", line 75, in login_user
    track_user_activity(request.user,ip_address,"login/url")
  File "/home/simprosys-aman/Aman/Aman/Practical/Shopify/frontapp/views.py", line 64, in track_user_activity
    activity = UserActivity(user_id=user, IP=ip_address, description=description)
               ^^^^^^^^^^^^^^^^^^^^^^^^^^^^^^^^^^^^^^^^^^^^^^^^^^^^^^^^^^^^^^^^^^
  File "/home/simprosys-aman/.local/lib/python3.11/site-packages/django/db/models/base.py", line 543, in __init__
    _setattr(self, field.name, rel_obj)
  File "/home/simprosys-aman/.local/lib/python3.11/site-packages/django/db/models/fields/related_descriptors.py", line 266, in __set__
    raise ValueError(
ValueError: Cannot assign "<SimpleLazyObject: <django.contrib.auth.models.AnonymousUser object at 0x7faf0bf59410>>": "UserActivity.user_id" must be a "User" instance.

During handling of the above exception, another exception occurred:

Traceback (most recent call last):
  File "/home/simprosys-aman/.local/lib/python3.11/site-packages/django/core/handlers/exception.py", line 55, in inner
    response = get_response(request)
               ^^^^^^^^^^^^^^^^^^^^^
  File "/home/simprosys-aman/.local/lib/python3.11/site-packages/django/core/handlers/base.py", line 197, in _get_response
    response = wrapped_callback(request, *callback_args, **callback_kwargs)
               ^^^^^^^^^^^^^^^^^^^^^^^^^^^^^^^^^^^^^^^^^^^^^^^^^^^^^^^^^^^^
  File "/home/simprosys-aman/Aman/Aman/Practical/Shopify/frontapp/views.py", line 105, in login_user
    save_exception_to_database(request.user.id, "40", type(e), str(e), ip_address)
  File "/home/simprosys-aman/Aman/Aman/Practical/Shopify/frontapp/views.py", line 51, in save_exception_to_database
    user_id_instence = User.objects.get(id=user_id)
                       ^^^^^^^^^^^^^^^^^^^^^^^^^^^^
  File "/home/simprosys-aman/.local/lib/python3.11/site-packages/django/db/models/manager.py", line 87, in manager_method
    return getattr(self.get_queryset(), name)(*args, **kwargs)
           ^^^^^^^^^^^^^^^^^^^^^^^^^^^^^^^^^^^^^^^^^^^^^^^^^^^
  File "/home/simprosys-aman/.local/lib/python3.11/site-packages/django/db/models/query.py", line 637, in get
    raise self.model.DoesNotExist(
django.contrib.auth.models.User.DoesNotExist: User matching query does not exist.
2023-05-16 05:28:45,025 ERROR Internal Server Error: /front/login/
Traceback (most recent call last):
  File "/home/simprosys-aman/Aman/Aman/Practical/Shopify/frontapp/views.py", line 75, in login_user
    track_user_activity(request.user,ip_address,"login/url")
  File "/home/simprosys-aman/Aman/Aman/Practical/Shopify/frontapp/views.py", line 64, in track_user_activity
    activity = UserActivity(user_id=user, IP=ip_address, description=description)
               ^^^^^^^^^^^^^^^^^^^^^^^^^^^^^^^^^^^^^^^^^^^^^^^^^^^^^^^^^^^^^^^^^^
  File "/home/simprosys-aman/.local/lib/python3.11/site-packages/django/db/models/base.py", line 543, in __init__
    _setattr(self, field.name, rel_obj)
  File "/home/simprosys-aman/.local/lib/python3.11/site-packages/django/db/models/fields/related_descriptors.py", line 266, in __set__
    raise ValueError(
ValueError: Cannot assign "<SimpleLazyObject: <django.contrib.auth.models.AnonymousUser object at 0x7faf139f4190>>": "UserActivity.user_id" must be a "User" instance.

During handling of the above exception, another exception occurred:

Traceback (most recent call last):
  File "/home/simprosys-aman/.local/lib/python3.11/site-packages/django/core/handlers/exception.py", line 55, in inner
    response = get_response(request)
               ^^^^^^^^^^^^^^^^^^^^^
  File "/home/simprosys-aman/.local/lib/python3.11/site-packages/django/core/handlers/base.py", line 197, in _get_response
    response = wrapped_callback(request, *callback_args, **callback_kwargs)
               ^^^^^^^^^^^^^^^^^^^^^^^^^^^^^^^^^^^^^^^^^^^^^^^^^^^^^^^^^^^^
  File "/home/simprosys-aman/Aman/Aman/Practical/Shopify/frontapp/views.py", line 105, in login_user
    save_exception_to_database(request.user.id, "40", type(e), str(e), ip_address)
  File "/home/simprosys-aman/Aman/Aman/Practical/Shopify/frontapp/views.py", line 51, in save_exception_to_database
    user_id_instence = User.objects.get(id=user_id)
                       ^^^^^^^^^^^^^^^^^^^^^^^^^^^^
  File "/home/simprosys-aman/.local/lib/python3.11/site-packages/django/db/models/manager.py", line 87, in manager_method
    return getattr(self.get_queryset(), name)(*args, **kwargs)
           ^^^^^^^^^^^^^^^^^^^^^^^^^^^^^^^^^^^^^^^^^^^^^^^^^^^
  File "/home/simprosys-aman/.local/lib/python3.11/site-packages/django/db/models/query.py", line 637, in get
    raise self.model.DoesNotExist(
django.contrib.auth.models.User.DoesNotExist: User matching query does not exist.
2023-05-16 05:51:06,767 ERROR Internal Server Error: /front/logout/
Traceback (most recent call last):
  File "/home/simprosys-aman/Aman/Aman/Practical/Shopify/frontapp/views.py", line 114, in logout_user
    user_id_instence = User.objects.get(id=request.user.id)
                       ^^^^^^^^^^^^^^^^^^^^^^^^^^^^^^^^^^^^
  File "/home/simprosys-aman/.local/lib/python3.11/site-packages/django/db/models/manager.py", line 87, in manager_method
    return getattr(self.get_queryset(), name)(*args, **kwargs)
           ^^^^^^^^^^^^^^^^^^^^^^^^^^^^^^^^^^^^^^^^^^^^^^^^^^^
  File "/home/simprosys-aman/.local/lib/python3.11/site-packages/django/db/models/query.py", line 637, in get
    raise self.model.DoesNotExist(
django.contrib.auth.models.User.DoesNotExist: User matching query does not exist.

During handling of the above exception, another exception occurred:

Traceback (most recent call last):
  File "/home/simprosys-aman/.local/lib/python3.11/site-packages/django/core/handlers/exception.py", line 55, in inner
    response = get_response(request)
               ^^^^^^^^^^^^^^^^^^^^^
  File "/home/simprosys-aman/.local/lib/python3.11/site-packages/django/core/handlers/base.py", line 197, in _get_response
    response = wrapped_callback(request, *callback_args, **callback_kwargs)
               ^^^^^^^^^^^^^^^^^^^^^^^^^^^^^^^^^^^^^^^^^^^^^^^^^^^^^^^^^^^^
  File "/home/simprosys-aman/Aman/Aman/Practical/Shopify/frontapp/views.py", line 130, in logout_user
    save_exception_to_database(request.user.id, "40", type(e), str(e), ip_address)
  File "/home/simprosys-aman/Aman/Aman/Practical/Shopify/frontapp/views.py", line 51, in save_exception_to_database
    user_id_instence = User.objects.get(id=user_id)
                       ^^^^^^^^^^^^^^^^^^^^^^^^^^^^
  File "/home/simprosys-aman/.local/lib/python3.11/site-packages/django/db/models/manager.py", line 87, in manager_method
    return getattr(self.get_queryset(), name)(*args, **kwargs)
           ^^^^^^^^^^^^^^^^^^^^^^^^^^^^^^^^^^^^^^^^^^^^^^^^^^^
  File "/home/simprosys-aman/.local/lib/python3.11/site-packages/django/db/models/query.py", line 637, in get
    raise self.model.DoesNotExist(
django.contrib.auth.models.User.DoesNotExist: User matching query does not exist.
2023-05-16 05:56:52,243 ERROR Internal Server Error: /front/registration/
Traceback (most recent call last):
  File "/home/simprosys-aman/Aman/Aman/Practical/Shopify/frontapp/views.py", line 140, in signup
    profile_obj = Profile.objects.create(user=user_obj)
                                              ^^^^^^^^
UnboundLocalError: cannot access local variable 'user_obj' where it is not associated with a value

During handling of the above exception, another exception occurred:

Traceback (most recent call last):
  File "/home/simprosys-aman/.local/lib/python3.11/site-packages/django/core/handlers/exception.py", line 55, in inner
    response = get_response(request)
               ^^^^^^^^^^^^^^^^^^^^^
  File "/home/simprosys-aman/.local/lib/python3.11/site-packages/django/core/handlers/base.py", line 197, in _get_response
    response = wrapped_callback(request, *callback_args, **callback_kwargs)
               ^^^^^^^^^^^^^^^^^^^^^^^^^^^^^^^^^^^^^^^^^^^^^^^^^^^^^^^^^^^^
  File "/home/simprosys-aman/Aman/Aman/Practical/Shopify/frontapp/views.py", line 191, in signup
    save_exception_to_database(request.user.id, "40", type(e), str(e), ip_address)
  File "/home/simprosys-aman/Aman/Aman/Practical/Shopify/frontapp/views.py", line 51, in save_exception_to_database
    user_id_instence = User.objects.get(id=user_id)
                       ^^^^^^^^^^^^^^^^^^^^^^^^^^^^
  File "/home/simprosys-aman/.local/lib/python3.11/site-packages/django/db/models/manager.py", line 87, in manager_method
    return getattr(self.get_queryset(), name)(*args, **kwargs)
           ^^^^^^^^^^^^^^^^^^^^^^^^^^^^^^^^^^^^^^^^^^^^^^^^^^^
  File "/home/simprosys-aman/.local/lib/python3.11/site-packages/django/db/models/query.py", line 637, in get
    raise self.model.DoesNotExist(
django.contrib.auth.models.User.DoesNotExist: User matching query does not exist.
2023-05-16 06:03:26,368 ERROR Internal Server Error: /front/change_password/
Traceback (most recent call last):
  File "/home/simprosys-aman/.local/lib/python3.11/site-packages/django/core/handlers/exception.py", line 55, in inner
    response = get_response(request)
               ^^^^^^^^^^^^^^^^^^^^^
  File "/home/simprosys-aman/.local/lib/python3.11/site-packages/django/core/handlers/base.py", line 197, in _get_response
    response = wrapped_callback(request, *callback_args, **callback_kwargs)
               ^^^^^^^^^^^^^^^^^^^^^^^^^^^^^^^^^^^^^^^^^^^^^^^^^^^^^^^^^^^^
  File "/home/simprosys-aman/.local/lib/python3.11/site-packages/django/contrib/auth/decorators.py", line 23, in _wrapper_view
    return view_func(request, *args, **kwargs)
           ^^^^^^^^^^^^^^^^^^^^^^^^^^^^^^^^^^^
  File "/home/simprosys-aman/Aman/Aman/Practical/Shopify/frontapp/views.py", line 196, in change_password
    description = {"messages":"This user try to changepassword","data":request.data}
                                                                       ^^^^^^^^^^^^
AttributeError: 'WSGIRequest' object has no attribute 'data'
2023-05-16 06:15:12,252 ERROR Internal Server Error: /front/change_password/73f6d29d-ec2c-4047-bfab-c7b90be31e6c
Traceback (most recent call last):
  File "/home/simprosys-aman/Aman/Aman/Practical/Shopify/frontapp/views.py", line 220, in change_password_with_token
    user_id_instence = User.objects.get(id=request.user.id)
                       ^^^^^^^^^^^^^^^^^^^^^^^^^^^^^^^^^^^^
  File "/home/simprosys-aman/.local/lib/python3.11/site-packages/django/db/models/manager.py", line 87, in manager_method
    return getattr(self.get_queryset(), name)(*args, **kwargs)
           ^^^^^^^^^^^^^^^^^^^^^^^^^^^^^^^^^^^^^^^^^^^^^^^^^^^
  File "/home/simprosys-aman/.local/lib/python3.11/site-packages/django/db/models/query.py", line 637, in get
    raise self.model.DoesNotExist(
django.contrib.auth.models.User.DoesNotExist: User matching query does not exist.

During handling of the above exception, another exception occurred:

Traceback (most recent call last):
  File "/home/simprosys-aman/.local/lib/python3.11/site-packages/django/core/handlers/exception.py", line 55, in inner
    response = get_response(request)
               ^^^^^^^^^^^^^^^^^^^^^
  File "/home/simprosys-aman/.local/lib/python3.11/site-packages/django/core/handlers/base.py", line 197, in _get_response
    response = wrapped_callback(request, *callback_args, **callback_kwargs)
               ^^^^^^^^^^^^^^^^^^^^^^^^^^^^^^^^^^^^^^^^^^^^^^^^^^^^^^^^^^^^
  File "/home/simprosys-aman/Aman/Aman/Practical/Shopify/frontapp/views.py", line 261, in change_password_with_token
    save_exception_to_database(request.user.id, "40", type(e), str(e), ip_address)
  File "/home/simprosys-aman/Aman/Aman/Practical/Shopify/frontapp/views.py", line 51, in save_exception_to_database
    user_id_instence = User.objects.get(id=user_id)
                       ^^^^^^^^^^^^^^^^^^^^^^^^^^^^
  File "/home/simprosys-aman/.local/lib/python3.11/site-packages/django/db/models/manager.py", line 87, in manager_method
    return getattr(self.get_queryset(), name)(*args, **kwargs)
           ^^^^^^^^^^^^^^^^^^^^^^^^^^^^^^^^^^^^^^^^^^^^^^^^^^^
  File "/home/simprosys-aman/.local/lib/python3.11/site-packages/django/db/models/query.py", line 637, in get
    raise self.model.DoesNotExist(
django.contrib.auth.models.User.DoesNotExist: User matching query does not exist.
2023-05-16 06:16:32,437 ERROR Internal Server Error: /front/forgot-password/
Traceback (most recent call last):
  File "/home/simprosys-aman/Aman/Aman/Practical/Shopify/frontapp/views.py", line 278, in forgot_password_with_email
    user_id_instence = User.objects.get(id=request.user.id)
                       ^^^^^^^^^^^^^^^^^^^^^^^^^^^^^^^^^^^^
  File "/home/simprosys-aman/.local/lib/python3.11/site-packages/django/db/models/manager.py", line 87, in manager_method
    return getattr(self.get_queryset(), name)(*args, **kwargs)
           ^^^^^^^^^^^^^^^^^^^^^^^^^^^^^^^^^^^^^^^^^^^^^^^^^^^
  File "/home/simprosys-aman/.local/lib/python3.11/site-packages/django/db/models/query.py", line 637, in get
    raise self.model.DoesNotExist(
django.contrib.auth.models.User.DoesNotExist: User matching query does not exist.

During handling of the above exception, another exception occurred:

Traceback (most recent call last):
  File "/home/simprosys-aman/.local/lib/python3.11/site-packages/django/core/handlers/exception.py", line 55, in inner
    response = get_response(request)
               ^^^^^^^^^^^^^^^^^^^^^
  File "/home/simprosys-aman/.local/lib/python3.11/site-packages/django/core/handlers/base.py", line 197, in _get_response
    response = wrapped_callback(request, *callback_args, **callback_kwargs)
               ^^^^^^^^^^^^^^^^^^^^^^^^^^^^^^^^^^^^^^^^^^^^^^^^^^^^^^^^^^^^
  File "/home/simprosys-aman/Aman/Aman/Practical/Shopify/frontapp/views.py", line 293, in forgot_password_with_email
    save_exception_to_database(request.user.id, "40", type(e), str(e), ip_address)
  File "/home/simprosys-aman/Aman/Aman/Practical/Shopify/frontapp/views.py", line 51, in save_exception_to_database
    user_id_instence = User.objects.get(id=user_id)
                       ^^^^^^^^^^^^^^^^^^^^^^^^^^^^
  File "/home/simprosys-aman/.local/lib/python3.11/site-packages/django/db/models/manager.py", line 87, in manager_method
    return getattr(self.get_queryset(), name)(*args, **kwargs)
           ^^^^^^^^^^^^^^^^^^^^^^^^^^^^^^^^^^^^^^^^^^^^^^^^^^^
  File "/home/simprosys-aman/.local/lib/python3.11/site-packages/django/db/models/query.py", line 637, in get
    raise self.model.DoesNotExist(
django.contrib.auth.models.User.DoesNotExist: User matching query does not exist.
2023-05-16 06:17:11,528 ERROR Internal Server Error: /front/forgot-password/
Traceback (most recent call last):
  File "/home/simprosys-aman/.local/lib/python3.11/site-packages/django/db/models/fields/__init__.py", line 2055, in get_prep_value
    return int(value)
           ^^^^^^^^^^
ValueError: invalid literal for int() with base 10: ''

The above exception was the direct cause of the following exception:

Traceback (most recent call last):
  File "/home/simprosys-aman/Aman/Aman/Practical/Shopify/frontapp/views.py", line 278, in forgot_password_with_email
    user_id_instence = User.objects.get(id=request.user.username)
                       ^^^^^^^^^^^^^^^^^^^^^^^^^^^^^^^^^^^^^^^^^^
  File "/home/simprosys-aman/.local/lib/python3.11/site-packages/django/db/models/manager.py", line 87, in manager_method
    return getattr(self.get_queryset(), name)(*args, **kwargs)
           ^^^^^^^^^^^^^^^^^^^^^^^^^^^^^^^^^^^^^^^^^^^^^^^^^^^
  File "/home/simprosys-aman/.local/lib/python3.11/site-packages/django/db/models/query.py", line 623, in get
    clone = self._chain() if self.query.combinator else self.filter(*args, **kwargs)
                                                        ^^^^^^^^^^^^^^^^^^^^^^^^^^^^
  File "/home/simprosys-aman/.local/lib/python3.11/site-packages/django/db/models/query.py", line 1436, in filter
    return self._filter_or_exclude(False, args, kwargs)
           ^^^^^^^^^^^^^^^^^^^^^^^^^^^^^^^^^^^^^^^^^^^^
  File "/home/simprosys-aman/.local/lib/python3.11/site-packages/django/db/models/query.py", line 1454, in _filter_or_exclude
    clone._filter_or_exclude_inplace(negate, args, kwargs)
  File "/home/simprosys-aman/.local/lib/python3.11/site-packages/django/db/models/query.py", line 1461, in _filter_or_exclude_inplace
    self._query.add_q(Q(*args, **kwargs))
  File "/home/simprosys-aman/.local/lib/python3.11/site-packages/django/db/models/sql/query.py", line 1502, in add_q
    clause, _ = self._add_q(q_object, self.used_aliases)
                ^^^^^^^^^^^^^^^^^^^^^^^^^^^^^^^^^^^^^^^^
  File "/home/simprosys-aman/.local/lib/python3.11/site-packages/django/db/models/sql/query.py", line 1533, in _add_q
    child_clause, needed_inner = self.build_filter(
                                 ^^^^^^^^^^^^^^^^^^
  File "/home/simprosys-aman/.local/lib/python3.11/site-packages/django/db/models/sql/query.py", line 1448, in build_filter
    condition = self.build_lookup(lookups, col, value)
                ^^^^^^^^^^^^^^^^^^^^^^^^^^^^^^^^^^^^^^
  File "/home/simprosys-aman/.local/lib/python3.11/site-packages/django/db/models/sql/query.py", line 1275, in build_lookup
    lookup = lookup_class(lhs, rhs)
             ^^^^^^^^^^^^^^^^^^^^^^
  File "/home/simprosys-aman/.local/lib/python3.11/site-packages/django/db/models/lookups.py", line 27, in __init__
    self.rhs = self.get_prep_lookup()
               ^^^^^^^^^^^^^^^^^^^^^^
  File "/home/simprosys-aman/.local/lib/python3.11/site-packages/django/db/models/lookups.py", line 341, in get_prep_lookup
    return super().get_prep_lookup()
           ^^^^^^^^^^^^^^^^^^^^^^^^^
  File "/home/simprosys-aman/.local/lib/python3.11/site-packages/django/db/models/lookups.py", line 85, in get_prep_lookup
    return self.lhs.output_field.get_prep_value(self.rhs)
           ^^^^^^^^^^^^^^^^^^^^^^^^^^^^^^^^^^^^^^^^^^^^^^
  File "/home/simprosys-aman/.local/lib/python3.11/site-packages/django/db/models/fields/__init__.py", line 2057, in get_prep_value
    raise e.__class__(
ValueError: Field 'id' expected a number but got ''.

During handling of the above exception, another exception occurred:

Traceback (most recent call last):
  File "/home/simprosys-aman/.local/lib/python3.11/site-packages/django/core/handlers/exception.py", line 55, in inner
    response = get_response(request)
               ^^^^^^^^^^^^^^^^^^^^^
  File "/home/simprosys-aman/.local/lib/python3.11/site-packages/django/core/handlers/base.py", line 197, in _get_response
    response = wrapped_callback(request, *callback_args, **callback_kwargs)
               ^^^^^^^^^^^^^^^^^^^^^^^^^^^^^^^^^^^^^^^^^^^^^^^^^^^^^^^^^^^^
  File "/home/simprosys-aman/Aman/Aman/Practical/Shopify/frontapp/views.py", line 293, in forgot_password_with_email
    save_exception_to_database(request.user.id, "40", type(e), str(e), ip_address)
  File "/home/simprosys-aman/Aman/Aman/Practical/Shopify/frontapp/views.py", line 51, in save_exception_to_database
    user_id_instence = User.objects.get(id=user_id)
                       ^^^^^^^^^^^^^^^^^^^^^^^^^^^^
  File "/home/simprosys-aman/.local/lib/python3.11/site-packages/django/db/models/manager.py", line 87, in manager_method
    return getattr(self.get_queryset(), name)(*args, **kwargs)
           ^^^^^^^^^^^^^^^^^^^^^^^^^^^^^^^^^^^^^^^^^^^^^^^^^^^
  File "/home/simprosys-aman/.local/lib/python3.11/site-packages/django/db/models/query.py", line 637, in get
    raise self.model.DoesNotExist(
django.contrib.auth.models.User.DoesNotExist: User matching query does not exist.
2023-05-16 06:41:21,310 ERROR Internal Server Error: /front/send_mail/
Traceback (most recent call last):
  File "/home/simprosys-aman/.local/lib/python3.11/site-packages/django/core/handlers/exception.py", line 55, in inner
    response = get_response(request)
               ^^^^^^^^^^^^^^^^^^^^^
  File "/home/simprosys-aman/.local/lib/python3.11/site-packages/django/core/handlers/base.py", line 197, in _get_response
    response = wrapped_callback(request, *callback_args, **callback_kwargs)
               ^^^^^^^^^^^^^^^^^^^^^^^^^^^^^^^^^^^^^^^^^^^^^^^^^^^^^^^^^^^^
  File "/home/simprosys-aman/Aman/Aman/Practical/Shopify/frontapp/views.py", line 635, in send_mail_to_all_users
    send_mail_to_user.delay()
  File "/home/simprosys-aman/.local/lib/python3.11/site-packages/celery/app/task.py", line 425, in delay
    return self.apply_async(args, kwargs)
           ^^^^^^^^^^^^^^^^^^^^^^^^^^^^^^
  File "/home/simprosys-aman/.local/lib/python3.11/site-packages/celery/app/task.py", line 575, in apply_async
    return app.send_task(
           ^^^^^^^^^^^^^^
  File "/home/simprosys-aman/.local/lib/python3.11/site-packages/celery/app/base.py", line 784, in send_task
    with self.producer_or_acquire(producer) as P:
         ^^^^^^^^^^^^^^^^^^^^^^^^^^^^^^^^^^
  File "/home/simprosys-aman/.local/lib/python3.11/site-packages/celery/app/base.py", line 919, in producer_or_acquire
    producer, self.producer_pool.acquire, block=True,
              ^^^^^^^^^^^^^^^^^^
  File "/home/simprosys-aman/.local/lib/python3.11/site-packages/celery/app/base.py", line 1303, in producer_pool
    return self.amqp.producer_pool
           ^^^^^^^^^^^^^^^^^^^^^^^
  File "/home/simprosys-aman/.local/lib/python3.11/site-packages/celery/app/amqp.py", line 583, in producer_pool
    self.app.connection_for_write()]
    ^^^^^^^^^^^^^^^^^^^^^^^^^^^^^^^
  File "/home/simprosys-aman/.local/lib/python3.11/site-packages/celery/app/base.py", line 816, in connection_for_write
    return self._connection(url or self.conf.broker_write_url, **kwargs)
           ^^^^^^^^^^^^^^^^^^^^^^^^^^^^^^^^^^^^^^^^^^^^^^^^^^^^^^^^^^^^^
  File "/home/simprosys-aman/.local/lib/python3.11/site-packages/celery/app/base.py", line 867, in _connection
    return self.amqp.Connection(
           ^^^^^^^^^^^^^^^^^^^^^
  File "/home/simprosys-aman/.local/lib/python3.11/site-packages/kombu/connection.py", line 181, in __init__
    if not get_transport_cls(transport).can_parse_url:
           ^^^^^^^^^^^^^^^^^^^^^^^^^^^^
  File "/home/simprosys-aman/.local/lib/python3.11/site-packages/kombu/transport/__init__.py", line 85, in get_transport_cls
    _transport_cache[transport] = resolve_transport(transport)
                                  ^^^^^^^^^^^^^^^^^^^^^^^^^^^^
  File "/home/simprosys-aman/.local/lib/python3.11/site-packages/kombu/transport/__init__.py", line 70, in resolve_transport
    return symbol_by_name(transport)
           ^^^^^^^^^^^^^^^^^^^^^^^^^
  File "/home/simprosys-aman/.local/lib/python3.11/site-packages/kombu/utils/imports.py", line 56, in symbol_by_name
    module = imp(module_name, package=package, **kwargs)
             ^^^^^^^^^^^^^^^^^^^^^^^^^^^^^^^^^^^^^^^^^^^
  File "/usr/lib/python3.11/importlib/__init__.py", line 126, in import_module
    return _bootstrap._gcd_import(name[level:], package, level)
           ^^^^^^^^^^^^^^^^^^^^^^^^^^^^^^^^^^^^^^^^^^^^^^^^^^^^
  File "<frozen importlib._bootstrap>", line 1206, in _gcd_import
  File "<frozen importlib._bootstrap>", line 1178, in _find_and_load
  File "<frozen importlib._bootstrap>", line 1149, in _find_and_load_unlocked
  File "<frozen importlib._bootstrap>", line 690, in _load_unlocked
  File "<frozen importlib._bootstrap_external>", line 940, in exec_module
  File "<frozen importlib._bootstrap>", line 241, in _call_with_frames_removed
  File "/home/simprosys-aman/.local/lib/python3.11/site-packages/kombu/transport/redis.py", line 262, in <module>
    class PrefixedStrictRedis(GlobalKeyPrefixMixin, redis.Redis):
                                                    ^^^^^^^^^^^
AttributeError: 'NoneType' object has no attribute 'Redis'
2023-05-16 06:44:32,811 ERROR Internal Server Error: /front/send_mail/
Traceback (most recent call last):
  File "/home/simprosys-aman/.local/lib/python3.11/site-packages/django/core/handlers/exception.py", line 55, in inner
    response = get_response(request)
               ^^^^^^^^^^^^^^^^^^^^^
  File "/home/simprosys-aman/.local/lib/python3.11/site-packages/django/core/handlers/base.py", line 197, in _get_response
    response = wrapped_callback(request, *callback_args, **callback_kwargs)
               ^^^^^^^^^^^^^^^^^^^^^^^^^^^^^^^^^^^^^^^^^^^^^^^^^^^^^^^^^^^^
  File "/home/simprosys-aman/Aman/Aman/Practical/Shopify/frontapp/views.py", line 635, in send_mail_to_all_users
    send_mail_to_user.delay()
  File "/home/simprosys-aman/.local/lib/python3.11/site-packages/celery/app/task.py", line 425, in delay
    return self.apply_async(args, kwargs)
           ^^^^^^^^^^^^^^^^^^^^^^^^^^^^^^
  File "/home/simprosys-aman/.local/lib/python3.11/site-packages/celery/app/task.py", line 575, in apply_async
    return app.send_task(
           ^^^^^^^^^^^^^^
  File "/home/simprosys-aman/.local/lib/python3.11/site-packages/celery/app/base.py", line 784, in send_task
    with self.producer_or_acquire(producer) as P:
         ^^^^^^^^^^^^^^^^^^^^^^^^^^^^^^^^^^
  File "/home/simprosys-aman/.local/lib/python3.11/site-packages/celery/app/base.py", line 919, in producer_or_acquire
    producer, self.producer_pool.acquire, block=True,
              ^^^^^^^^^^^^^^^^^^
  File "/home/simprosys-aman/.local/lib/python3.11/site-packages/celery/app/base.py", line 1303, in producer_pool
    return self.amqp.producer_pool
           ^^^^^^^^^^^^^^^^^^^^^^^
  File "/home/simprosys-aman/.local/lib/python3.11/site-packages/celery/app/amqp.py", line 583, in producer_pool
    self.app.connection_for_write()]
    ^^^^^^^^^^^^^^^^^^^^^^^^^^^^^^^
  File "/home/simprosys-aman/.local/lib/python3.11/site-packages/celery/app/base.py", line 816, in connection_for_write
    return self._connection(url or self.conf.broker_write_url, **kwargs)
           ^^^^^^^^^^^^^^^^^^^^^^^^^^^^^^^^^^^^^^^^^^^^^^^^^^^^^^^^^^^^^
  File "/home/simprosys-aman/.local/lib/python3.11/site-packages/celery/app/base.py", line 867, in _connection
    return self.amqp.Connection(
           ^^^^^^^^^^^^^^^^^^^^^
  File "/home/simprosys-aman/.local/lib/python3.11/site-packages/kombu/connection.py", line 181, in __init__
    if not get_transport_cls(transport).can_parse_url:
           ^^^^^^^^^^^^^^^^^^^^^^^^^^^^
  File "/home/simprosys-aman/.local/lib/python3.11/site-packages/kombu/transport/__init__.py", line 85, in get_transport_cls
    _transport_cache[transport] = resolve_transport(transport)
                                  ^^^^^^^^^^^^^^^^^^^^^^^^^^^^
  File "/home/simprosys-aman/.local/lib/python3.11/site-packages/kombu/transport/__init__.py", line 70, in resolve_transport
    return symbol_by_name(transport)
           ^^^^^^^^^^^^^^^^^^^^^^^^^
  File "/home/simprosys-aman/.local/lib/python3.11/site-packages/kombu/utils/imports.py", line 56, in symbol_by_name
    module = imp(module_name, package=package, **kwargs)
             ^^^^^^^^^^^^^^^^^^^^^^^^^^^^^^^^^^^^^^^^^^^
  File "/usr/lib/python3.11/importlib/__init__.py", line 126, in import_module
    return _bootstrap._gcd_import(name[level:], package, level)
           ^^^^^^^^^^^^^^^^^^^^^^^^^^^^^^^^^^^^^^^^^^^^^^^^^^^^
  File "<frozen importlib._bootstrap>", line 1206, in _gcd_import
  File "<frozen importlib._bootstrap>", line 1178, in _find_and_load
  File "<frozen importlib._bootstrap>", line 1149, in _find_and_load_unlocked
  File "<frozen importlib._bootstrap>", line 690, in _load_unlocked
  File "<frozen importlib._bootstrap_external>", line 940, in exec_module
  File "<frozen importlib._bootstrap>", line 241, in _call_with_frames_removed
  File "/home/simprosys-aman/.local/lib/python3.11/site-packages/kombu/transport/redis.py", line 262, in <module>
    class PrefixedStrictRedis(GlobalKeyPrefixMixin, redis.Redis):
                                                    ^^^^^^^^^^^
AttributeError: 'NoneType' object has no attribute 'Redis'
2023-05-16 07:00:40,967 ERROR Internal Server Error: /token
Traceback (most recent call last):
  File "/home/simprosys-aman/.local/lib/python3.11/site-packages/django/core/handlers/exception.py", line 55, in inner
    response = get_response(request)
               ^^^^^^^^^^^^^^^^^^^^^
  File "/home/simprosys-aman/.local/lib/python3.11/site-packages/django/utils/deprecation.py", line 136, in __call__
    response = self.process_response(request, response)
               ^^^^^^^^^^^^^^^^^^^^^^^^^^^^^^^^^^^^^^^^
  File "/home/simprosys-aman/.local/lib/python3.11/site-packages/django/middleware/common.py", line 108, in process_response
    return self.response_redirect_class(self.get_full_path_with_slash(request))
                                        ^^^^^^^^^^^^^^^^^^^^^^^^^^^^^^^^^^^^^^
  File "/home/simprosys-aman/.local/lib/python3.11/site-packages/django/middleware/common.py", line 87, in get_full_path_with_slash
    raise RuntimeError(
RuntimeError: You called this URL via POST, but the URL doesn't end in a slash and you have APPEND_SLASH set. Django can't redirect to the slash URL while maintaining POST data. Change your form to point to 127.0.0.1:8000/token/ (note the trailing slash), or set APPEND_SLASH=False in your Django settings.
2023-05-16 07:00:48,540 ERROR Internal Server Error: /token
Traceback (most recent call last):
  File "/home/simprosys-aman/.local/lib/python3.11/site-packages/django/core/handlers/exception.py", line 55, in inner
    response = get_response(request)
               ^^^^^^^^^^^^^^^^^^^^^
  File "/home/simprosys-aman/.local/lib/python3.11/site-packages/django/utils/deprecation.py", line 136, in __call__
    response = self.process_response(request, response)
               ^^^^^^^^^^^^^^^^^^^^^^^^^^^^^^^^^^^^^^^^
  File "/home/simprosys-aman/.local/lib/python3.11/site-packages/django/middleware/common.py", line 108, in process_response
    return self.response_redirect_class(self.get_full_path_with_slash(request))
                                        ^^^^^^^^^^^^^^^^^^^^^^^^^^^^^^^^^^^^^^
  File "/home/simprosys-aman/.local/lib/python3.11/site-packages/django/middleware/common.py", line 87, in get_full_path_with_slash
    raise RuntimeError(
RuntimeError: You called this URL via POST, but the URL doesn't end in a slash and you have APPEND_SLASH set. Django can't redirect to the slash URL while maintaining POST data. Change your form to point to 127.0.0.1:8000/token/ (note the trailing slash), or set APPEND_SLASH=False in your Django settings.
2023-05-16 08:44:32,374 ERROR Internal Server Error: /front/login/
Traceback (most recent call last):
  File "/home/simprosys-aman/.local/lib/python3.11/site-packages/django/db/backends/utils.py", line 89, in _execute
    return self.cursor.execute(sql, params)
           ^^^^^^^^^^^^^^^^^^^^^^^^^^^^^^^^
  File "/home/simprosys-aman/.local/lib/python3.11/site-packages/django/db/backends/mysql/base.py", line 75, in execute
    return self.cursor.execute(query, args)
           ^^^^^^^^^^^^^^^^^^^^^^^^^^^^^^^^
  File "/home/simprosys-aman/.local/lib/python3.11/site-packages/MySQLdb/cursors.py", line 206, in execute
    res = self._query(query)
          ^^^^^^^^^^^^^^^^^^
  File "/home/simprosys-aman/.local/lib/python3.11/site-packages/MySQLdb/cursors.py", line 319, in _query
    db.query(q)
  File "/home/simprosys-aman/.local/lib/python3.11/site-packages/MySQLdb/connections.py", line 254, in query
    _mysql.connection.query(self, query)
MySQLdb.ProgrammingError: (1146, "Table 'FlaskDB.frontapp_useractivity' doesn't exist")

The above exception was the direct cause of the following exception:

Traceback (most recent call last):
  File "/home/simprosys-aman/Aman/Aman/Practical/Shopify/frontapp/views.py", line 89, in login_user
    activity.save()
  File "/home/simprosys-aman/.local/lib/python3.11/site-packages/django/db/models/base.py", line 814, in save
    self.save_base(
  File "/home/simprosys-aman/.local/lib/python3.11/site-packages/django/db/models/base.py", line 877, in save_base
    updated = self._save_table(
              ^^^^^^^^^^^^^^^^^
  File "/home/simprosys-aman/.local/lib/python3.11/site-packages/django/db/models/base.py", line 1020, in _save_table
    results = self._do_insert(
              ^^^^^^^^^^^^^^^^
  File "/home/simprosys-aman/.local/lib/python3.11/site-packages/django/db/models/base.py", line 1061, in _do_insert
    return manager._insert(
           ^^^^^^^^^^^^^^^^
  File "/home/simprosys-aman/.local/lib/python3.11/site-packages/django/db/models/manager.py", line 87, in manager_method
    return getattr(self.get_queryset(), name)(*args, **kwargs)
           ^^^^^^^^^^^^^^^^^^^^^^^^^^^^^^^^^^^^^^^^^^^^^^^^^^^
  File "/home/simprosys-aman/.local/lib/python3.11/site-packages/django/db/models/query.py", line 1805, in _insert
    return query.get_compiler(using=using).execute_sql(returning_fields)
           ^^^^^^^^^^^^^^^^^^^^^^^^^^^^^^^^^^^^^^^^^^^^^^^^^^^^^^^^^^^^^
  File "/home/simprosys-aman/.local/lib/python3.11/site-packages/django/db/models/sql/compiler.py", line 1820, in execute_sql
    cursor.execute(sql, params)
  File "/home/simprosys-aman/.local/lib/python3.11/site-packages/django/db/backends/utils.py", line 102, in execute
    return super().execute(sql, params)
           ^^^^^^^^^^^^^^^^^^^^^^^^^^^^
  File "/home/simprosys-aman/.local/lib/python3.11/site-packages/django/db/backends/utils.py", line 67, in execute
    return self._execute_with_wrappers(
           ^^^^^^^^^^^^^^^^^^^^^^^^^^^^
  File "/home/simprosys-aman/.local/lib/python3.11/site-packages/django/db/backends/utils.py", line 80, in _execute_with_wrappers
    return executor(sql, params, many, context)
           ^^^^^^^^^^^^^^^^^^^^^^^^^^^^^^^^^^^^
  File "/home/simprosys-aman/.local/lib/python3.11/site-packages/django/db/backends/utils.py", line 84, in _execute
    with self.db.wrap_database_errors:
  File "/home/simprosys-aman/.local/lib/python3.11/site-packages/django/db/utils.py", line 91, in __exit__
    raise dj_exc_value.with_traceback(traceback) from exc_value
  File "/home/simprosys-aman/.local/lib/python3.11/site-packages/django/db/backends/utils.py", line 89, in _execute
    return self.cursor.execute(sql, params)
           ^^^^^^^^^^^^^^^^^^^^^^^^^^^^^^^^
  File "/home/simprosys-aman/.local/lib/python3.11/site-packages/django/db/backends/mysql/base.py", line 75, in execute
    return self.cursor.execute(query, args)
           ^^^^^^^^^^^^^^^^^^^^^^^^^^^^^^^^
  File "/home/simprosys-aman/.local/lib/python3.11/site-packages/MySQLdb/cursors.py", line 206, in execute
    res = self._query(query)
          ^^^^^^^^^^^^^^^^^^
  File "/home/simprosys-aman/.local/lib/python3.11/site-packages/MySQLdb/cursors.py", line 319, in _query
    db.query(q)
  File "/home/simprosys-aman/.local/lib/python3.11/site-packages/MySQLdb/connections.py", line 254, in query
    _mysql.connection.query(self, query)
django.db.utils.ProgrammingError: (1146, "Table 'FlaskDB.frontapp_useractivity' doesn't exist")

During handling of the above exception, another exception occurred:

Traceback (most recent call last):
  File "/home/simprosys-aman/.local/lib/python3.11/site-packages/django/db/backends/utils.py", line 89, in _execute
    return self.cursor.execute(sql, params)
           ^^^^^^^^^^^^^^^^^^^^^^^^^^^^^^^^
  File "/home/simprosys-aman/.local/lib/python3.11/site-packages/django/db/backends/mysql/base.py", line 75, in execute
    return self.cursor.execute(query, args)
           ^^^^^^^^^^^^^^^^^^^^^^^^^^^^^^^^
  File "/home/simprosys-aman/.local/lib/python3.11/site-packages/MySQLdb/cursors.py", line 206, in execute
    res = self._query(query)
          ^^^^^^^^^^^^^^^^^^
  File "/home/simprosys-aman/.local/lib/python3.11/site-packages/MySQLdb/cursors.py", line 319, in _query
    db.query(q)
  File "/home/simprosys-aman/.local/lib/python3.11/site-packages/MySQLdb/connections.py", line 254, in query
    _mysql.connection.query(self, query)
MySQLdb.ProgrammingError: (1146, "Table 'FlaskDB.frontapp_exceptions' doesn't exist")

The above exception was the direct cause of the following exception:

Traceback (most recent call last):
  File "/home/simprosys-aman/Aman/Aman/Practical/Shopify/frontapp/views.py", line 101, in login_user
    save_exception_to_database(
  File "/home/simprosys-aman/Aman/Aman/Practical/Shopify/frontapp/views.py", line 60, in save_exception_to_database
    exception_log.save()
  File "/home/simprosys-aman/.local/lib/python3.11/site-packages/django/db/models/base.py", line 814, in save
    self.save_base(
  File "/home/simprosys-aman/.local/lib/python3.11/site-packages/django/db/models/base.py", line 877, in save_base
    updated = self._save_table(
              ^^^^^^^^^^^^^^^^^
  File "/home/simprosys-aman/.local/lib/python3.11/site-packages/django/db/models/base.py", line 1020, in _save_table
    results = self._do_insert(
              ^^^^^^^^^^^^^^^^
  File "/home/simprosys-aman/.local/lib/python3.11/site-packages/django/db/models/base.py", line 1061, in _do_insert
    return manager._insert(
           ^^^^^^^^^^^^^^^^
  File "/home/simprosys-aman/.local/lib/python3.11/site-packages/django/db/models/manager.py", line 87, in manager_method
    return getattr(self.get_queryset(), name)(*args, **kwargs)
           ^^^^^^^^^^^^^^^^^^^^^^^^^^^^^^^^^^^^^^^^^^^^^^^^^^^
  File "/home/simprosys-aman/.local/lib/python3.11/site-packages/django/db/models/query.py", line 1805, in _insert
    return query.get_compiler(using=using).execute_sql(returning_fields)
           ^^^^^^^^^^^^^^^^^^^^^^^^^^^^^^^^^^^^^^^^^^^^^^^^^^^^^^^^^^^^^
  File "/home/simprosys-aman/.local/lib/python3.11/site-packages/django/db/models/sql/compiler.py", line 1820, in execute_sql
    cursor.execute(sql, params)
  File "/home/simprosys-aman/.local/lib/python3.11/site-packages/django/db/backends/utils.py", line 102, in execute
    return super().execute(sql, params)
           ^^^^^^^^^^^^^^^^^^^^^^^^^^^^
  File "/home/simprosys-aman/.local/lib/python3.11/site-packages/django/db/backends/utils.py", line 67, in execute
    return self._execute_with_wrappers(
           ^^^^^^^^^^^^^^^^^^^^^^^^^^^^
  File "/home/simprosys-aman/.local/lib/python3.11/site-packages/django/db/backends/utils.py", line 80, in _execute_with_wrappers
    return executor(sql, params, many, context)
           ^^^^^^^^^^^^^^^^^^^^^^^^^^^^^^^^^^^^
  File "/home/simprosys-aman/.local/lib/python3.11/site-packages/django/db/backends/utils.py", line 84, in _execute
    with self.db.wrap_database_errors:
  File "/home/simprosys-aman/.local/lib/python3.11/site-packages/django/db/utils.py", line 91, in __exit__
    raise dj_exc_value.with_traceback(traceback) from exc_value
  File "/home/simprosys-aman/.local/lib/python3.11/site-packages/django/db/backends/utils.py", line 89, in _execute
    return self.cursor.execute(sql, params)
           ^^^^^^^^^^^^^^^^^^^^^^^^^^^^^^^^
  File "/home/simprosys-aman/.local/lib/python3.11/site-packages/django/db/backends/mysql/base.py", line 75, in execute
    return self.cursor.execute(query, args)
           ^^^^^^^^^^^^^^^^^^^^^^^^^^^^^^^^
  File "/home/simprosys-aman/.local/lib/python3.11/site-packages/MySQLdb/cursors.py", line 206, in execute
    res = self._query(query)
          ^^^^^^^^^^^^^^^^^^
  File "/home/simprosys-aman/.local/lib/python3.11/site-packages/MySQLdb/cursors.py", line 319, in _query
    db.query(q)
  File "/home/simprosys-aman/.local/lib/python3.11/site-packages/MySQLdb/connections.py", line 254, in query
    _mysql.connection.query(self, query)
django.db.utils.ProgrammingError: (1146, "Table 'FlaskDB.frontapp_exceptions' doesn't exist")

During handling of the above exception, another exception occurred:

Traceback (most recent call last):
  File "/home/simprosys-aman/.local/lib/python3.11/site-packages/django/db/backends/utils.py", line 89, in _execute
    return self.cursor.execute(sql, params)
           ^^^^^^^^^^^^^^^^^^^^^^^^^^^^^^^^
  File "/home/simprosys-aman/.local/lib/python3.11/site-packages/django/db/backends/mysql/base.py", line 75, in execute
    return self.cursor.execute(query, args)
           ^^^^^^^^^^^^^^^^^^^^^^^^^^^^^^^^
  File "/home/simprosys-aman/.local/lib/python3.11/site-packages/MySQLdb/cursors.py", line 206, in execute
    res = self._query(query)
          ^^^^^^^^^^^^^^^^^^
  File "/home/simprosys-aman/.local/lib/python3.11/site-packages/MySQLdb/cursors.py", line 319, in _query
    db.query(q)
  File "/home/simprosys-aman/.local/lib/python3.11/site-packages/MySQLdb/connections.py", line 254, in query
    _mysql.connection.query(self, query)
MySQLdb.ProgrammingError: (1146, "Table 'FlaskDB.frontapp_exceptions' doesn't exist")

The above exception was the direct cause of the following exception:

Traceback (most recent call last):
  File "/home/simprosys-aman/.local/lib/python3.11/site-packages/django/core/handlers/exception.py", line 55, in inner
    response = get_response(request)
               ^^^^^^^^^^^^^^^^^^^^^
  File "/home/simprosys-aman/.local/lib/python3.11/site-packages/django/core/handlers/base.py", line 197, in _get_response
    response = wrapped_callback(request, *callback_args, **callback_kwargs)
               ^^^^^^^^^^^^^^^^^^^^^^^^^^^^^^^^^^^^^^^^^^^^^^^^^^^^^^^^^^^^
  File "/home/simprosys-aman/Aman/Aman/Practical/Shopify/frontapp/views.py", line 107, in login_user
    save_exception_to_database(request.user.id, "40", type(e), str(e), ip_address)
  File "/home/simprosys-aman/Aman/Aman/Practical/Shopify/frontapp/views.py", line 60, in save_exception_to_database
    exception_log.save()
  File "/home/simprosys-aman/.local/lib/python3.11/site-packages/django/db/models/base.py", line 814, in save
    self.save_base(
  File "/home/simprosys-aman/.local/lib/python3.11/site-packages/django/db/models/base.py", line 877, in save_base
    updated = self._save_table(
              ^^^^^^^^^^^^^^^^^
  File "/home/simprosys-aman/.local/lib/python3.11/site-packages/django/db/models/base.py", line 1020, in _save_table
    results = self._do_insert(
              ^^^^^^^^^^^^^^^^
  File "/home/simprosys-aman/.local/lib/python3.11/site-packages/django/db/models/base.py", line 1061, in _do_insert
    return manager._insert(
           ^^^^^^^^^^^^^^^^
  File "/home/simprosys-aman/.local/lib/python3.11/site-packages/django/db/models/manager.py", line 87, in manager_method
    return getattr(self.get_queryset(), name)(*args, **kwargs)
           ^^^^^^^^^^^^^^^^^^^^^^^^^^^^^^^^^^^^^^^^^^^^^^^^^^^
  File "/home/simprosys-aman/.local/lib/python3.11/site-packages/django/db/models/query.py", line 1805, in _insert
    return query.get_compiler(using=using).execute_sql(returning_fields)
           ^^^^^^^^^^^^^^^^^^^^^^^^^^^^^^^^^^^^^^^^^^^^^^^^^^^^^^^^^^^^^
  File "/home/simprosys-aman/.local/lib/python3.11/site-packages/django/db/models/sql/compiler.py", line 1820, in execute_sql
    cursor.execute(sql, params)
  File "/home/simprosys-aman/.local/lib/python3.11/site-packages/django/db/backends/utils.py", line 102, in execute
    return super().execute(sql, params)
           ^^^^^^^^^^^^^^^^^^^^^^^^^^^^
  File "/home/simprosys-aman/.local/lib/python3.11/site-packages/django/db/backends/utils.py", line 67, in execute
    return self._execute_with_wrappers(
           ^^^^^^^^^^^^^^^^^^^^^^^^^^^^
  File "/home/simprosys-aman/.local/lib/python3.11/site-packages/django/db/backends/utils.py", line 80, in _execute_with_wrappers
    return executor(sql, params, many, context)
           ^^^^^^^^^^^^^^^^^^^^^^^^^^^^^^^^^^^^
  File "/home/simprosys-aman/.local/lib/python3.11/site-packages/django/db/backends/utils.py", line 84, in _execute
    with self.db.wrap_database_errors:
  File "/home/simprosys-aman/.local/lib/python3.11/site-packages/django/db/utils.py", line 91, in __exit__
    raise dj_exc_value.with_traceback(traceback) from exc_value
  File "/home/simprosys-aman/.local/lib/python3.11/site-packages/django/db/backends/utils.py", line 89, in _execute
    return self.cursor.execute(sql, params)
           ^^^^^^^^^^^^^^^^^^^^^^^^^^^^^^^^
  File "/home/simprosys-aman/.local/lib/python3.11/site-packages/django/db/backends/mysql/base.py", line 75, in execute
    return self.cursor.execute(query, args)
           ^^^^^^^^^^^^^^^^^^^^^^^^^^^^^^^^
  File "/home/simprosys-aman/.local/lib/python3.11/site-packages/MySQLdb/cursors.py", line 206, in execute
    res = self._query(query)
          ^^^^^^^^^^^^^^^^^^
  File "/home/simprosys-aman/.local/lib/python3.11/site-packages/MySQLdb/cursors.py", line 319, in _query
    db.query(q)
  File "/home/simprosys-aman/.local/lib/python3.11/site-packages/MySQLdb/connections.py", line 254, in query
    _mysql.connection.query(self, query)
django.db.utils.ProgrammingError: (1146, "Table 'FlaskDB.frontapp_exceptions' doesn't exist")
2023-05-16 08:46:40,851 ERROR Internal Server Error: /admin/frontapp/exceptions/
Traceback (most recent call last):
  File "/home/simprosys-aman/.local/lib/python3.11/site-packages/django/db/backends/utils.py", line 89, in _execute
    return self.cursor.execute(sql, params)
           ^^^^^^^^^^^^^^^^^^^^^^^^^^^^^^^^
  File "/home/simprosys-aman/.local/lib/python3.11/site-packages/django/db/backends/mysql/base.py", line 75, in execute
    return self.cursor.execute(query, args)
           ^^^^^^^^^^^^^^^^^^^^^^^^^^^^^^^^
  File "/home/simprosys-aman/.local/lib/python3.11/site-packages/MySQLdb/cursors.py", line 206, in execute
    res = self._query(query)
          ^^^^^^^^^^^^^^^^^^
  File "/home/simprosys-aman/.local/lib/python3.11/site-packages/MySQLdb/cursors.py", line 319, in _query
    db.query(q)
  File "/home/simprosys-aman/.local/lib/python3.11/site-packages/MySQLdb/connections.py", line 254, in query
    _mysql.connection.query(self, query)
MySQLdb.ProgrammingError: (1146, "Table 'FlaskDB.frontapp_exceptions' doesn't exist")

The above exception was the direct cause of the following exception:

Traceback (most recent call last):
  File "/home/simprosys-aman/.local/lib/python3.11/site-packages/django/core/handlers/exception.py", line 55, in inner
    response = get_response(request)
               ^^^^^^^^^^^^^^^^^^^^^
  File "/home/simprosys-aman/.local/lib/python3.11/site-packages/django/core/handlers/base.py", line 197, in _get_response
    response = wrapped_callback(request, *callback_args, **callback_kwargs)
               ^^^^^^^^^^^^^^^^^^^^^^^^^^^^^^^^^^^^^^^^^^^^^^^^^^^^^^^^^^^^
  File "/home/simprosys-aman/.local/lib/python3.11/site-packages/django/contrib/admin/options.py", line 688, in wrapper
    return self.admin_site.admin_view(view)(*args, **kwargs)
           ^^^^^^^^^^^^^^^^^^^^^^^^^^^^^^^^^^^^^^^^^^^^^^^^^
  File "/home/simprosys-aman/.local/lib/python3.11/site-packages/django/utils/decorators.py", line 134, in _wrapper_view
    response = view_func(request, *args, **kwargs)
               ^^^^^^^^^^^^^^^^^^^^^^^^^^^^^^^^^^^
  File "/home/simprosys-aman/.local/lib/python3.11/site-packages/django/views/decorators/cache.py", line 62, in _wrapper_view_func
    response = view_func(request, *args, **kwargs)
               ^^^^^^^^^^^^^^^^^^^^^^^^^^^^^^^^^^^
  File "/home/simprosys-aman/.local/lib/python3.11/site-packages/django/contrib/admin/sites.py", line 242, in inner
    return view(request, *args, **kwargs)
           ^^^^^^^^^^^^^^^^^^^^^^^^^^^^^^
  File "/home/simprosys-aman/.local/lib/python3.11/site-packages/django/utils/decorators.py", line 46, in _wrapper
    return bound_method(*args, **kwargs)
           ^^^^^^^^^^^^^^^^^^^^^^^^^^^^^
  File "/home/simprosys-aman/.local/lib/python3.11/site-packages/django/utils/decorators.py", line 134, in _wrapper_view
    response = view_func(request, *args, **kwargs)
               ^^^^^^^^^^^^^^^^^^^^^^^^^^^^^^^^^^^
  File "/home/simprosys-aman/.local/lib/python3.11/site-packages/django/contrib/admin/options.py", line 1926, in changelist_view
    cl = self.get_changelist_instance(request)
         ^^^^^^^^^^^^^^^^^^^^^^^^^^^^^^^^^^^^^
  File "/home/simprosys-aman/.local/lib/python3.11/site-packages/django/contrib/admin/options.py", line 836, in get_changelist_instance
    return ChangeList(
           ^^^^^^^^^^^
  File "/home/simprosys-aman/.local/lib/python3.11/site-packages/django/contrib/admin/views/main.py", line 123, in __init__
    self.get_results(request)
  File "/home/simprosys-aman/.local/lib/python3.11/site-packages/django/contrib/admin/views/main.py", line 279, in get_results
    result_count = paginator.count
                   ^^^^^^^^^^^^^^^
  File "/home/simprosys-aman/.local/lib/python3.11/site-packages/django/utils/functional.py", line 57, in __get__
    res = instance.__dict__[self.name] = self.func(instance)
                                         ^^^^^^^^^^^^^^^^^^^
  File "/home/simprosys-aman/.local/lib/python3.11/site-packages/django/core/paginator.py", line 93, in count
    return c()
           ^^^
  File "/home/simprosys-aman/.local/lib/python3.11/site-packages/django/db/models/query.py", line 608, in count
    return self.query.get_count(using=self.db)
           ^^^^^^^^^^^^^^^^^^^^^^^^^^^^^^^^^^^
  File "/home/simprosys-aman/.local/lib/python3.11/site-packages/django/db/models/sql/query.py", line 539, in get_count
    return obj.get_aggregation(using, {"__count": Count("*")})["__count"]
           ^^^^^^^^^^^^^^^^^^^^^^^^^^^^^^^^^^^^^^^^^^^^^^^^^^^
  File "/home/simprosys-aman/.local/lib/python3.11/site-packages/django/db/models/sql/query.py", line 525, in get_aggregation
    result = compiler.execute_sql(SINGLE)
             ^^^^^^^^^^^^^^^^^^^^^^^^^^^^
  File "/home/simprosys-aman/.local/lib/python3.11/site-packages/django/db/models/sql/compiler.py", line 1560, in execute_sql
    cursor.execute(sql, params)
  File "/home/simprosys-aman/.local/lib/python3.11/site-packages/django/db/backends/utils.py", line 102, in execute
    return super().execute(sql, params)
           ^^^^^^^^^^^^^^^^^^^^^^^^^^^^
  File "/home/simprosys-aman/.local/lib/python3.11/site-packages/django/db/backends/utils.py", line 67, in execute
    return self._execute_with_wrappers(
           ^^^^^^^^^^^^^^^^^^^^^^^^^^^^
  File "/home/simprosys-aman/.local/lib/python3.11/site-packages/django/db/backends/utils.py", line 80, in _execute_with_wrappers
    return executor(sql, params, many, context)
           ^^^^^^^^^^^^^^^^^^^^^^^^^^^^^^^^^^^^
  File "/home/simprosys-aman/.local/lib/python3.11/site-packages/django/db/backends/utils.py", line 84, in _execute
    with self.db.wrap_database_errors:
  File "/home/simprosys-aman/.local/lib/python3.11/site-packages/django/db/utils.py", line 91, in __exit__
    raise dj_exc_value.with_traceback(traceback) from exc_value
  File "/home/simprosys-aman/.local/lib/python3.11/site-packages/django/db/backends/utils.py", line 89, in _execute
    return self.cursor.execute(sql, params)
           ^^^^^^^^^^^^^^^^^^^^^^^^^^^^^^^^
  File "/home/simprosys-aman/.local/lib/python3.11/site-packages/django/db/backends/mysql/base.py", line 75, in execute
    return self.cursor.execute(query, args)
           ^^^^^^^^^^^^^^^^^^^^^^^^^^^^^^^^
  File "/home/simprosys-aman/.local/lib/python3.11/site-packages/MySQLdb/cursors.py", line 206, in execute
    res = self._query(query)
          ^^^^^^^^^^^^^^^^^^
  File "/home/simprosys-aman/.local/lib/python3.11/site-packages/MySQLdb/cursors.py", line 319, in _query
    db.query(q)
  File "/home/simprosys-aman/.local/lib/python3.11/site-packages/MySQLdb/connections.py", line 254, in query
    _mysql.connection.query(self, query)
django.db.utils.ProgrammingError: (1146, "Table 'FlaskDB.frontapp_exceptions' doesn't exist")
2023-05-16 08:47:31,553 ERROR Internal Server Error: /admin/frontapp/exceptions/
Traceback (most recent call last):
  File "/home/simprosys-aman/.local/lib/python3.11/site-packages/django/db/backends/utils.py", line 89, in _execute
    return self.cursor.execute(sql, params)
           ^^^^^^^^^^^^^^^^^^^^^^^^^^^^^^^^
  File "/home/simprosys-aman/.local/lib/python3.11/site-packages/django/db/backends/mysql/base.py", line 75, in execute
    return self.cursor.execute(query, args)
           ^^^^^^^^^^^^^^^^^^^^^^^^^^^^^^^^
  File "/home/simprosys-aman/.local/lib/python3.11/site-packages/MySQLdb/cursors.py", line 206, in execute
    res = self._query(query)
          ^^^^^^^^^^^^^^^^^^
  File "/home/simprosys-aman/.local/lib/python3.11/site-packages/MySQLdb/cursors.py", line 319, in _query
    db.query(q)
  File "/home/simprosys-aman/.local/lib/python3.11/site-packages/MySQLdb/connections.py", line 254, in query
    _mysql.connection.query(self, query)
MySQLdb.ProgrammingError: (1146, "Table 'FlaskDB.frontapp_exceptions' doesn't exist")

The above exception was the direct cause of the following exception:

Traceback (most recent call last):
  File "/home/simprosys-aman/.local/lib/python3.11/site-packages/django/core/handlers/exception.py", line 55, in inner
    response = get_response(request)
               ^^^^^^^^^^^^^^^^^^^^^
  File "/home/simprosys-aman/.local/lib/python3.11/site-packages/django/core/handlers/base.py", line 197, in _get_response
    response = wrapped_callback(request, *callback_args, **callback_kwargs)
               ^^^^^^^^^^^^^^^^^^^^^^^^^^^^^^^^^^^^^^^^^^^^^^^^^^^^^^^^^^^^
  File "/home/simprosys-aman/.local/lib/python3.11/site-packages/django/contrib/admin/options.py", line 688, in wrapper
    return self.admin_site.admin_view(view)(*args, **kwargs)
           ^^^^^^^^^^^^^^^^^^^^^^^^^^^^^^^^^^^^^^^^^^^^^^^^^
  File "/home/simprosys-aman/.local/lib/python3.11/site-packages/django/utils/decorators.py", line 134, in _wrapper_view
    response = view_func(request, *args, **kwargs)
               ^^^^^^^^^^^^^^^^^^^^^^^^^^^^^^^^^^^
  File "/home/simprosys-aman/.local/lib/python3.11/site-packages/django/views/decorators/cache.py", line 62, in _wrapper_view_func
    response = view_func(request, *args, **kwargs)
               ^^^^^^^^^^^^^^^^^^^^^^^^^^^^^^^^^^^
  File "/home/simprosys-aman/.local/lib/python3.11/site-packages/django/contrib/admin/sites.py", line 242, in inner
    return view(request, *args, **kwargs)
           ^^^^^^^^^^^^^^^^^^^^^^^^^^^^^^
  File "/home/simprosys-aman/.local/lib/python3.11/site-packages/django/utils/decorators.py", line 46, in _wrapper
    return bound_method(*args, **kwargs)
           ^^^^^^^^^^^^^^^^^^^^^^^^^^^^^
  File "/home/simprosys-aman/.local/lib/python3.11/site-packages/django/utils/decorators.py", line 134, in _wrapper_view
    response = view_func(request, *args, **kwargs)
               ^^^^^^^^^^^^^^^^^^^^^^^^^^^^^^^^^^^
  File "/home/simprosys-aman/.local/lib/python3.11/site-packages/django/contrib/admin/options.py", line 1926, in changelist_view
    cl = self.get_changelist_instance(request)
         ^^^^^^^^^^^^^^^^^^^^^^^^^^^^^^^^^^^^^
  File "/home/simprosys-aman/.local/lib/python3.11/site-packages/django/contrib/admin/options.py", line 836, in get_changelist_instance
    return ChangeList(
           ^^^^^^^^^^^
  File "/home/simprosys-aman/.local/lib/python3.11/site-packages/django/contrib/admin/views/main.py", line 123, in __init__
    self.get_results(request)
  File "/home/simprosys-aman/.local/lib/python3.11/site-packages/django/contrib/admin/views/main.py", line 279, in get_results
    result_count = paginator.count
                   ^^^^^^^^^^^^^^^
  File "/home/simprosys-aman/.local/lib/python3.11/site-packages/django/utils/functional.py", line 57, in __get__
    res = instance.__dict__[self.name] = self.func(instance)
                                         ^^^^^^^^^^^^^^^^^^^
  File "/home/simprosys-aman/.local/lib/python3.11/site-packages/django/core/paginator.py", line 93, in count
    return c()
           ^^^
  File "/home/simprosys-aman/.local/lib/python3.11/site-packages/django/db/models/query.py", line 608, in count
    return self.query.get_count(using=self.db)
           ^^^^^^^^^^^^^^^^^^^^^^^^^^^^^^^^^^^
  File "/home/simprosys-aman/.local/lib/python3.11/site-packages/django/db/models/sql/query.py", line 539, in get_count
    return obj.get_aggregation(using, {"__count": Count("*")})["__count"]
           ^^^^^^^^^^^^^^^^^^^^^^^^^^^^^^^^^^^^^^^^^^^^^^^^^^^
  File "/home/simprosys-aman/.local/lib/python3.11/site-packages/django/db/models/sql/query.py", line 525, in get_aggregation
    result = compiler.execute_sql(SINGLE)
             ^^^^^^^^^^^^^^^^^^^^^^^^^^^^
  File "/home/simprosys-aman/.local/lib/python3.11/site-packages/django/db/models/sql/compiler.py", line 1560, in execute_sql
    cursor.execute(sql, params)
  File "/home/simprosys-aman/.local/lib/python3.11/site-packages/django/db/backends/utils.py", line 102, in execute
    return super().execute(sql, params)
           ^^^^^^^^^^^^^^^^^^^^^^^^^^^^
  File "/home/simprosys-aman/.local/lib/python3.11/site-packages/django/db/backends/utils.py", line 67, in execute
    return self._execute_with_wrappers(
           ^^^^^^^^^^^^^^^^^^^^^^^^^^^^
  File "/home/simprosys-aman/.local/lib/python3.11/site-packages/django/db/backends/utils.py", line 80, in _execute_with_wrappers
    return executor(sql, params, many, context)
           ^^^^^^^^^^^^^^^^^^^^^^^^^^^^^^^^^^^^
  File "/home/simprosys-aman/.local/lib/python3.11/site-packages/django/db/backends/utils.py", line 84, in _execute
    with self.db.wrap_database_errors:
  File "/home/simprosys-aman/.local/lib/python3.11/site-packages/django/db/utils.py", line 91, in __exit__
    raise dj_exc_value.with_traceback(traceback) from exc_value
  File "/home/simprosys-aman/.local/lib/python3.11/site-packages/django/db/backends/utils.py", line 89, in _execute
    return self.cursor.execute(sql, params)
           ^^^^^^^^^^^^^^^^^^^^^^^^^^^^^^^^
  File "/home/simprosys-aman/.local/lib/python3.11/site-packages/django/db/backends/mysql/base.py", line 75, in execute
    return self.cursor.execute(query, args)
           ^^^^^^^^^^^^^^^^^^^^^^^^^^^^^^^^
  File "/home/simprosys-aman/.local/lib/python3.11/site-packages/MySQLdb/cursors.py", line 206, in execute
    res = self._query(query)
          ^^^^^^^^^^^^^^^^^^
  File "/home/simprosys-aman/.local/lib/python3.11/site-packages/MySQLdb/cursors.py", line 319, in _query
    db.query(q)
  File "/home/simprosys-aman/.local/lib/python3.11/site-packages/MySQLdb/connections.py", line 254, in query
    _mysql.connection.query(self, query)
django.db.utils.ProgrammingError: (1146, "Table 'FlaskDB.frontapp_exceptions' doesn't exist")
2023-05-16 09:08:43,938 ERROR Internal Server Error: /front/registration/
Traceback (most recent call last):
  File "/home/simprosys-aman/Aman/Aman/Practical/Shopify/frontapp/views.py", line 142, in signup
    profile_obj = Profile.objects.create(user=user_obj)
                                              ^^^^^^^^
UnboundLocalError: cannot access local variable 'user_obj' where it is not associated with a value

During handling of the above exception, another exception occurred:

Traceback (most recent call last):
  File "/home/simprosys-aman/.local/lib/python3.11/site-packages/django/core/handlers/exception.py", line 55, in inner
    response = get_response(request)
               ^^^^^^^^^^^^^^^^^^^^^
  File "/home/simprosys-aman/.local/lib/python3.11/site-packages/django/core/handlers/base.py", line 197, in _get_response
    response = wrapped_callback(request, *callback_args, **callback_kwargs)
               ^^^^^^^^^^^^^^^^^^^^^^^^^^^^^^^^^^^^^^^^^^^^^^^^^^^^^^^^^^^^
  File "/home/simprosys-aman/Aman/Aman/Practical/Shopify/frontapp/views.py", line 184, in signup
    save_exception_to_database(request.user.id, "40", type(e), str(e), ip_address)
  File "/home/simprosys-aman/Aman/Aman/Practical/Shopify/frontapp/views.py", line 51, in save_exception_to_database
    user_id_instence = User.objects.get(id=user_id)
                       ^^^^^^^^^^^^^^^^^^^^^^^^^^^^
  File "/home/simprosys-aman/.local/lib/python3.11/site-packages/django/db/models/manager.py", line 87, in manager_method
    return getattr(self.get_queryset(), name)(*args, **kwargs)
           ^^^^^^^^^^^^^^^^^^^^^^^^^^^^^^^^^^^^^^^^^^^^^^^^^^^
  File "/home/simprosys-aman/.local/lib/python3.11/site-packages/django/db/models/query.py", line 637, in get
    raise self.model.DoesNotExist(
django.contrib.auth.models.User.DoesNotExist: User matching query does not exist.
2023-05-16 09:18:00,785 ERROR Internal Server Error: /front/registration/
Traceback (most recent call last):
  File "/home/simprosys-aman/.local/lib/python3.11/site-packages/django/db/backends/utils.py", line 89, in _execute
    return self.cursor.execute(sql, params)
           ^^^^^^^^^^^^^^^^^^^^^^^^^^^^^^^^
  File "/home/simprosys-aman/.local/lib/python3.11/site-packages/django/db/backends/mysql/base.py", line 75, in execute
    return self.cursor.execute(query, args)
           ^^^^^^^^^^^^^^^^^^^^^^^^^^^^^^^^
  File "/home/simprosys-aman/.local/lib/python3.11/site-packages/MySQLdb/cursors.py", line 206, in execute
    res = self._query(query)
          ^^^^^^^^^^^^^^^^^^
  File "/home/simprosys-aman/.local/lib/python3.11/site-packages/MySQLdb/cursors.py", line 319, in _query
    db.query(q)
  File "/home/simprosys-aman/.local/lib/python3.11/site-packages/MySQLdb/connections.py", line 254, in query
    _mysql.connection.query(self, query)
MySQLdb.IntegrityError: (1062, "Duplicate entry 'Satya Bhau' for key 'auth_user.username'")

The above exception was the direct cause of the following exception:

Traceback (most recent call last):
  File "/home/simprosys-aman/Aman/Aman/Practical/Shopify/frontapp/views.py", line 167, in signup
    user_obj = User.objects.create_superuser(
               ^^^^^^^^^^^^^^^^^^^^^^^^^^^^^^
  File "/home/simprosys-aman/.local/lib/python3.11/site-packages/django/contrib/auth/models.py", line 172, in create_superuser
    return self._create_user(username, email, password, **extra_fields)
           ^^^^^^^^^^^^^^^^^^^^^^^^^^^^^^^^^^^^^^^^^^^^^^^^^^^^^^^^^^^^
  File "/home/simprosys-aman/.local/lib/python3.11/site-packages/django/contrib/auth/models.py", line 155, in _create_user
    user.save(using=self._db)
  File "/home/simprosys-aman/.local/lib/python3.11/site-packages/django/contrib/auth/base_user.py", line 76, in save
    super().save(*args, **kwargs)
  File "/home/simprosys-aman/.local/lib/python3.11/site-packages/django/db/models/base.py", line 814, in save
    self.save_base(
  File "/home/simprosys-aman/.local/lib/python3.11/site-packages/django/db/models/base.py", line 877, in save_base
    updated = self._save_table(
              ^^^^^^^^^^^^^^^^^
  File "/home/simprosys-aman/.local/lib/python3.11/site-packages/django/db/models/base.py", line 1020, in _save_table
    results = self._do_insert(
              ^^^^^^^^^^^^^^^^
  File "/home/simprosys-aman/.local/lib/python3.11/site-packages/django/db/models/base.py", line 1061, in _do_insert
    return manager._insert(
           ^^^^^^^^^^^^^^^^
  File "/home/simprosys-aman/.local/lib/python3.11/site-packages/django/db/models/manager.py", line 87, in manager_method
    return getattr(self.get_queryset(), name)(*args, **kwargs)
           ^^^^^^^^^^^^^^^^^^^^^^^^^^^^^^^^^^^^^^^^^^^^^^^^^^^
  File "/home/simprosys-aman/.local/lib/python3.11/site-packages/django/db/models/query.py", line 1805, in _insert
    return query.get_compiler(using=using).execute_sql(returning_fields)
           ^^^^^^^^^^^^^^^^^^^^^^^^^^^^^^^^^^^^^^^^^^^^^^^^^^^^^^^^^^^^^
  File "/home/simprosys-aman/.local/lib/python3.11/site-packages/django/db/models/sql/compiler.py", line 1820, in execute_sql
    cursor.execute(sql, params)
  File "/home/simprosys-aman/.local/lib/python3.11/site-packages/django/db/backends/utils.py", line 102, in execute
    return super().execute(sql, params)
           ^^^^^^^^^^^^^^^^^^^^^^^^^^^^
  File "/home/simprosys-aman/.local/lib/python3.11/site-packages/django/db/backends/utils.py", line 67, in execute
    return self._execute_with_wrappers(
           ^^^^^^^^^^^^^^^^^^^^^^^^^^^^
  File "/home/simprosys-aman/.local/lib/python3.11/site-packages/django/db/backends/utils.py", line 80, in _execute_with_wrappers
    return executor(sql, params, many, context)
           ^^^^^^^^^^^^^^^^^^^^^^^^^^^^^^^^^^^^
  File "/home/simprosys-aman/.local/lib/python3.11/site-packages/django/db/backends/utils.py", line 84, in _execute
    with self.db.wrap_database_errors:
  File "/home/simprosys-aman/.local/lib/python3.11/site-packages/django/db/utils.py", line 91, in __exit__
    raise dj_exc_value.with_traceback(traceback) from exc_value
  File "/home/simprosys-aman/.local/lib/python3.11/site-packages/django/db/backends/utils.py", line 89, in _execute
    return self.cursor.execute(sql, params)
           ^^^^^^^^^^^^^^^^^^^^^^^^^^^^^^^^
  File "/home/simprosys-aman/.local/lib/python3.11/site-packages/django/db/backends/mysql/base.py", line 75, in execute
    return self.cursor.execute(query, args)
           ^^^^^^^^^^^^^^^^^^^^^^^^^^^^^^^^
  File "/home/simprosys-aman/.local/lib/python3.11/site-packages/MySQLdb/cursors.py", line 206, in execute
    res = self._query(query)
          ^^^^^^^^^^^^^^^^^^
  File "/home/simprosys-aman/.local/lib/python3.11/site-packages/MySQLdb/cursors.py", line 319, in _query
    db.query(q)
  File "/home/simprosys-aman/.local/lib/python3.11/site-packages/MySQLdb/connections.py", line 254, in query
    _mysql.connection.query(self, query)
django.db.utils.IntegrityError: (1062, "Duplicate entry 'Satya Bhau' for key 'auth_user.username'")

During handling of the above exception, another exception occurred:

Traceback (most recent call last):
  File "/home/simprosys-aman/.local/lib/python3.11/site-packages/django/core/handlers/exception.py", line 55, in inner
    response = get_response(request)
               ^^^^^^^^^^^^^^^^^^^^^
  File "/home/simprosys-aman/.local/lib/python3.11/site-packages/django/core/handlers/base.py", line 197, in _get_response
    response = wrapped_callback(request, *callback_args, **callback_kwargs)
               ^^^^^^^^^^^^^^^^^^^^^^^^^^^^^^^^^^^^^^^^^^^^^^^^^^^^^^^^^^^^
  File "/home/simprosys-aman/Aman/Aman/Practical/Shopify/frontapp/views.py", line 187, in signup
    save_exception_to_database(request.user.id, "40", type(e), str(e), ip_address)
  File "/home/simprosys-aman/Aman/Aman/Practical/Shopify/frontapp/views.py", line 51, in save_exception_to_database
    user_id_instence = User.objects.get(id=user_id)
                       ^^^^^^^^^^^^^^^^^^^^^^^^^^^^
  File "/home/simprosys-aman/.local/lib/python3.11/site-packages/django/db/models/manager.py", line 87, in manager_method
    return getattr(self.get_queryset(), name)(*args, **kwargs)
           ^^^^^^^^^^^^^^^^^^^^^^^^^^^^^^^^^^^^^^^^^^^^^^^^^^^
  File "/home/simprosys-aman/.local/lib/python3.11/site-packages/django/db/models/query.py", line 637, in get
    raise self.model.DoesNotExist(
django.contrib.auth.models.User.DoesNotExist: User matching query does not exist.
